Workbook

Sheet Sheet1
A1: =IF(OR(C2>3.5,D2>3.5,D1>3.5),"wow",IF(AND(C2>2,D2>2,D1>2),"yes",IF(C2=MAX(C2,D2,D1),1,IF(D2=MAX(C2,D2,D1),2,IF(D1=MAX(C2,D2,D1),3,""))))) | B1: =IF(OR(E2>3.5,F2>3.5,F1>3.5),"wow",IF(AND(E2>2,F2>2,F1>2),"yes",IF(E2=MAX(E2,F2,F1),1,IF(F2=MAX(E2,F2,F1),2,IF(F1=MAX(E2,F2,F1),3,""))))) | C1: =$E46-D1 | D1: =AVERAGE(C2,D2) | E1: =$E46-F1 | F1: =AVERAGE(E2,F2) | G1: =$E46-H1 | H1: =AVERAGE(G2,H2) | I1: =$E46-J1 | J1: =AVERAGE(I2,J2) | K1: =$E46-L1 | L1: =AVERAGE(K2,L2)
A2: =IF(OR(G2>3.5,H2>3.5,H1>3.5),"wow",IF(AND(G2>2,H2>2,H1>2),"yes",IF(G2=MAX(G2,H2,H1),1,IF(H2=MAX(G2,H2,H1),2,IF(H1=MAX(G2,H2,H1),3,""))))) | B2: =IF(OR(I2>3.5,J2>3.5,J1>3.5),"wow",IF(AND(I2>2,J2>2,J1>2),"yes",IF(I2=MAX(I2,J2,J1),1,IF(J2=MAX(I2,J2,J1),2,IF(J1=MAX(I2,J2,J1),3,""))))) | C2: =VLOOKUP(F48,$C6:$V42,14)+VLOOKUP(F48,C6:V42,16)*1.35 | D2: =VLOOKUP(G48,$C6:$V42,16)+VLOOKUP(G48,$C6:$V42,14)*1.35 | E2: =VLOOKUP(J48,$C6:$V42,14)+VLOOKUP(J48,$C6:$V42,16)*1.35 | F2: =VLOOKUP(K48,$C6:$V42,16)+VLOOKUP(K48,$C6:$V42,14)*1.35 | G2: =VLOOKUP(N48,$C6:$V42,14)+VLOOKUP(N48,$C6:$V42,16)*1.35 | H2: =VLOOKUP(O48,$C6:$V42,16)+VLOOKUP(O48,$C6:$V42,14)*1.35 | I2: =VLOOKUP(R48,$C6:$V42,14)+VLOOKUP(R48,$C6:$V42,16)*1.35 | J2: =VLOOKUP(S48,$C6:$V42,16)+VLOOKUP(S48,$C6:$V42,14)*1.35 | K2: =VLOOKUP(V48,$C6:$V42,14)+VLOOKUP(V48,$C6:$V42,16)*1.35 | L2: =VLOOKUP(W48,$C6:$V42,16)+VLOOKUP(W48,$C6:$V42,14)*1.35
A3: =IF(OR(K2>3.5,L2>3.5,L1>3.5),"wow",IF(AND(K2>2,L2>2,L1>2),"yes",IF(K2=MAX(K2,L2,L1),1,IF(L2=MAX(K2,L2,L1),2,IF(L1=MAX(K2,L2,L1),3,""))))) | B3: =IF(OR(A64="",Sheet2!AA15="no"),"",Sheet2!N2) | C3: Goals per match
A4: =_xlfn.TEXTJOIN(" /", ,IF(AND(A113="yes",E74=""),"+2",IF(AND(A113="yes",OR(E74="u2.5",E74="u3.5",E74="u4.5",E74="u5.5",E74="u6.5")),"+1",IF(AND(A113="yes",E74<>""),E74,"no"))),_xlfn.IFERROR(E74,""),A79,IF(Sheet2!M71="under",Sheet2!M77,Sheet2!M71)) | B4: =_xlfn.TEXTJOIN(" /", ,H104,_xlfn.IFERROR(E114,""),B115) | D4: GP | E4: Average goals overall | I4: Average goals at home | M4: Average goals away | P4: home | Q4: home | R4: away | S4: away | T4: Home advantage | AB4: Points per game | AD4: 2.25 | AF4: 1.6 | AI4: Points per game | AK4: 2.2 | AM4: 1.03
A5: =_xlfn.TEXTJOIN("/ ", ,Sheet2!Y25,Sheet2!BW25) | B5: =IF(A74<51,"",IF(B70="","",IF(AND(T89="yes",U89="Yes"),"",_xlfn.TEXTJOIN("+ ", ,Sheet2!S3,M106,N106)))) | E5: Scored | F5: Conc. | G5: Total | I5: Scored | J5: Conc. | K5: Total | M5: Scored | N5: Conc. | O5: Total | P5: att | Q5: defend | R5: att | S5: defend | T5: HA | U5: =COUNT(C6:S6) | AB5: % Wins | AD5: 0.75 | AF5: 0.47 | AI5: % Wins | AK5: 0.6 | AM5: 0.28
A6: =IF(Sheet2!F40="coup","just Add 1 goal","clean") | B6: =_xlfn.TEXTJOIN(" ,", , ,Sheet2!V25,D46) | C6: America MG | D6: 13 | E6: 0.77 | F6: 1.85 | G6: 2.62 | I6: 0.67 | J6: 1.83 | K6: 2.5 | M6: 0.86 | N6: 1.86 | O6: 2.71 | P6: =I6/$I$44 | Q6: =J6/$J$44 | R6: =M6/$M$44 | S6: =N6/$N$44 | T6: =IF((I6-M6)/D6<0,0*(I6-M6)/D6,(I6-M6)/D6) | V6: =IF(K6>0,AVERAGE(K6,O6)," ") | AB6: % Draws | AD6: 0 | AF6: 0.18 | AI6: % Draws | AK6: 0.4 | AM6: 0.2
C7: Athletic Club | D7: 14 | E7: 1.07 | F7: 1.07 | G7: 2.14 | I7: 0.86 | J7: 0.71 | K7: 1.57 | M7: 1.29 | N7: 1.43 | O7: 2.71 | P7: =I7/$I$44 | Q7: =J7/$J$44 | R7: =M7/$M$44 | S7: =N7/$N$44 | T7: =IF((I7-M7)/D7<0,0*(I7-M7)/D7,(I7-M7)/D7) | V7: =IF(K7>0,AVERAGE(K7,O7)," ") | AB7: % Defeats | AD7: 0.25 | AF7: 0.35 | AI7: % Defeats | AK7: 0 | AM7: 0.52
C8: Atletico GO | D8: 14 | E8: 1.14 | F8: 1.14 | G8: 2.29 | I8: 1.29 | J8: 1.29 | K8: 2.57 | M8: 1 | N8: 1 | O8: 2 | P8: =I8/$I$44 | Q8: =J8/$J$44 | R8: =M8/$M$44 | S8: =N8/$N$44 | T8: =IF((I8-M8)/D8<0,0*(I8-M8)/D8,(I8-M8)/D8) | V8: =IF(K8>0,AVERAGE(K8,O8)," ") | AB8: Goals scored per game | AD8: 1.75 | AF8: 1.97 | AI8: Goals scored per game | AK8: 1.8 | AM8: 1.2
C9: Avai | D9: 14 | E9: 1.07 | F9: 1.43 | G9: 2.5 | I9: 1 | J9: 1.13 | K9: 2.13 | M9: 1.17 | N9: 1.83 | O9: 3 | P9: =I9/$I$44 | Q9: =J9/$J$44 | R9: =M9/$M$44 | S9: =N9/$N$44 | T9: =IF((I9-M9)/D9<0,0*(I9-M9)/D9,(I9-M9)/D9) | V9: =IF(K9>0,AVERAGE(K9,O9)," ") | AB9: Goals conceded per game | AD9: 1.25 | AF9: 1.57 | AI9: Goals conceded per game | AK9: 0.4 | AM9: 1.57
A10: =IF(B10>AVERAGE(D6:D42),"no","yes") | B10: =ROUND(((COUNTA(C6:C42)-1)*((COUNTA(C6:C42)-1)*2))/38,0) | C10: Botafogo SP | D10: 14 | E10: 1 | F10: 0.93 | G10: 1.93 | I10: 1.67 | J10: 1.17 | K10: 2.83 | M10: 0.5 | N10: 0.75 | O10: 1.25 | P10: =I10/$I$44 | Q10: =J10/$J$44 | R10: =M10/$M$44 | S10: =N10/$N$44 | T10: =IF((I10-M10)/D10<0,0*(I10-M10)/D10,(I10-M10)/D10) | V10: =IF(K10>0,AVERAGE(K10,O10)," ") | AB10: % Clean sheets | AD10: 0.5 | AF10: 0.26 | AI10: % Clean sheets | AK10: 0.6 | AM10: 0.24
C11: Ceara | D11: 14 | E11: 1.07 | F11: 1.14 | G11: 2.21 | I11: 1.25 | J11: 1.25 | K11: 2.5 | M11: 0.83 | N11: 1 | O11: 1.83 | P11: =I11/$I$44 | Q11: =J11/$J$44 | R11: =M11/$M$44 | S11: =N11/$N$44 | T11: =IF((I11-M11)/D11<0,0*(I11-M11)/D11,(I11-M11)/D11) | V11: =IF(K11>0,AVERAGE(K11,O11)," ") | AB11: % Failed To Score | AD11: 0 | AF11: 0.14 | AI11: % Failed To Score | AK11: 0 | AM11: 0.34
C12: CRB | D12: 14 | E12: 1.64 | F12: 1.71 | G12: 3.36 | I12: 1.71 | J12: 1.57 | K12: 3.29 | M12: 1.57 | N12: 1.86 | O12: 3.43 | P12: =I12/$I$44 | Q12: =J12/$J$44 | R12: =M12/$M$44 | S12: =N12/$N$44 | T12: =IF((I12-M12)/D12<0,0*(I12-M12)/D12,(I12-M12)/D12) | V12: =IF(K12>0,AVERAGE(K12,O12)," ") | AB12: % Won To Nil | AD12: 0.5 | AF12: 0.24 | AI12: % Won To Nil | AK12: 0.6 | AM12: 0.17
C13: Criciuma | D13: 13 | E13: 1.15 | F13: 0.85 | G13: 2 | I13: 1.33 | J13: 0.67 | K13: 2 | M13: 1 | N13: 1 | O13: 2 | P13: =I13/$I$44 | Q13: =J13/$J$44 | R13: =M13/$M$44 | S13: =N13/$N$44 | T13: =IF((I13-M13)/D13<0,0*(I13-M13)/D13,(I13-M13)/D13) | V13: =IF(K13>0,AVERAGE(K13,O13)," ") | AB13: % Lost To Nil | AD13: 0 | AF13: 0.11 | AI13: % Lost To Nil | AK13: 0 | AM13: 0.27
C14: Cuiaba | D14: 14 | E14: 0.64 | F14: 0.5 | G14: 1.14 | I14: 0.71 | J14: 0.57 | K14: 1.29 | M14: 0.57 | N14: 0.43 | O14: 1 | P14: =I14/$I$44 | Q14: =J14/$J$44 | R14: =M14/$M$44 | S14: =N14/$N$44 | T14: =IF((I14-M14)/D14<0,0*(I14-M14)/D14,(I14-M14)/D14) | V14: =IF(K14>0,AVERAGE(K14,O14)," ") | AB14: Total goals per game | AD14: 3 | AF14: 3.54 | AI14: % Team scored first | AK14: 1 | AM14: 0.36
C15: Fortaleza | D15: 14 | E15: 1.14 | F15: 1.07 | G15: 2.21 | I15: 2 | J15: 1.17 | K15: 3.17 | M15: 0.5 | N15: 1 | O15: 1.5 | P15: =I15/$I$44 | Q15: =J15/$J$44 | R15: =M15/$M$44 | S15: =N15/$N$44 | T15: =IF((I15-M15)/D15<0,0*(I15-M15)/D15,(I15-M15)/D15) | V15: =IF(K15>0,AVERAGE(K15,O15)," ") | AB15: % over 1.5 goals | AD15: 0.75 | AF15: 0.88 | AI15: % Opponent scored first | AK15: 0 | AM15: 0.57
C16: Goias | D16: 13 | E16: 1 | F16: 1.38 | G16: 2.38 | I16: 1 | J16: 1.17 | K16: 2.17 | M16: 1 | N16: 1.57 | O16: 2.57 | P16: =I16/$I$44 | Q16: =J16/$J$44 | R16: =M16/$M$44 | S16: =N16/$N$44 | T16: =IF((I16-M16)/D16<0,0*(I16-M16)/D16,(I16-M16)/D16) | V16: =IF(K16>0,AVERAGE(K16,O16)," ") | AB16: % over 2.5 goals | AD16: 0.5 | AF16: 0.74 | AI16: Total goals per game | AK16: 2.2 | AM16: 2.77
C17: Juventude | D17: 13 | E17: 1 | F17: 0.62 | G17: 1.62 | I17: 1.29 | J17: 0.14 | K17: 1.43 | M17: 0.67 | N17: 1.17 | O17: 1.83 | P17: =I17/$I$44 | Q17: =J17/$J$44 | R17: =M17/$M$44 | S17: =N17/$N$44 | T17: =IF((I17-M17)/D17<0,0*(I17-M17)/D17,(I17-M17)/D17) | V17: =IF(K17>0,AVERAGE(K17,O17)," ") | AB17: % over 3.5 goals | AD17: 0.25 | AF17: 0.51 | AI17: % over 1.5 goals | AK17: 0.8 | AM17: 0.76
C18: Londrina | D18: 14 | E18: 1.21 | F18: 1.57 | G18: 2.79 | I18: 1.29 | J18: 1.43 | K18: 2.71 | M18: 1.14 | N18: 1.71 | O18: 2.86 | P18: =I18/$I$44 | Q18: =J18/$J$44 | R18: =M18/$M$44 | S18: =N18/$N$44 | T18: =IF((I18-M18)/D18<0,0*(I18-M18)/D18,(I18-M18)/D18) | V18: =IF(K18>0,AVERAGE(K18,O18)," ") | AB18: % both teams scored | AD18: 0.5 | AF18: 0.62 | AI18: % over 2.5 goals | AK18: 0.4 | AM18: 0.55
C19: Nautico | D19: 14 | E19: 1.5 | F19: 1.29 | G19: 2.79 | I19: 1 | J19: 0.83 | K19: 1.83 | M19: 1.88 | N19: 1.63 | O19: 3.5 | P19: =I19/$I$44 | Q19: =J19/$J$44 | R19: =M19/$M$44 | S19: =N19/$N$44 | T19: =IF((I19-M19)/D19<0,0*(I19-M19)/D19,(I19-M19)/D19) | V19: =IF(K19>0,AVERAGE(K19,O19)," ") | AB19: % Team scored first | AD19: 0.5 | AF19: 0.56 | AI19: % over 3.5 goals | AK19: 0 | AM19: 0.29
C20: Novorizontino | D20: 13 | E20: 1.54 | F20: 1 | G20: 2.54 | I20: 1.5 | J20: 1.33 | K20: 2.83 | M20: 1.57 | N20: 0.71 | O20: 2.29 | P20: =I20/$I$44 | Q20: =J20/$J$44 | R20: =M20/$M$44 | S20: =N20/$N$44 | T20: =IF((I20-M20)/D20<0,0*(I20-M20)/D20,(I20-M20)/D20) | V20: =IF(K20>0,AVERAGE(K20,O20)," ") | AB20: % Opponent scored first | AD20: 0.5 | AF20: 0.42 | AI20: % both teams scored | AK20: 0.4 | AM20: 0.49
C21: Operario PR | D21: 13 | E21: 1.15 | F21: 1.31 | G21: 2.46 | I21: 1.29 | J21: 1.14 | K21: 2.43 | M21: 1 | N21: 1.5 | O21: 2.5 | P21: =I21/$I$44 | Q21: =J21/$J$44 | R21: =M21/$M$44 | S21: =N21/$N$44 | T21: =IF((I21-M21)/D21<0,0*(I21-M21)/D21,(I21-M21)/D21) | V21: =IF(K21>0,AVERAGE(K21,O21)," ") | AB21: Average minute scored first | AD21: 48 | AF21: 24
C22: Ponte Preta | D22: 13 | E22: 0.77 | F22: 1.92 | G22: 2.69 | I22: 0.71 | J22: 1.57 | K22: 2.29 | M22: 0.83 | N22: 2.33 | O22: 3.17 | P22: =I22/$I$44 | Q22: =J22/$J$44 | R22: =M22/$M$44 | S22: =N22/$N$44 | T22: =IF((I22-M22)/D22<0,0*(I22-M22)/D22,(I22-M22)/D22) | V22: =IF(K22>0,AVERAGE(K22,O22)," ") | AB22: Average minute conceded first | AD22: 13 | AF22: 27
C23: Sao Bernardo | D23: 13 | E23: 1.54 | F23: 0.77 | G23: 2.31 | I23: 1 | J23: 0.71 | K23: 1.71 | M23: 2.17 | N23: 0.83 | O23: 3 | P23: =I23/$I$44 | Q23: =J23/$J$44 | R23: =M23/$M$44 | S23: =N23/$N$44 | T23: =IF((I23-M23)/D23<0,0*(I23-M23)/D23,(I23-M23)/D23) | V23: =IF(K23>0,AVERAGE(K23,O23)," ") | AB23: Lead-defending rate | AD23: 0.75 | AF23: 0.6
C24: Sport Recife | D24: 14 | E24: 1.21 | F24: 0.64 | G24: 1.86 | I24: 1.38 | J24: 0.88 | K24: 2.25 | M24: 1 | N24: 0.33 | O24: 1.33 | P24: =I24/$I$44 | Q24: =J24/$J$44 | R24: =M24/$M$44 | S24: =N24/$N$44 | T24: =IF((I24-M24)/D24<0,0*(I24-M24)/D24,(I24-M24)/D24) | V24: =IF(K24>0,AVERAGE(K24,O24)," ") | AB24: Equalizing rate | AD24: 0.67 | AF24: 0.43
C25: Vila Nova | D25: 14 | E25: 1.57 | F25: 1.07 | G25: 2.64 | I25: 2 | J25: 1.14 | K25: 3.14 | M25: 1.14 | N25: 1 | O25: 2.14 | P25: =I25/$I$44 | Q25: =J25/$J$44 | R25: =M25/$M$44 | S25: =N25/$N$44 | T25: =IF((I25-M25)/D25<0,0*(I25-M25)/D25,(I25-M25)/D25) | V25: =IF(K25>0,AVERAGE(K25,O25)," ") | AB25: % Time leading | AD25: 0.4 | AF25: 0.37
P26: =I26/$I$44 | Q26: =J26/$J$44 | R26: =M26/$M$44 | S26: =N26/$N$44 | T26: =IF((I26-M26)/D26<0,0*(I26-M26)/D26,(I26-M26)/D26) | V26: =IF(K26>0,AVERAGE(K26,O26)," ") | AB26: % Time level in goals | AD26: 0.47 | AF26: 0.4
P27: =I27/$I$44 | Q27: =J27/$J$44 | R27: =M27/$M$44 | S27: =N27/$N$44 | T27: =IF((I27-M27)/D27<0,0*(I27-M27)/D27,(I27-M27)/D27) | V27: =IF(K27>0,AVERAGE(K27,O27)," ") | AB27: % Time trailing | AD27: 0.13 | AF27: 0.23
P28: =I28/$I$44 | Q28: =J28/$J$44 | R28: =M28/$M$44 | S28: =N28/$N$44 | T28: =IF((I28-M28)/D28<0,0*(I28-M28)/D28,(I28-M28)/D28) | V28: =IF(K28>0,AVERAGE(K28,O28)," ") | AB28: PPG when scored first | AD28: 3 | AF28: 2.23
P29: =I29/$I$44 | Q29: =J29/$J$44 | R29: =M29/$M$44 | S29: =N29/$N$44 | T29: =IF((I29-M29)/D29<0,0*(I29-M29)/D29,(I29-M29)/D29) | V29: =IF(K29>0,AVERAGE(K29,O29)," ") | AB29: PPG when conceded first | AD29: 1.5 | AF29: 0.8
P30: =I30/$I$44 | Q30: =J30/$J$44 | R30: =M30/$M$44 | S30: =N30/$N$44 | T30: =IF((I30-M30)/D30<0,0*(I30-M30)/D30,(I30-M30)/D30) | V30: =IF(K30>0,AVERAGE(K30,O30)," ")
P31: =I31/$I$44 | Q31: =J31/$J$44 | R31: =M31/$M$44 | S31: =N31/$N$44 | T31: =IF((I31-M31)/D31<0,0*(I31-M31)/D31,(I31-M31)/D31) | V31: =IF(K31>0,AVERAGE(K31,O31)," ")
P32: =I32/$I$44 | Q32: =J32/$J$44 | R32: =M32/$M$44 | S32: =N32/$N$44 | T32: =IF((I32-M32)/D32<0,0*(I32-M32)/D32,(I32-M32)/D32) | V32: =IF(K32>0,AVERAGE(K32,O32)," ")
P33: =I33/$I$44 | Q33: =J33/$J$44 | R33: =M33/$M$44 | S33: =N33/$N$44 | T33: =IF((I33-M33)/D33<0,0*(I33-M33)/D33,(I33-M33)/D33) | V33: =IF(K33>0,AVERAGE(K33,O33)," ")
P34: =I34/$I$44 | Q34: =J34/$J$44 | R34: =M34/$M$44 | S34: =N34/$N$44 | T34: =IF((I34-M34)/D34<0,0*(I34-M34)/D34,(I34-M34)/D34) | V34: =IF(K34>0,AVERAGE(K34,O34)," ")
P35: =I35/$I$44 | Q35: =J35/$J$44 | R35: =M35/$M$44 | S35: =N35/$N$44 | T35: =IF((I35-M35)/D35<0,0*(I35-M35)/D35,(I35-M35)/D35) | V35: =IF(K35>0,AVERAGE(K35,O35)," ")
P36: =I36/$I$44 | Q36: =J36/$J$44 | R36: =M36/$M$44 | S36: =N36/$N$44 | T36: =IF((I36-M36)/D36<0,0*(I36-M36)/D36,(I36-M36)/D36) | V36: =IF(K36>0,AVERAGE(K36,O36)," ")
P37: =I37/$I$44 | Q37: =J37/$J$44 | R37: =M37/$M$44 | S37: =N37/$N$44 | T37: =IF((I37-M37)/D37<0,0*(I37-M37)/D37,(I37-M37)/D37) | V37: =IF(K37>0,AVERAGE(K37,O37)," ")
P38: =I38/$I$44 | Q38: =J38/$J$44 | R38: =M38/$M$44 | S38: =N38/$N$44 | T38: =IF((I38-M38)/D38<0,0*(I38-M38)/D38,(I38-M38)/D38) | V38: =IF(K38>0,AVERAGE(K38,O38)," ")
P39: =I39/$I$44 | Q39: =J39/$J$44 | R39: =M39/$M$44 | S39: =N39/$N$44 | T39: =IF((I39-M39)/D39<0,0*(I39-M39)/D39,(I39-M39)/D39) | V39: =IF(K39>0,AVERAGE(K39,O39)," ")
P40: =I40/$I$44 | Q40: =J40/$J$44 | R40: =M40/$M$44 | S40: =N40/$N$44 | T40: =IF((I40-M40)/D40<0,0*(I40-M40)/D40,(I40-M40)/D40) | V40: =IF(K40>0,AVERAGE(K40,O40)," ")
...

Sheet Sheet2
Q1: =AVERAGE(N8:O11,N7,P9,P10,P11,Q10,Q11,R11) | R1: =AVERAGE(N6,O7,P8,Q9,R10,S11) | S1: =AVERAGE(R6:S9,S10,Q6,Q7,Q8,P7,P6,O6) | U1: 0 | V1: =U1+1 | W1: =V1+1 | X1: =W1+1 | Y1: =X1+1 | AP1: =AVERAGE(AM8:AN11,AM7,AO9,AO10,AO11,AP10,AP11,AQ11) | AQ1: =AVERAGE(AM6,AN7,AO8,AP9,AQ10,AR11) | AR1: =AVERAGE(AQ6:AR9,AR10,AP6,AP7,AP8,AO7,AO6,AN6) | AT1: 0 | AU1: =AT1+1 | AV1: =AU1+1 | AW1: =AV1+1 | AX1: =AW1+1 | BS1: 0 | BT1: =BS1+1 | BU1: =BT1+1 | BV1: =BU1+1 | BW1: =BV1+1 | CR1: 0 | CS1: =CR1+1 | CT1: =CS1+1 | CU1: =CT1+1 | CV1: =CU1+1 | DQ1: 0 | DR1: =DQ1+1 | DS1: =DR1+1 | DT1: =DS1+1 | DU1: =DT1+1
N2: =IF(AND(O3<>"bad",O16>67,Sheet1!H104<>"high",Y25<>"D'over",OR(Sheet1!B5="",Sheet1!B70="")),"good+1",IF(AND(O3<>"bad",O16>67,Sheet1!H104<>"high",Y25<>"D'over"),"good","bad")) | O2: =IF(AND(Sheet1!E114="yes",Sheet1!B115<14),"ok","no") | P2: 1 | Q2: =AVERAGE(C5,Q1) | R2: =(Sheet1!N105/1000)+Q3 | S2: =AVERAGE(S1,D5) | T2: =AVERAGE(C5,D5) | U2: =POISSON(U1,$T$2,FALSE)*100 | V2: =POISSON(V1,$T$2,FALSE)*100 | W2: =POISSON(W1,$T$2,FALSE)*100 | X2: =POISSON(X1,$T$2,FALSE)*100 | Y2: =POISSON(Y1,$T$2,FALSE)*100 | Z2: =SUM(U2:Y2,U4:Y4) | AN2: 2 | AP2: =AVERAGE(AP1,C6) | AR2: =AVERAGE(AR1,D6) | AS2: =AVERAGE(C6,D6) | AT2: =POISSON(AT1,$AS$2,FALSE)*100 | AU2: =POISSON(AU1,$AS$2,FALSE)*100 | AV2: =POISSON(AV1,$AS$2,FALSE)*100 | AW2: =POISSON(AW1,$AS$2,FALSE)*100 | AX2: =POISSON(AX1,$AS$2,FALSE)*100 | AY2: =SUM(AT2:AX2,AT4:AX4) | BM2: 3 | BR2: =AVERAGE(C7,D7) | BS2: =POISSON(BS1,$BR$2,FALSE)*100 | BT2: =POISSON(BT1,$BR$2,FALSE)*100 | BU2: =POISSON(BU1,$BR$2,FALSE)*100 | BV2: =POISSON(BV1,$BR$2,FALSE)*100 | BW2: =POISSON(BW1,$BR$2,FALSE)*100 | BX2: =SUM(BS2:BW2,BS4:BW4) | CL2: 4 | CQ2: =AVERAGE(C8,D8) | CR2: =POISSON(CR1,$CQ$2,FALSE)*100 | CS2: =POISSON(CS1,$CQ$2,FALSE)*100 | CT2: =POISSON(CT1,$CQ$2,FALSE)*100 | CU2: =POISSON(CU1,$CQ$2,FALSE)*100 | CV2: =POISSON(CV1,$CQ$2,FALSE)*100 | CW2: =SUM(CR2:CV2,CR4:CV4) | DK2: 5 | DP2: =AVERAGE(C9,D9) | DQ2: =POISSON(DQ1,$DP$2,FALSE)*100 | DR2: =POISSON(DR1,$DP$2,FALSE)*100 | DS2: =POISSON(DS1,$DP$2,FALSE)*100 | DT2: =POISSON(DT1,$DP$2,FALSE)*100 | DU2: =POISSON(DU1,$DP$2,FALSE)*100 | DV2: =SUM(DQ2:DU2,DQ4:DU4)
F3: 1 | O3: =IF(AND(O2="ok",P3="yes1"),"wow",IF(AND(O2="ok",P3="yes"),"good","bad")) | P3: =IF(AND(Sheet1!M106<>"F",S3="F"),"yes1",IF(AND(S3<>"F",Sheet1!M106<>"F"),"yes","no")) | Q3: =AR3-AP3 | R3: =(ABS(R2))*100+(Sheet1!I106)*10 | S3: =IF(R3<30,"A",IF(R3<34,"B",IF(R3<40,"C","F"))) | T3: =C5-D5 | U3: 5 | V3: =U3+1 | W3: =V3+1 | X3: =W3+1 | Y3: =X3+1 | Z3: 0 | AA3: =U2 | AB3: =AA4-AA3 | AC3: 9.8187575 | AE3: 2 | AP3: =AVERAGE(AP2,S2) | AR3: =AVERAGE(AR2,Q2) | AS3: =C6-D6 | AT3: 5 | AU3: =AT3+1 | AV3: =AU3+1 | AW3: =AV3+1 | AX3: =AW3+1 | AY3: 0 | AZ3: =AT2 | BA3: =AZ4-AZ3 | BB3: 9.8187575 | BD3: 3 | BR3: =C7-D7 | BS3: 5 | BT3: =BS3+1 | BU3: =BT3+1 | BV3: =BU3+1 | BW3: =BV3+1 | BX3: 0 | BY3: =BS2 | BZ3: =BY4-BY3 | CA3: =BZ3-BZ4 | CC3: 4 | CQ3: =C8-D8 | CR3: 5 | CS3: =CR3+1 | CT3: =CS3+1 | CU3: =CT3+1 | CV3: =CU3+1 | CW3: 0 | CX3: =CR2 | CY3: =CX4-CX3 | CZ3: =CY3-CY4 | DB3: 5 | DP3: =C9-D9 | DQ3: 5 | DR3: =DQ3+1 | DS3: =DR3+1 | DT3: =DS3+1 | DU3: =DT3+1 | DV3: 0 | DW3: =DQ2 | DX3: =DW4-DW3 | DY3: =DX3-DX4
C4: home | D4: away | E4: =Sheet1!F48 | G4: =Sheet1!G48 | H4: chances | L4: no. of goals | M4: =G4 | N4: 0 | O4: =N4+1 | P4: =O4+1 | Q4: =P4+1 | R4: =Q4+1 | S4: =R4+1 | U4: =POISSON(U3,$T$2,FALSE)*100 | V4: =POISSON(V3,$T$2,FALSE)*100 | W4: =POISSON(W3,$T$2,FALSE)*100 | X4: =POISSON(X3,$T$2,FALSE)*100 | Y4: =POISSON(Y3,$T$2,FALSE)*100 | Z4: =Z3+1 | AA4: =SUM(U2,V2) | AB4: =AA5-AA4 | AC4: 12.814904 | AD4: =Sheet1!J48 | AF4: =Sheet1!K48 | AG4: chances | AK4: no. of goals | AL4: =AF4 | AM4: 0 | AN4: =AM4+1 | AO4: =AN4+1 | AP4: =AO4+1 | AQ4: =AP4+1 | AR4: =AQ4+1 | AT4: =POISSON(AT3,$AS$2,FALSE)*100 | AU4: =POISSON(AU3,$AS$2,FALSE)*100 | AV4: =POISSON(AV3,$AS$2,FALSE)*100 | AW4: =POISSON(AW3,$AS$2,FALSE)*100 | AX4: =POISSON(AX3,$AS$2,FALSE)*100 | AY4: =AY3+1 | AZ4: =SUM(AT2,AU2) | BA4: =AZ5-AZ4 | BB4: 12.814904 | BC4: =Sheet1!N48 | BE4: =Sheet1!O48 | BF4: chances | BJ4: no. of goals | BK4: =BE4 | BL4: 0 | BM4: =BL4+1 | BN4: =BM4+1 | BO4: =BN4+1 | BP4: =BO4+1 | BQ4: =BP4+1 | BS4: =POISSON(BS3,$BR$2,FALSE)*100 | BT4: =POISSON(BT3,$BR$2,FALSE)*100 | BU4: =POISSON(BU3,$BR$2,FALSE)*100 | BV4: =POISSON(BV3,$BR$2,FALSE)*100 | BW4: =POISSON(BW3,$BR$2,FALSE)*100 | BX4: =BX3+1 | BY4: =SUM(BS2,BT2) | BZ4: =BY5-BY4 | CA4: =BZ4-BZ5 | CB4: =Sheet1!R48 | CD4: =Sheet1!S48 | CE4: chances | CI4: no. of goals | CJ4: =CD4 | CK4: 0 | CL4: =CK4+1 | CM4: =CL4+1 | CN4: =CM4+1 | CO4: =CN4+1 | CP4: =CO4+1 | CR4: =POISSON(CR3,$CQ$2,FALSE)*100 | CS4: =POISSON(CS3,$CQ$2,FALSE)*100 | CT4: =POISSON(CT3,$CQ$2,FALSE)*100 | CU4: =POISSON(CU3,$CQ$2,FALSE)*100 | CV4: =POISSON(CV3,$CQ$2,FALSE)*100 | CW4: =CW3+1 | CX4: =SUM(CR2,CS2) | CY4: =CX5-CX4 | CZ4: =CY4-CY5 | DA4: =Sheet1!V48 | DC4: =Sheet1!W48 | DD4: chances | DH4: no. of goals | DI4: =DC4 | DJ4: 0 | DK4: =DJ4+1 | DL4: =DK4+1 | DM4: =DL4+1 | DN4: =DM4+1 | DO4: =DN4+1 | DQ4: =POISSON(DQ3,$DP$2,FALSE)*100 | DR4: =POISSON(DR3,$DP$2,FALSE)*100 | DS4: =POISSON(DS3,$DP$2,FALSE)*100 | DT4: =POISSON(DT3,$DP$2,FALSE)*100 | DU4: =POISSON(DU3,$DP$2,FALSE)*100 | DV4: =DV3+1 | DW4: =SUM(DQ2,DR2) | DX4: =DW5-DW4 | DY4: =DX4-DX5
B5: 1 | C5: =Sheet1!F52 | D5: =Sheet1!G52 | E5: 0 | F5: : | G5: 0 | H5: =POISSON(E5,$C$5,FALSE)*POISSON(G5,$D$5,FALSE)*100 | I5: =RANK(H5,$H$5:$H$36,0) | J5: =IF(J24="away",J19-(J23*3),IF(J24="home",J19-(J22*3),J19)) | L5: =E4 | M5: probablity | N5: =POISSON(N4,$D$5,FALSE) | O5: =POISSON(O4,$D$5,FALSE) | P5: =POISSON(P4,$D$5,FALSE) | Q5: =POISSON(Q4,$D$5,FALSE) | R5: =POISSON(R4,$D$5,FALSE) | S5: =POISSON(S4,$D$5,FALSE) | W5: under | X5: over | Z5: =Z4+1 | AA5: =SUM(U2,V2,W2) | AB5: =AA6-AA5 | AC5: 7.47612 | AD5: 0 | AE5: =AD5+AF5 | AF5: 0 | AG5: =POISSON(AD5,$C$6,FALSE)*POISSON(AF5,$D$6,FALSE)*100 | AH5: =RANK(AG5,$AG$5:$AG$36,0) | AI5: =IF(AI24="away",AI19-(AI23*3),IF(AI24="home",AI19-(AI22*3),AI19)) | AK5: =AD4 | AL5: probablity | AM5: =POISSON(AM4,$D$6,FALSE) | AN5: =POISSON(AN4,$D$6,FALSE) | AO5: =POISSON(AO4,$D$6,FALSE) | AP5: =POISSON(AP4,$D$6,FALSE) | AQ5: =POISSON(AQ4,$D$6,FALSE) | AR5: =POISSON(AR4,$D$6,FALSE) | AV5: under | AW5: over | AY5: =AY4+1 | AZ5: =SUM(AT2,AU2,AV2) | BA5: =AZ6-AZ5 | BB5: 7.47612 | BC5: 0 | BD5: : | BE5: 0 | BF5: =POISSON(BC5,$C$7,FALSE)*POISSON(BE5,$D$7,FALSE)*100 | BG5: =RANK(BF5,$BF$5:$BF$36,0) | BH5: =IF(BH24="away",BH19-(BH23*3),IF(BH24="home",BH19-(BH22*3),BH19)) | BJ5: =BC4 | BK5: probablity | BL5: =POISSON(BL4,$D$7,FALSE) | BM5: =POISSON(BM4,$D$7,FALSE) | BN5: =POISSON(BN4,$D$7,FALSE) | BO5: =POISSON(BO4,$D$7,FALSE) | BP5: =POISSON(BP4,$D$7,FALSE) | BQ5: =POISSON(BQ4,$D$7,FALSE) | BU5: under | BV5: over | BX5: =BX4+1 | BY5: =SUM(BS2,BT2,BU2) | BZ5: =BY6-BY5 | CA5: =BZ5-BZ6 | CB5: 0 | CC5: : | CD5: 0 | CE5: =POISSON(CB5,$C$8,FALSE)*POISSON(CD5,$D$8,FALSE)*100 | CF5: =RANK(CE5,$CE$5:$CE$36,0) | CG5: =IF(CG24="away",CG19-(CG23*3),IF(CG24="home",CG19-(CG22*3),CG19)) | CI5: =CB4 | CJ5: probablity | CK5: =POISSON(CK4,$D$8,FALSE) | CL5: =POISSON(CL4,$D$8,FALSE) | CM5: =POISSON(CM4,$D$8,FALSE) | CN5: =POISSON(CN4,$D$8,FALSE) | CO5: =POISSON(CO4,$D$8,FALSE) | CP5: =POISSON(CP4,$D$8,FALSE) | CT5: under | CU5: over | CW5: =CW4+1 | CX5: =SUM(CR2,CS2,CT2) | CY5: =CX6-CX5 | CZ5: =CY5-CY6 | DA5: 0 | DB5: : | DC5: 0 | DD5: =POISSON(DA5,$C$9,FALSE)*POISSON(DC5,$D$9,FALSE)*100 | DE5: =RANK(DD5,$DD$5:$DD$36,0) | DF5: =IF(DF24="away",DF19-(DF23*3),IF(DF24="home",DF19-(DF22*3),DF19)) | DH5: =DA4 | DI5: probablity | DJ5: =POISSON(DJ4,$D$9,FALSE) | DK5: =POISSON(DK4,$D$9,FALSE) | DL5: =POISSON(DL4,$D$9,FALSE) | DM5: =POISSON(DM4,$D$9,FALSE) | DN5: =POISSON(DN4,$D$9,FALSE) | DO5: =POISSON(DO4,$D$9,FALSE) | DS5: under | DT5: over | DV5: =DV4+1 | DW5: =SUM(DQ2,DR2,DS2) | DX5: =DW6-DW5 | DY5: =DX5-DX6
B6: =B5+1 | C6: =Sheet1!J52 | D6: =Sheet1!K52 | E6: 0 | F6: : | G6: 1 | H6: =POISSON(E6,$C$5,FALSE)*POISSON(G6,$D$5,FALSE)*100 | I6: =RANK(H6,$H$5:$H$36,0) | J6: =IF(I5=1,"draw",IF(I6=1,"away",IF(I7=1,"draw 1-1",IF(I8=1,"home",IF(I9=1,"away 0-2",IF(I10=1,"away 1-2",IF(I11=1,"home 2-1","rountime"))))))) | K6: =IF(OR(J6="away",J6="home",J6="draw"),"small",IF(OR(J6="away",J6="home",J6="draw",J6="draw 1-1",J6="away 0-2"),"under",IF(J6="rountime","RT",0))) | L6: 0 | M6: =POISSON(L6,$C$5,FALSE) | N6: =$N$5*M6 | O6: =$O$5*M6 | P6: =$P$5*M6 | Q6: =$Q$5*M6 | R6: =$R$5*M6 | S6: =$S$5*M6 | T6: =SUM(R6:S9,S10,Q6,Q7,Q8,P7,P6,O6)*100 | V6: 0.5 | W6: =N6 | X6: =(Y6-W6) | Y6: =SUM(N6:S11) | Z6: =Z5+1 | AA6: =SUM(U2,V2,W2,X2) | AB6: =AA7-AA6 | AC6: =IF(AND(AC4>AC3,AC5),2.5,IF(AND(AC3>AC4,AC5),1.5,IF(AND(AC5>AC3,AC4),3.5))) | AD6: 0 | AE6: =AD6+AF6 | AF6: 1 | AG6: =POISSON(AD6,$C$6,FALSE)*POISSON(AF6,$D$6,FALSE)*100 | AH6: =RANK(AG6,$AG$5:$AG$36,0) | AI6: =IF(AH5=1,"draw",IF(AH6=1,"away",IF(AH7=1,"draw 1-1",IF(AH8=1,"home",IF(AH9=1,"away 0-2",IF(AH10=1,"away 1-2",IF(AH11=1,"home 2-1","rountime"))))))) | AJ6: =IF(OR(AI6="away",AI6="home",AI6="draw"),"small",IF(OR(AI6="away",AI6="home",AI6="draw",AI6="draw 1-1",AI6="away 0-2"),"under",IF(AI6="rountime","RT",0))) | AK6: 0 | AL6: =POISSON(AK6,$C$6,FALSE) | AM6: =$AM$5*AL6 | AN6: =$AN$5*AL6 | AO6: =$AO$5*AL6 | AP6: =$AP$5*AL6 | AQ6: =$AQ$5*AL6 | AR6: =$AR$5*AL6 | AS6: =SUM(AQ6:AR9,AR10,AP6,AP7,AP8,AO7,AO6,AN6)*100 | AU6: 0.5 | AV6: =AM6 | AW6: =(AX6-AV6) | AX6: =SUM(AM6:AR11) | AY6: =AY5+1 | AZ6: =SUM(AT2,AU2,AV2,AW2) | BA6: =AZ7-AZ6 | BB6: =IF(AND(BB4>BB3,BB5),2.5,IF(AND(BB3>BB4,BB5),1.5,IF(AND(BB5>BB3,BB4),3.5))) | BC6: 0 | BD6: : | BE6: 1 | BF6: =POISSON(BC6,$C$7,FALSE)*POISSON(BE6,$D$7,FALSE)*100 | BG6: =RANK(BF6,$BF$5:$BF$36,0) | BH6: =IF(BG5=1,"draw",IF(BG6=1,"away",IF(BG7=1,"draw 1-1",IF(BG8=1,"home",IF(BG9=1,"away 0-2",IF(BG10=1,"away 1-2",IF(BG11=1,"home 2-1","rountime"))))))) | BI6: =IF(OR(BH6="away",BH6="home",BH6="draw"),"small",IF(OR(BH6="away",BH6="home",BH6="draw",BH6="draw 1-1",BH6="away 0-2"),"under",IF(BH6="rountime","RT",0))) | BJ6: 0 | BK6: =POISSON(BJ6,$C$7,FALSE) | BL6: =$BL$5*BK6 | BM6: =$BM$5*BK6 | BN6: =$BN$5*BK6 | BO6: =$BO$5*BK6 | BP6: =$BP$5*BK6 | BQ6: =$BQ$5*BK6 | BR6: =SUM(BP6:BQ9,BQ10,BO6,BO7,BO8,BN7,BN6,BM6)*100 | BT6: 0.5 | BU6: =BL6 | BV6: =(BW6-BU6) | BW6: =SUM(BL6:BQ11) | BX6: =BX5+1 | BY6: =SUM(BS2,BT2,BU2,BV2) | BZ6: =BY7-BY6 | CA6: =IF(AND(CA4>CA3,CA5),2.5,IF(AND(CA3>CA4,CA5),1.5,IF(AND(CA5>CA3,CA4),3.5))) | CB6: 0 | CC6: : | CD6: 1 | CE6: =POISSON(CB6,$C$8,FALSE)*POISSON(CD6,$D$8,FALSE)*100 | CF6: =RANK(CE6,$CE$5:$CE$36,0) | CG6: =IF(CF5=1,"draw",IF(CF6=1,"away",IF(CF7=1,"draw 1-1",IF(CF8=1,"home",IF(CF9=1,"away 0-2",IF(CF10=1,"away 1-2",IF(CF11=1,"home 2-1","rountime"))))))) | CH6: =IF(OR(CG6="away",CG6="home",CG6="draw"),"small",IF(OR(CG6="away",CG6="home",CG6="draw",CG6="draw 1-1",CG6="away 0-2"),"under",IF(CG6="rountime","RT",0))) | CI6: 0 | CJ6: =POISSON(CI6,$C$8,FALSE) | CK6: =$CK$5*CJ6 | CL6: =$CL$5*CJ6 | CM6: =$CM$5*CJ6 | CN6: =$CN$5*CJ6 | CO6: =$CO$5*CJ6 | CP6: =$CP$5*CJ6 | CQ6: =SUM(CO6:CP9,CP10,CN6,CN7,CN8,CM7,CM6,CL6)*100 | CS6: 0.5 | CT6: =CK6 | CU6: =(CV6-CT6) | CV6: =SUM(CK6:CP11) | CW6: =CW5+1 | CX6: =SUM(CR2,CS2,CT2,CU2) | CY6: =CX7-CX6 | CZ6: =IF(AND(CZ4>CZ3,CZ5),2.5,IF(AND(CZ3>CZ4,CZ5),1.5,IF(AND(CZ5>CZ3,CZ4),3.5))) | DA6: 0 | DB6: : | DC6: 1 | DD6: =POISSON(DA6,$C$9,FALSE)*POISSON(DC6,$D$9,FALSE)*100 | DE6: =RANK(DD6,$DD$5:$DD$36,0) | DF6: =IF(DE5=1,"draw",IF(DE6=1,"away",IF(DE7=1,"draw 1-1",IF(DE8=1,"home",IF(DE9=1,"away 0-2",IF(DE10=1,"away 1-2",IF(DE11=1,"home 2-1","rountime"))))))) | DG6: =IF(OR(DF6="away",DF6="home",DF6="draw"),"small",IF(OR(DF6="away",DF6="home",DF6="draw",DF6="draw 1-1",DF6="away 0-2"),"under",IF(DF6="rountime","RT",0))) | DH6: 0 | DI6: =POISSON(DH6,$C$9,FALSE) | DJ6: =$DJ$5*DI6 | DK6: =$DK$5*DI6 | DL6: =$DL$5*DI6 | DM6: =$DM$5*DI6 | DN6: =$DN$5*DI6 | DO6: =$DO$5*DI6 | DP6: =SUM(DN6:DO9,DO10,DM6,DM7,DM8,DL7,DL6,DK6)*100 | DR6: 0.5 | DS6: =DJ6 | DT6: =(DU6-DS6) | DU6: =SUM(DJ6:DO11) | DV6: =DV5+1 | DW6: =SUM(DQ2,DR2,DS2,DT2) | DX6: =DW7-DW6 | DY6: =IF(AND(DY4>DY3,DY5),2.5,IF(AND(DY3>DY4,DY5),1.5,IF(AND(DY5>DY3,DY4),3.5)))
B7: =B6+1 | C7: =Sheet1!N52 | D7: =Sheet1!O52 | E7: 1 | F7: : | G7: 1 | H7: =POISSON(E7,$C$5,FALSE)*POISSON(G7,$D$5,FALSE)*100 | I7: =RANK(H7,$H$5:$H$36,0) | J7: =IF(I5=2,"draw",IF(I6=2,"away",IF(I7=2,"draw 1-1",IF(I8=2,"home",IF(I9=2,"away 0-2",IF(I10=2,"away 1-2",IF(I11=2,"home 2-1","rountime"))))))) | K7: =IF(OR(J7="away",J7="home",J7="draw"),"small",IF(OR(J7="away",J7="home",J7="draw",J7="draw 1-1",J7="away 0-2"),"under",IF(J7="rountime","RT",0))) | L7: =L6+1 | M7: =POISSON(L7,$C$5,FALSE) | N7: =$N$5*M7 | O7: =$O$5*M7 | P7: =$P$5*M7 | Q7: =$Q$5*M7 | R7: =$R$5*M7 | S7: =$S$5*M7 | V7: =V6+1 | W7: =SUM(N6,O6,N7) | X7: =(Y6-W7) | Z7: =Z6+1 | AA7: =SUM(U2,V2,W2,X2,Y2) | AC7: =IF(AC6=AC44,AC6+1,AC6+AC44+0.5) | AD7: 1 | AE7: =AD7+AF7 | AF7: 1 | AG7: =POISSON(AD7,$C$6,FALSE)*POISSON(AF7,$D$6,FALSE)*100 | AH7: =RANK(AG7,$AG$5:$AG$36,0) | AI7: =IF(AH5=2,"draw",IF(AH6=2,"away",IF(AH7=2,"draw 1-1",IF(AH8=2,"home",IF(AH9=2,"away 0-2",IF(AH10=2,"away 1-2",IF(AH11=2,"home 2-1","rountime"))))))) | AJ7: =IF(OR(AI7="away",AI7="home",AI7="draw"),"small",IF(OR(AI7="away",AI7="home",AI7="draw",AI7="draw 1-1",AI7="away 0-2"),"under",IF(AI7="rountime","RT",0))) | AK7: =AK6+1 | AL7: =POISSON(AK7,$C$6,FALSE) | AM7: =$AM$5*AL7 | AN7: =$AN$5*AL7 | AO7: =$AO$5*AL7 | AP7: =$AP$5*AL7 | AQ7: =$AQ$5*AL7 | AR7: =$AR$5*AL7 | AU7: =AU6+1 | AV7: =SUM(AM6,AN6,AM7) | AW7: =(AX6-AV7) | AY7: =AY6+1 | AZ7: =SUM(AT2,AU2,AV2,AW2,AX2) | BB7: =IF(BB6=BB44,BB6+1,BB6+BB44+0.5) | BC7: 1 | BD7: : | BE7: 1 | BF7: =POISSON(BC7,$C$7,FALSE)*POISSON(BE7,$D$7,FALSE)*100 | BG7: =RANK(BF7,$BF$5:$BF$36,0) | BH7: =IF(BG5=2,"draw",IF(BG6=2,"away",IF(BG7=2,"draw 1-1",IF(BG8=2,"home",IF(BG9=2,"away 0-2",IF(BG10=2,"away 1-2",IF(BG11=2,"home 2-1","rountime"))))))) | BI7: =IF(OR(BH7="away",BH7="home",BH7="draw"),"small",IF(OR(BH7="away",BH7="home",BH7="draw",BH7="draw 1-1",BH7="away 0-2"),"under",IF(BH7="rountime","RT",0))) | BJ7: =BJ6+1 | BK7: =POISSON(BJ7,$C$7,FALSE) | BL7: =$BL$5*BK7 | BM7: =$BM$5*BK7 | BN7: =$BN$5*BK7 | BO7: =$BO$5*BK7 | BP7: =$BP$5*BK7 | BQ7: =$BQ$5*BK7 | BT7: =BT6+1 | BU7: =SUM(BL6,BM6,BL7) | BV7: =(BW6-BU7) | BX7: =BX6+1 | BY7: =SUM(BS2,BT2,BU2,BV2,BW2) | CA7: =IF(CA6=CA44,CA6+1,CA6+CA44+0.5) | CB7: 1 | CC7: : | CD7: 1 | CE7: =POISSON(CB7,$C$8,FALSE)*POISSON(CD7,$D$8,FALSE)*100 | CF7: =RANK(CE7,$CE$5:$CE$36,0) | CG7: =IF(CF5=2,"draw",IF(CF6=2,"away",IF(CF7=2,"draw 1-1",IF(CF8=2,"home",IF(CF9=2,"away 0-2",IF(CF10=2,"away 1-2",IF(CF11=2,"home 2-1","rountime"))))))) | CH7: =IF(OR(CG7="away",CG7="home",CG7="draw"),"small",IF(OR(CG7="away",CG7="home",CG7="draw",CG7="draw 1-1",CG7="away 0-2"),"under",IF(CG7="rountime","RT",0))) | CI7: =CI6+1 | CJ7: =POISSON(CI7,$C$8,FALSE) | CK7: =$CK$5*CJ7 | CL7: =$CL$5*CJ7 | CM7: =$CM$5*CJ7 | CN7: =$CN$5*CJ7 | CO7: =$CO$5*CJ7 | CP7: =$CP$5*CJ7 | CS7: =CS6+1 | CT7: =SUM(CK6,CL6,CK7) | CU7: =(CV6-CT7) | CW7: =CW6+1 | CX7: =SUM(CR2,CS2,CT2,CU2,CV2) | CZ7: =IF(CZ6=CZ44,CZ6+1,CZ6+CZ44+0.5) | DA7: 1 | DB7: : | DC7: 1 | DD7: =POISSON(DA7,$C$9,FALSE)*POISSON(DC7,$D$9,FALSE)*100 | DE7: =RANK(DD7,$DD$5:$DD$36,0) | DF7: =IF(DE5=2,"draw",IF(DE6=2,"away",IF(DE7=2,"draw 1-1",IF(DE8=2,"home",IF(DE9=2,"away 0-2",IF(DE10=2,"away 1-2",IF(DE11=2,"home 2-1","rountime"))))))) | DG7: =IF(OR(DF7="away",DF7="home",DF7="draw"),"small",IF(OR(DF7="away",DF7="home",DF7="draw",DF7="draw 1-1",DF7="away 0-2"),"under",IF(DF7="rountime","RT",0))) | DH7: =DH6+1 | DI7: =POISSON(DH7,$C$9,FALSE) | DJ7: =$DJ$5*DI7 | DK7: =$DK$5*DI7 | DL7: =$DL$5*DI7 | DM7: =$DM$5*DI7 | DN7: =$DN$5*DI7 | DO7: =$DO$5*DI7 | DR7: =DR6+1 | DS7: =SUM(DJ6,DK6,DJ7) | DT7: =(DU6-DS7) | DV7: =DV6+1 | DW7: =SUM(DQ2,DR2,DS2,DT2,DU2) | DY7: =IF(DY6=DY44,DY6+1,DY6+DY44+0.5)
B8: =B7+1 | C8: =Sheet1!R52 | D8: =Sheet1!S52 | E8: 1 | F8: : | G8: 0 | H8: =POISSON(E8,$C$5,FALSE)*POISSON(G8,$D$5,FALSE)*100 | I8: =RANK(H8,$H$5:$H$36,0) | J8: =IF(I5=3,"draw",IF(I6=3,"away",IF(I7=3,"draw 1-1",IF(I8=3,"home",IF(I9=3,"away 0-2",IF(I10=3,"away 1-2",IF(I11=3,"home 2-1","rountime"))))))) | K8: =IF(OR(J8="away",J8="home",J8="draw"),"small",IF(OR(J8="away",J8="home",J8="draw",J8="draw 1-1",J8="away 0-2"),"under",IF(J8="rountime","RT",0))) | L8: =L7+1 | M8: =POISSON(L8,$C$5,FALSE) | N8: =$N$5*M8 | O8: =$O$5*M8 | P8: =$P$5*M8 | Q8: =$Q$5*M8 | R8: =$R$5*M8 | S8: =$S$5*M8 | T8: =IF(T2<0.6,"low",IF(T2<1.38,"medium","high")) | V8: =V7+1 | W8: =SUM(N6,O6,P6,N7,N8,O7) | X8: =(Y6-W8) | Y8: =(X6/$Y$16)*100 | Z8: remain | AA8: =Z2-AA7 | AB8: =IF(AA9<0.6,"Under",IF(AA9<0.9,"under+",IF(AND(AA8<0.9,AA9>1,AA9<2.9),"under",IF(AND(AA8<1.5,AA9>0.9,AA9<1.75),"under+","over")))) | AC8: =AVERAGE(AC6,AC7,AC44)+0.666667 | AD8: 1 | AE8: =AD8+AF8 | AF8: 0 | AG8: =POISSON(AD8,$C$6,FALSE)*POISSON(AF8,$D$6,FALSE)*100 | AH8: =RANK(AG8,$AG$5:$AG$36,0) | AI8: =IF(AH5=3,"draw",IF(AH6=3,"away",IF(AH7=3,"draw 1-1",IF(AH8=3,"home",IF(AH9=3,"away 0-2",IF(AH10=3,"away 1-2",IF(AH11=3,"home 2-1","rountime"))))))) | AJ8: =IF(OR(AI8="away",AI8="home",AI8="draw"),"small",IF(OR(AI8="away",AI8="home",AI8="draw",AI8="draw 1-1",AI8="away 0-2"),"under",IF(AI8="rountime","RT",0))) | AK8: =AK7+1 | AL8: =POISSON(AK8,$C$6,FALSE) | AM8: =$AM$5*AL8 | AN8: =$AN$5*AL8 | AO8: =$AO$5*AL8 | AP8: =$AP$5*AL8 | AQ8: =$AQ$5*AL8 | AR8: =$AR$5*AL8 | AS8: =IF(AS2<0.6,"low",IF(AS2<1.38,"medium","high")) | AU8: =AU7+1 | AV8: =SUM(AM6,AN6,AO6,AM7,AM8,AN7) | AW8: =(AX6-AV8) | AX8: =(AW6/$AX$16)*100 | AY8: remain | AZ8: =AY2-AZ7 | BA8: =IF(AZ9<0.6,"Under",IF(AZ9<0.9,"under+",IF(AND(AZ8<0.9,AZ9>1,AZ9<2.9),"under",IF(AND(AZ8<1.5,AZ9>0.9,AZ9<1.75),"under+","over")))) | BB8: =AVERAGE(BB6,BB7,BB44)+0.666667 | BC8: 1 | BD8: : | BE8: 0 | BF8: =POISSON(BC8,$C$7,FALSE)*POISSON(BE8,$D$7,FALSE)*100 | BG8: =RANK(BF8,$BF$5:$BF$36,0) | BH8: =IF(BG5=3,"draw",IF(BG6=3,"away",IF(BG7=3,"draw 1-1",IF(BG8=3,"home",IF(BG9=3,"away 0-2",IF(BG10=3,"away 1-2",IF(BG11=3,"home 2-1","rountime"))))))) | BI8: =IF(OR(BH8="away",BH8="home",BH8="draw"),"small",IF(OR(BH8="away",BH8="home",BH8="draw",BH8="draw 1-1",BH8="away 0-2"),"under",IF(BH8="rountime","RT",0))) | BJ8: =BJ7+1 | BK8: =POISSON(BJ8,$C$7,FALSE) | BL8: =$BL$5*BK8 | BM8: =$BM$5*BK8 | BN8: =$BN$5*BK8 | BO8: =$BO$5*BK8 | BP8: =$BP$5*BK8 | BQ8: =$BQ$5*BK8 | BR8: =IF(BR2<0.6,"low",IF(BR2<1.38,"medium","high")) | BT8: =BT7+1 | BU8: =SUM(BL6,BM6,BN6,BL7,BL8,BM7) | BV8: =(BW6-BU8) | BX8: remain | BY8: =BX2-BY7 | BZ8: =IF(BY9<0.6,"Under",IF(BY9<0.9,"under+",IF(AND(BY8<0.9,BY9>1,BY9<2.9),"under",IF(AND(BY8<1.5,BY9>0.9,BY9<1.75),"under+","over")))) | CA8: =AVERAGE(CA6,CA7,CA44)+0.666667 | CB8: 1 | CC8: : | CD8: 0 | CE8: =POISSON(CB8,$C$8,FALSE)*POISSON(CD8,$D$8,FALSE)*100 | CF8: =RANK(CE8,$CE$5:$CE$36,0) | CG8: =IF(CF5=3,"draw",IF(CF6=3,"away",IF(CF7=3,"draw 1-1",IF(CF8=3,"home",IF(CF9=3,"away 0-2",IF(CF10=3,"away 1-2",IF(CF11=3,"home 2-1","rountime"))))))) | CH8: =IF(OR(CG8="away",CG8="home",CG8="draw"),"small",IF(OR(CG8="away",CG8="home",CG8="draw",CG8="draw 1-1",CG8="away 0-2"),"under",IF(CG8="rountime","RT",0))) | CI8: =CI7+1 | CJ8: =POISSON(CI8,$C$8,FALSE) | CK8: =$CK$5*CJ8 | CL8: =$CL$5*CJ8 | CM8: =$CM$5*CJ8 | CN8: =$CN$5*CJ8 | CO8: =$CO$5*CJ8 | CP8: =$CP$5*CJ8 | CQ8: =IF(CQ2<0.6,"low",IF(CQ2<1.38,"medium","high")) | CS8: =CS7+1 | CT8: =SUM(CK6,CL6,CM6,CK7,CK8,CL7) | CU8: =(CV6-CT8) | CW8: remain | CX8: =CW2-CX7 | CY8: =IF(CX9<0.6,"Under",IF(CX9<0.9,"under+",IF(AND(CX8<0.9,CX9>1,CX9<2.9),"under",IF(AND(CX8<1.5,CX9>0.9,CX9<1.75),"under+","over")))) | CZ8: =AVERAGE(CZ6,CZ7,CZ44)+0.666667 | DA8: 1 | DB8: : | DC8: 0 | DD8: =POISSON(DA8,$C$9,FALSE)*POISSON(DC8,$D$9,FALSE)*100 | DE8: =RANK(DD8,$DD$5:$DD$36,0) | DF8: =IF(DE5=3,"draw",IF(DE6=3,"away",IF(DE7=3,"draw 1-1",IF(DE8=3,"home",IF(DE9=3,"away 0-2",IF(DE10=3,"away 1-2",IF(DE11=3,"home 2-1","rountime"))))))) | DG8: =IF(OR(DF8="away",DF8="home",DF8="draw"),"small",IF(OR(DF8="away",DF8="home",DF8="draw",DF8="draw 1-1",DF8="away 0-2"),"under",IF(DF8="rountime","RT",0))) | DH8: =DH7+1 | DI8: =POISSON(DH8,$C$9,FALSE) | DJ8: =$DJ$5*DI8 | DK8: =$DK$5*DI8 | DL8: =$DL$5*DI8 | DM8: =$DM$5*DI8 | DN8: =$DN$5*DI8 | DO8: =$DO$5*DI8 | DP8: =IF(DP2<0.6,"low",IF(DP2<1.38,"medium","high")) | DR8: =DR7+1 | DS8: =SUM(DJ6,DK6,DL6,DJ7,DJ8,DK7) | DT8: =(DU6-DS8) | DV8: remain | DW8: =DV2-DW7 | DX8: =IF(DW9<0.6,"Under",IF(DW9<0.9,"under+",IF(AND(DW8<0.9,DW9>1,DW9<2.9),"under",IF(AND(DW8<1.5,DW9>0.9,DW9<1.75),"under+","over")))) | DY8: =AVERAGE(DY6,DY7,DY44)+0.666667
B9: =B8+1 | C9: =Sheet1!V52 | D9: =Sheet1!W52 | E9: 0 | F9: : | G9: 2 | H9: =POISSON(E9,$C$5,FALSE)*POISSON(G9,$D$5,FALSE)*100 | I9: =RANK(H9,$H$5:$H$36,0) | J9: =IF(I5=4,"draw",IF(I6=4,"away",IF(I7=4,"draw 1-1",IF(I8=4,"home",IF(I9=4,"away 0-2",IF(I10=4,"away 1-2",IF(I11=4,"home 2-1","rountime"))))))) | K9: =IF(OR(J9="away",J9="home",J9="draw"),"small",IF(OR(J9="away",J9="home",J9="draw",J9="draw 1-1",J9="away 0-2"),"under",IF(J9="rountime","RT",0))) | L9: =L8+1 | M9: =POISSON(L9,$C$5,FALSE) | N9: =$N$5*M9 | O9: =$O$5*M9 | P9: =$P$5*M9 | Q9: =$Q$5*M9 | R9: =$R$5*M9 | S9: =$S$5*M9 | T9: =IF(W6>0.38,"u0.5",IF(W7>0.352,"U1.5",IF(W8>0.5885,"u2.5",IF(W9>0.6871,"U3.5",IF(W10>0.6993,"u4.5","Run"))))) | U9: =IF(X10>0.34,"O4.5",IF(X9>0.6155,"O3.5",IF(X8>0.5063,"O2.5",IF(X7>0.74,"O1.5",IF(X6>0.95,"O0.5","Run"))))) | V9: =V8+1 | W9: =SUM(N6,N7,O6,P6,O7,N8,N9,O8,P7,Q6) | X9: =(Y6-W9) | Y9: =(X7/$Y$16)*100 | AA9: =AA47 | AD9: 0 | AE9: =AD9+AF9 | AF9: 2 | AG9: =POISSON(AD9,$C$6,FALSE)*POISSON(AF9,$D$6,FALSE)*100 | AH9: =RANK(AG9,$AG$5:$AG$36,0) | AI9: =IF(AH5=4,"draw",IF(AH6=4,"away",IF(AH7=4,"draw 1-1",IF(AH8=4,"home",IF(AH9=4,"away 0-2",IF(AH10=4,"away 1-2",IF(AH11=4,"home 2-1","rountime"))))))) | AJ9: =IF(OR(AI9="away",AI9="home",AI9="draw"),"small",IF(OR(AI9="away",AI9="home",AI9="draw",AI9="draw 1-1",AI9="away 0-2"),"under",IF(AI9="rountime","RT",0))) | AK9: =AK8+1 | AL9: =POISSON(AK9,$C$6,FALSE) | AM9: =$AM$5*AL9 | AN9: =$AN$5*AL9 | AO9: =$AO$5*AL9 | AP9: =$AP$5*AL9 | AQ9: =$AQ$5*AL9 | AR9: =$AR$5*AL9 | AS9: =IF(AV6>0.38,"u0.5",IF(AV7>0.352,"U1.5",IF(AV8>0.5885,"u2.5",IF(AV9>0.6871,"U3.5",IF(AV10>0.6993,"u4.5","Run"))))) | AT9: =IF(AW10>0.34,"O4.5",IF(AW9>0.6155,"O3.5",IF(AW8>0.5063,"O2.5",IF(AW7>0.74,"O1.5",IF(AW6>0.95,"O0.5","Run"))))) | AU9: =AU8+1 | AV9: =SUM(AM6,AM7,AN6,AO6,AN7,AM8,AM9,AN8,AO7,AP6) | AW9: =(AX6-AV9) | AX9: =(AW7/$AX$16)*100 | AZ9: =AZ47 | BC9: 0 | BD9: : | BE9: 2 | BF9: =POISSON(BC9,$C$7,FALSE)*POISSON(BE9,$D$7,FALSE)*100 | BG9: =RANK(BF9,$BF$5:$BF$36,0) | BH9: =IF(BG5=4,"draw",IF(BG6=4,"away",IF(BG7=4,"draw 1-1",IF(BG8=4,"home",IF(BG9=4,"away 0-2",IF(BG10=4,"away 1-2",IF(BG11=4,"home 2-1","rountime"))))))) | BI9: =IF(OR(BH9="away",BH9="home",BH9="draw"),"small",IF(OR(BH9="away",BH9="home",BH9="draw",BH9="draw 1-1",BH9="away 0-2"),"under",IF(BH9="rountime","RT",0))) | BJ9: =BJ8+1 | BK9: =POISSON(BJ9,$C$7,FALSE) | BL9: =$BL$5*BK9 | BM9: =$BM$5*BK9 | BN9: =$BN$5*BK9 | BO9: =$BO$5*BK9 | BP9: =$BP$5*BK9 | BQ9: =$BQ$5*BK9 | BR9: =IF(BU6>0.38,"u0.5",IF(BU7>0.352,"U1.5",IF(BU8>0.5885,"u2.5",IF(BU9>0.6871,"U3.5",IF(BU10>0.6993,"u4.5","Run"))))) | BS9: =IF(BV10>0.34,"O4.5",IF(BV9>0.6155,"O3.5",IF(BV8>0.5063,"O2.5",IF(BV7>0.74,"O1.5",IF(BV6>0.95,"O0.5","Run"))))) | BT9: =BT8+1 | BU9: =SUM(BL6,BL7,BM6,BN6,BM7,BL8,BL9,BM8,BN7,BO6) | BV9: =(BW6-BU9) | BY9: =BY47 | CB9: 0 | CC9: : | CD9: 2 | CE9: =POISSON(CB9,$C$8,FALSE)*POISSON(CD9,$D$8,FALSE)*100 | CF9: =RANK(CE9,$CE$5:$CE$36,0) | CG9: =IF(CF5=4,"draw",IF(CF6=4,"away",IF(CF7=4,"draw 1-1",IF(CF8=4,"home",IF(CF9=4,"away 0-2",IF(CF10=4,"away 1-2",IF(CF11=4,"home 2-1","rountime"))))))) | CH9: =IF(OR(CG9="away",CG9="home",CG9="draw"),"small",IF(OR(CG9="away",CG9="home",CG9="draw",CG9="draw 1-1",CG9="away 0-2"),"under",IF(CG9="rountime","RT",0))) | CI9: =CI8+1 | CJ9: =POISSON(CI9,$C$8,FALSE) | CK9: =$CK$5*CJ9 | CL9: =$CL$5*CJ9 | CM9: =$CM$5*CJ9 | CN9: =$CN$5*CJ9 | CO9: =$CO$5*CJ9 | CP9: =$CP$5*CJ9 | CQ9: =IF(CT6>0.38,"u0.5",IF(CT7>0.352,"U1.5",IF(CT8>0.5885,"u2.5",IF(CT9>0.6871,"U3.5",IF(CT10>0.6993,"u4.5","Run"))))) | CR9: =IF(CU10>0.34,"O4.5",IF(CU9>0.6155,"O3.5",IF(CU8>0.5063,"O2.5",IF(CU7>0.74,"O1.5",IF(CU6>0.95,"O0.5","Run"))))) | CS9: =CS8+1 | CT9: =SUM(CK6,CK7,CL6,CM6,CL7,CK8,CK9,CL8,CM7,CN6) | CU9: =(CV6-CT9) | CX9: =CX47 | DA9: 0 | DB9: : | DC9: 2 | DD9: =POISSON(DA9,$C$9,FALSE)*POISSON(DC9,$D$9,FALSE)*100 | DE9: =RANK(DD9,$DD$5:$DD$36,0) | DF9: =IF(DE5=4,"draw",IF(DE6=4,"away",IF(DE7=4,"draw 1-1",IF(DE8=4,"home",IF(DE9=4,"away 0-2",IF(DE10=4,"away 1-2",IF(DE11=4,"home 2-1","rountime"))))))) | DG9: =IF(OR(DF9="away",DF9="home",DF9="draw"),"small",IF(OR(DF9="away",DF9="home",DF9="draw",DF9="draw 1-1",DF9="away 0-2"),"under",IF(DF9="rountime","RT",0))) | DH9: =DH8+1 | DI9: =POISSON(DH9,$C$9,FALSE) | DJ9: =$DJ$5*DI9 | DK9: =$DK$5*DI9 | DL9: =$DL$5*DI9 | DM9: =$DM$5*DI9 | DN9: =$DN$5*DI9 | DO9: =$DO$5*DI9 | DP9: =IF(DS6>0.38,"u0.5",IF(DS7>0.352,"U1.5",IF(DS8>0.5885,"u2.5",IF(DS9>0.6871,"U3.5",IF(DS10>0.6993,"u4.5","Run"))))) | DQ9: =IF(DT10>0.34,"O4.5",IF(DT9>0.6155,"O3.5",IF(DT8>0.5063,"O2.5",IF(DT7>0.74,"O1.5",IF(DT6>0.95,"O0.5","Run"))))) | DR9: =DR8+1 | DS9: =SUM(DJ6,DJ7,DK6,DL6,DK7,DJ8,DJ9,DK8,DL7,DM6) | DT9: =(DU6-DS9) | DW9: =DW47
C10: avrrage | D10: =Sheet1!E45 | E10: 1 | F10: : | G10: 2 | H10: =POISSON(E10,$C$5,FALSE)*POISSON(G10,$D$5,FALSE)*100 | I10: =RANK(H10,$H$5:$H$36,0) | J10: =IF(J6="draw",1,IF(J6="draw 1-1",1,IF(J6="home",2,IF(J6="home 2-1",2,IF(J6="away",3,IF(J6="away 1-2",3,IF(J6="away 0-2",3,0))))))) | K10: =COUNTIF(K6:K9,"small") | L10: =L9+1 | M10: =POISSON(L10,$C$5,FALSE) | N10: =$N$5*M10 | O10: =$O$5*M10 | P10: =$P$5*M10 | Q10: =$Q$5*M10 | R10: =$R$5*M10 | S10: =$S$5*M10 | T10: =IF(W6>0.4,"u0.5",IF(W7>0.52,"U1.5",IF(W8>0.721,"u2.5",IF(W9>0.79775,"U3.5",IF(W10>0.8165,"u4.5","Run"))))) | U10: =IF(X10>0.55,"O4.5",IF(X9>0.69775,"O3.5",IF(X8>0.7,"O2.5",IF(X7>0.79,"O1.5",IF(X6>0.92,"O0.5","Run"))))) | V10: =V9+1 | W10: =SUM(N6,N7,O6,P6,O7,N8,N9,O8,P7,Q6,R6,Q7,P8,O9,N10) | X10: =(Y6-W10) | Y10: =(X8/$Y$16)*100 | Z10: =Y8-U13 | AA10: =IF(Z10<0,1,0) | AD10: 1 | AE10: =AD10+AF10 | AF10: 2 | AG10: =POISSON(AD10,$C$6,FALSE)*POISSON(AF10,$D$6,FALSE)*100 | AH10: =RANK(AG10,$AG$5:$AG$36,0) | AI10: =IF(AI6="draw",1,IF(AI6="draw 1-1",1,IF(AI6="home",2,IF(AI6="home 2-1",2,IF(AI6="away",3,IF(AI6="away 1-2",3,IF(AI6="away 0-2",3,0))))))) | AJ10: =COUNTIF(AJ6:AJ9,"small") | AK10: =AK9+1 | AL10: =POISSON(AK10,$C$6,FALSE) | AM10: =$AM$5*AL10 | AN10: =$AN$5*AL10 | AO10: =$AO$5*AL10 | AP10: =$AP$5*AL10 | AQ10: =$AQ$5*AL10 | AR10: =$AR$5*AL10 | AS10: =IF(AV6>0.4,"u0.5",IF(AV7>0.52,"U1.5",IF(AV8>0.721,"u2.5",IF(AV9>0.79775,"U3.5",IF(AV10>0.8165,"u4.5","Run"))))) | AT10: =IF(AW10>0.55,"O4.5",IF(AW9>0.69775,"O3.5",IF(AW8>0.7,"O2.5",IF(AW7>0.79,"O1.5",IF(AW6>0.92,"O0.5","Run"))))) | AU10: =AU9+1 | AV10: =SUM(AM6,AM7,AN6,AO6,AN7,AM8,AM9,AN8,AO7,AP6,AQ6,AP7,AO8,AN9,AM10) | AW10: =(AX6-AV10) | AX10: =(AW8/$AX$16)*100 | AY10: =AX8-AT13 | AZ10: =IF(AY10<0,1,0) | BC10: 1 | BD10: : | BE10: 2 | BF10: =POISSON(BC10,$C$7,FALSE)*POISSON(BE10,$D$7,FALSE)*100 | BG10: =RANK(BF10,$BF$5:$BF$36,0) | BH10: =IF(BH6="draw",1,IF(BH6="draw 1-1",1,IF(BH6="home",2,IF(BH6="home 2-1",2,IF(BH6="away",3,IF(BH6="away 1-2",3,IF(BH6="away 0-2",3,0))))))) | BI10: =COUNTIF(BI6:BI9,"small") | BJ10: =BJ9+1 | BK10: =POISSON(BJ10,$C$7,FALSE) | BL10: =$BL$5*BK10 | BM10: =$BM$5*BK10 | BN10: =$BN$5*BK10 | BO10: =$BO$5*BK10 | BP10: =$BP$5*BK10 | BQ10: =$BQ$5*BK10 | BR10: =IF(BU6>0.4,"u0.5",IF(BU7>0.52,"U1.5",IF(BU8>0.721,"u2.5",IF(BU9>0.79775,"U3.5",IF(BU10>0.8165,"u4.5","Run"))))) | BS10: =IF(BV10>0.55,"O4.5",IF(BV9>0.69775,"O3.5",IF(BV8>0.7,"O2.5",IF(BV7>0.79,"O1.5",IF(BV6>0.92,"O0.5","Run"))))) | BT10: =BT9+1 | BU10: =SUM(BL6,BL7,BM6,BN6,BM7,BL8,BL9,BM8,BN7,BO6,BP6,BO7,BN8,BM9,BL10) | BV10: =(BW6-BU10) | CB10: 1 | CC10: : | CD10: 2 | CE10: =POISSON(CB10,$C$8,FALSE)*POISSON(CD10,$D$8,FALSE)*100 | CF10: =RANK(CE10,$CE$5:$CE$36,0) | CG10: =IF(CG6="draw",1,IF(CG6="draw 1-1",1,IF(CG6="home",2,IF(CG6="home 2-1",2,IF(CG6="away",3,IF(CG6="away 1-2",3,IF(CG6="away 0-2",3,0))))))) | CH10: =COUNTIF(CH6:CH9,"small") | CI10: =CI9+1 | CJ10: =POISSON(CI10,$C$8,FALSE) | CK10: =$CK$5*CJ10 | CL10: =$CL$5*CJ10 | CM10: =$CM$5*CJ10 | CN10: =$CN$5*CJ10 | CO10: =$CO$5*CJ10 | CP10: =$CP$5*CJ10 | CQ10: =IF(CT6>0.4,"u0.5",IF(CT7>0.52,"U1.5",IF(CT8>0.721,"u2.5",IF(CT9>0.79775,"U3.5",IF(CT10>0.8165,"u4.5","Run"))))) | CR10: =IF(CU10>0.55,"O4.5",IF(CU9>0.69775,"O3.5",IF(CU8>0.7,"O2.5",IF(CU7>0.79,"O1.5",IF(CU6>0.92,"O0.5","Run"))))) | CS10: =CS9+1 | CT10: =SUM(CK6,CK7,CL6,CM6,CL7,CK8,CK9,CL8,CM7,CN6,CO6,CN7,CM8,CL9,CK10) | CU10: =(CV6-CT10) | DA10: 1 | DB10: : | DC10: 2 | DD10: =POISSON(DA10,$C$9,FALSE)*POISSON(DC10,$D$9,FALSE)*100 | DE10: =RANK(DD10,$DD$5:$DD$36,0) | DF10: =IF(DF6="draw",1,IF(DF6="draw 1-1",1,IF(DF6="home",2,IF(DF6="home 2-1",2,IF(DF6="away",3,IF(DF6="away 1-2",3,IF(DF6="away 0-2",3,0))))))) | DG10: =COUNTIF(DG6:DG9,"small") | DH10: =DH9+1 | DI10: =POISSON(DH10,$C$9,FALSE) | DJ10: =$DJ$5*DI10 | DK10: =$DK$5*DI10 | DL10: =$DL$5*DI10 | DM10: =$DM$5*DI10 | DN10: =$DN$5*DI10 | DO10: =$DO$5*DI10 | DP10: =IF(DS6>0.4,"u0.5",IF(DS7>0.52,"U1.5",IF(DS8>0.721,"u2.5",IF(DS9>0.79775,"U3.5",IF(DS10>0.8165,"u4.5","Run"))))) | DQ10: =IF(DT10>0.55,"O4.5",IF(DT9>0.69775,"O3.5",IF(DT8>0.7,"O2.5",IF(DT7>0.79,"O1.5",IF(DT6>0.92,"O0.5","Run"))))) | DR10: =DR9+1 | DS10: =SUM(DJ6,DJ7,DK6,DL6,DK7,DJ8,DJ9,DK8,DL7,DM6,DN6,DM7,DL8,DK9,DJ10) | DT10: =(DU6-DS10)
D11: =IF(D10>1.28,"High scoring league",IF(D10<1.1,"low scoring","medium")) | E11: 2 | F11: : | G11: 1 | H11: =POISSON(E11,$C$5,FALSE)*POISSON(G11,$D$5,FALSE)*100 | I11: =RANK(H11,$H$5:$H$36,0) | J11: =IF(J7="draw",1,IF(J7="draw 1-1",1,IF(J7="home",2,IF(J7="home 2-1",2,IF(J7="away",3,IF(J7="away 1-2",3,IF(J7="away 0-2",3,0))))))) | K11: =COUNTIF(K6:K9,"under") | L11: =L10+1 | M11: =POISSON(L11,$C$5,FALSE) | N11: =$N$5*M11 | O11: =$O$5*M11 | P11: =$P$5*M11 | Q11: =$Q$5*M11 | R11: =$R$5*M11 | S11: =$S$5*M11 | V11: decision | W11: =IF(W6>0.46,"u0.5",IF(W7>0.688,"U1.5",IF(W8>0.855,"u2.5",IF(W9>0.908,"U3.5",IF(W10>0.93,"u4.5","Run"))))) | X11: =IF(X10>0.77,"O4.5",IF(X9>0.79,"O3.5",IF(X8>0.84,"O2.5",IF(X7>0.855,"O1.5",IF(X6>0.88,"O0.5","Run"))))) | Y11: =(X9/$Y$16)*100 | Z11: =Y9-U14 | AA11: =IF(Z11<0,1,0) | AD11: 2 | AE11: =AD11+AF11 | AF11: 1 | AG11: =POISSON(AD11,$C$6,FALSE)*POISSON(AF11,$D$6,FALSE)*100 | AH11: =RANK(AG11,$AG$5:$AG$36,0) | AI11: =IF(AI7="draw",1,IF(AI7="draw 1-1",1,IF(AI7="home",2,IF(AI7="home 2-1",2,IF(AI7="away",3,IF(AI7="away 1-2",3,IF(AI7="away 0-2",3,0))))))) | AJ11: =COUNTIF(AJ6:AJ9,"under") | AK11: =AK10+1 | AL11: =POISSON(AK11,$C$6,FALSE) | AM11: =$AM$5*AL11 | AN11: =$AN$5*AL11 | AO11: =$AO$5*AL11 | AP11: =$AP$5*AL11 | AQ11: =$AQ$5*AL11 | AR11: =$AR$5*AL11 | AU11: decision | AV11: =IF(AV6>0.46,"u0.5",IF(AV7>0.688,"U1.5",IF(AV8>0.855,"u2.5",IF(AV9>0.908,"U3.5",IF(AV10>0.93,"u4.5","Run"))))) | AW11: =IF(AW10>0.77,"O4.5",IF(AW9>0.79,"O3.5",IF(AW8>0.84,"O2.5",IF(AW7>0.855,"O1.5",IF(AW6>0.88,"O0.5","Run"))))) | AX11: =(AW9/$AX$16)*100 | AY11: =AX9-AT14 | AZ11: =IF(AY11<0,1,0) | BC11: 2 | BD11: : | BE11: 1 | BF11: =POISSON(BC11,$C$7,FALSE)*POISSON(BE11,$D$7,FALSE)*100 | BG11: =RANK(BF11,$BF$5:$BF$36,0) | BH11: =IF(BH7="draw",1,IF(BH7="draw 1-1",1,IF(BH7="home",2,IF(BH7="home 2-1",2,IF(BH7="away",3,IF(BH7="away 1-2",3,IF(BH7="away 0-2",3,0))))))) | BI11: =COUNTIF(BI6:BI9,"under") | BJ11: =BJ10+1 | BK11: =POISSON(BJ11,$C$7,FALSE) | BL11: =$BL$5*BK11 | BM11: =$BM$5*BK11 | BN11: =$BN$5*BK11 | BO11: =$BO$5*BK11 | BP11: =$BP$5*BK11 | BQ11: =$BQ$5*BK11 | BT11: decision | BU11: =IF(BU6>0.46,"u0.5",IF(BU7>0.688,"U1.5",IF(BU8>0.855,"u2.5",IF(BU9>0.908,"U3.5",IF(BU10>0.93,"u4.5","Run"))))) | BV11: =IF(BV10>0.77,"O4.5",IF(BV9>0.79,"O3.5",IF(BV8>0.84,"O2.5",IF(BV7>0.855,"O1.5",IF(BV6>0.88,"O0.5","Run"))))) | CB11: 2 | CC11: : | CD11: 1 | CE11: =POISSON(CB11,$C$8,FALSE)*POISSON(CD11,$D$8,FALSE)*100 | CF11: =RANK(CE11,$CE$5:$CE$36,0) | CG11: =IF(CG7="draw",1,IF(CG7="draw 1-1",1,IF(CG7="home",2,IF(CG7="home 2-1",2,IF(CG7="away",3,IF(CG7="away 1-2",3,IF(CG7="away 0-2",3,0))))))) | CH11: =COUNTIF(CH6:CH9,"under") | CI11: =CI10+1 | CJ11: =POISSON(CI11,$C$8,FALSE) | CK11: =$CK$5*CJ11 | CL11: =$CL$5*CJ11 | CM11: =$CM$5*CJ11 | CN11: =$CN$5*CJ11 | CO11: =$CO$5*CJ11 | CP11: =$CP$5*CJ11 | CS11: decision | CT11: =IF(CT6>0.46,"u0.5",IF(CT7>0.688,"U1.5",IF(CT8>0.855,"u2.5",IF(CT9>0.908,"U3.5",IF(CT10>0.93,"u4.5","Run"))))) | CU11: =IF(CU10>0.77,"O4.5",IF(CU9>0.79,"O3.5",IF(CU8>0.84,"O2.5",IF(CU7>0.855,"O1.5",IF(CU6>0.88,"O0.5","Run"))))) | DA11: 2 | DB11: : | DC11: 1 | DD11: =POISSON(DA11,$C$9,FALSE)*POISSON(DC11,$D$9,FALSE)*100 | DE11: =RANK(DD11,$DD$5:$DD$36,0) | DF11: =IF(DF7="draw",1,IF(DF7="draw 1-1",1,IF(DF7="home",2,IF(DF7="home 2-1",2,IF(DF7="away",3,IF(DF7="away 1-2",3,IF(DF7="away 0-2",3,0))))))) | DG11: =COUNTIF(DG6:DG9,"under") | DH11: =DH10+1 | DI11: =POISSON(DH11,$C$9,FALSE) | DJ11: =$DJ$5*DI11 | DK11: =$DK$5*DI11 | DL11: =$DL$5*DI11 | DM11: =$DM$5*DI11 | DN11: =$DN$5*DI11 | DO11: =$DO$5*DI11 | DR11: decision | DS11: =IF(DS6>0.46,"u0.5",IF(DS7>0.688,"U1.5",IF(DS8>0.855,"u2.5",IF(DS9>0.908,"U3.5",IF(DS10>0.93,"u4.5","Run"))))) | DT11: =IF(DT10>0.77,"O4.5",IF(DT9>0.79,"O3.5",IF(DT8>0.84,"O2.5",IF(DT7>0.855,"O1.5",IF(DT6>0.88,"O0.5","Run")))))
E12: 1 | F12: : | G12: 3 | H12: =POISSON(E12,$C$5,FALSE)*POISSON(G12,$D$5,FALSE)*100 | I12: =RANK(H12,$H$5:$H$36,0) | J12: =IF(J8="draw",1,IF(J8="draw 1-1",1,IF(J8="home",2,IF(J8="home 2-1",2,IF(J8="away",3,IF(J8="away 1-2",3,IF(J8="away 0-2",3,0))))))) | K12: =COUNTIF(K6:K9,"0") | M12: =IF(N12>0.9,"waw1",IF(N12>0.85,"waw",IF(N12>0.74,"high",IF(N12>0.64,"medium",IF(N12>0.54,"low",IF(N12<0,"win","off")))))) | N12: =CORREL(N6:S11,N44:S49) | O12: =IF(AND(M12="waw1",M13>0.8,OR(H39="high1",H39="high"),N13>0.489),"all met",IF(AND(M12="high",M13>0.8,N13>0.49,OR(H39="high",H39="high1")),"met","check")) | P12: =SUM(N6:S11) | Q12: =SUM(N8:O11,N7,P9,P10,P11,Q10,Q11,R11)*100 | T12: =SUM(N6,O7,P8,Q9,R10,S11)*100 | W12: YES | X12: NO | Y12: =(X10/$Y$16)*100 | Z12: =Y10-U15 | AA12: =IF(Z12<0,1,0) | AD12: 1 | AE12: =AD12+AF12 | AF12: 3 | AG12: =POISSON(AD12,$C$6,FALSE)*POISSON(AF12,$D$6,FALSE)*100 | AH12: =RANK(AG12,$AG$5:$AG$36,0) | AI12: =IF(AI8="draw",1,IF(AI8="draw 1-1",1,IF(AI8="home",2,IF(AI8="home 2-1",2,IF(AI8="away",3,IF(AI8="away 1-2",3,IF(AI8="away 0-2",3,0))))))) | AJ12: =COUNTIF(AJ6:AJ9,"0") | AL12: =IF(AM12>0.9,"waw1",IF(AM12>0.85,"waw",IF(AM12>0.74,"high",IF(AM12>0.64,"medium",IF(AM12>0.54,"low",IF(AM12<0,"win","off")))))) | AM12: =CORREL(AM6:AR11,AM44:AR49) | AN12: =IF(AND(AL12="waw1",AL13>0.8,OR(AG39="high1",AG39="high"),AM13>0.489),"all met",IF(AND(AL12="high",AL13>0.8,AM13>0.49,OR(AG39="high",AG39="high1")),"met","check")) | AP12: =SUM(AM8:AN11,AM7,AO9,AO10,AO11,AP10,AP11,AQ11)*100 | AS12: =SUM(AM6,AN7,AO8,AP9,AQ10,AR11)*100 | AV12: YES | AW12: NO | AX12: =(AW10/$AX$16)*100 | AY12: =AX10-AT15 | AZ12: =IF(AY12<0,1,0) | BC12: 1 | BD12: : | BE12: 3 | BF12: =POISSON(BC12,$C$7,FALSE)*POISSON(BE12,$D$7,FALSE)*100 | BG12: =RANK(BF12,$BF$5:$BF$36,0) | BH12: =IF(BH8="draw",1,IF(BH8="draw 1-1",1,IF(BH8="home",2,IF(BH8="home 2-1",2,IF(BH8="away",3,IF(BH8="away 1-2",3,IF(BH8="away 0-2",3,0))))))) | BI12: =COUNTIF(BI6:BI9,"0") | BK12: =IF(BL12>0.9,"waw1",IF(BL12>0.85,"waw",IF(BL12>0.74,"high",IF(BL12>0.64,"medium",IF(BL12>0.54,"low",IF(BL12<0,"win","off")))))) | BL12: =CORREL(BL6:BQ11,BL44:BQ49) | BM12: =IF(AND(BK12="waw1",BK13>0.8,OR(BF39="high1",BF39="high"),BL13>0.489),"all met",IF(AND(BK12="high",BK13>0.8,BL13>0.49,OR(BF39="high",BF39="high1")),"met","check")) | BO12: =SUM(BL8:BM11,BL7,BN9,BN10,BN11,BO10,BO11,BP11)*100 | BR12: =SUM(BL6,BM7,BN8,BO9,BP10,BQ11)*100 | BU12: YES | BV12: NO | CB12: 1 | CC12: : | CD12: 3 | CE12: =POISSON(CB12,$C$8,FALSE)*POISSON(CD12,$D$8,FALSE)*100 | CF12: =RANK(CE12,$CE$5:$CE$36,0) | CG12: =IF(CG8="draw",1,IF(CG8="draw 1-1",1,IF(CG8="home",2,IF(CG8="home 2-1",2,IF(CG8="away",3,IF(CG8="away 1-2",3,IF(CG8="away 0-2",3,0))))))) | CH12: =COUNTIF(CH6:CH9,"0") | CJ12: =IF(CK12>0.9,"waw1",IF(CK12>0.85,"waw",IF(CK12>0.74,"high",IF(CK12>0.64,"medium",IF(CK12>0.54,"low",IF(CK12<0,"win","off")))))) | CK12: =CORREL(CK6:CP11,CK44:CP49) | CL12: =IF(AND(CJ12="waw1",CJ13>0.8,OR(CE39="high1",CE39="high"),CK13>0.489),"all met",IF(AND(CJ12="high",CJ13>0.8,CK13>0.49,OR(CE39="high",CE39="high1")),"met","check")) | CN12: =SUM(CK8:CL11,CK7,CM9,CM10,CM11,CN10,CN11,CO11)*100 | CQ12: =SUM(CK6,CL7,CM8,CN9,CO10,CP11)*100 | CT12: YES | CU12: NO | DA12: 1 | DB12: : | DC12: 3 | DD12: =POISSON(DA12,$C$9,FALSE)*POISSON(DC12,$D$9,FALSE)*100 | DE12: =RANK(DD12,$DD$5:$DD$36,0) | DF12: =IF(DF8="draw",1,IF(DF8="draw 1-1",1,IF(DF8="home",2,IF(DF8="home 2-1",2,IF(DF8="away",3,IF(DF8="away 1-2",3,IF(DF8="away 0-2",3,0))))))) | DG12: =COUNTIF(DG6:DG9,"0") | DI12: =IF(DJ12>0.9,"waw1",IF(DJ12>0.85,"waw",IF(DJ12>0.74,"high",IF(DJ12>0.64,"medium",IF(DJ12>0.54,"low",IF(DJ12<0,"win","off")))))) | DJ12: =CORREL(DJ6:DO11,DJ44:DO49) | DK12: =IF(AND(DI12="waw1",DI13>0.8,OR(DD39="high1",DD39="high"),DJ13>0.489),"all met",IF(AND(DI12="high",DI13>0.8,DJ13>0.49,OR(DD39="high",DD39="high1")),"met","check")) | DM12: =SUM(DJ8:DK11,DJ7,DL9,DL10,DL11,DM10,DM11,DN11)*100 | DP12: =SUM(DJ6,DK7,DL8,DM9,DN10,DO11)*100 | DS12: YES | DT12: NO
C13: home | D13: away | E13: 2 | F13: : | G13: 2 | H13: =POISSON(E13,$C$5,FALSE)*POISSON(G13,$D$5,FALSE)*100 | I13: =RANK(H13,$H$5:$H$36,0) | J13: =IF(J9="draw",1,IF(J9="draw 1-1",1,IF(J9="home",2,IF(J9="home 2-1",2,IF(J9="away",3,IF(J9="away 1-2",3,IF(J9="away 0-2",3,0))))))) | K13: =COUNTIF(K6:K9,"rt") | M13: =CORREL(M6:M11,N5:S5) | N13: =TTEST(N6:S11,N44:S49,1,2) | O13: =ABS(M13-N12) | P13: decision | Q13: =IF(Q12>75,"1",IF(Q12>54,"1X",IF(Q12>49,"Hadicap 2H",IF(T6>75,"2",IF(T6>54,"X2",IF(T6>49,"Handiap 2A",IF(T12>75,"X",IF(T12>60,"likely X",IF(T12<13,"12","don’t choose"))))))))) | R13: =IF(AND(Q13="don’t choose",Q51="don’t choose"),"+1","") | U13: =(W6/$Y$16)*100 | V13: BTS | W13: =SUM(O7:S11) | X13: =SUM(N6:S6,N7:N11) | Z13: =Y11-U16 | AA13: =IF(Z13<0,1,0) | AD13: 2 | AE13: =AD13+AF13 | AF13: 2 | AG13: =POISSON(AD13,$C$6,FALSE)*POISSON(AF13,$D$6,FALSE)*100 | AH13: =RANK(AG13,$AG$5:$AG$36,0) | AI13: =IF(AI9="draw",1,IF(AI9="draw 1-1",1,IF(AI9="home",2,IF(AI9="home 2-1",2,IF(AI9="away",3,IF(AI9="away 1-2",3,IF(AI9="away 0-2",3,0))))))) | AJ13: =COUNTIF(AJ6:AJ9,"rt") | AL13: =CORREL(AL6:AL11,AM5:AR5) | AM13: =TTEST(AM6:AR11,AM44:AR49,1,2) | AN13: =ABS(AL13-AM12) | AO13: decision | AP13: =IF(AP12>75,"1",IF(AP12>54,"1X",IF(AP12>49,"Hadicap 2H",IF(AS6>75,"2",IF(AS6>54,"X2",IF(AS6>49,"Handiap 2A",IF(AS12>75,"X",IF(AS12>60,"likely X",IF(AS12<13,"12","don’t choose"))))))))) | AT13: =(AV6/$AX$16)*100 | AU13: BTS | AV13: =SUM(AN7:AR11) | AW13: =SUM(AM6:AR6,AM7:AM11) | AY13: =AX11-AT16 | AZ13: =IF(AY13<0,1,0) | BC13: 2 | BD13: : | BE13: 2 | BF13: =POISSON(BC13,$C$7,FALSE)*POISSON(BE13,$D$7,FALSE)*100 | BG13: =RANK(BF13,$BF$5:$BF$36,0) | BH13: =IF(BH9="draw",1,IF(BH9="draw 1-1",1,IF(BH9="home",2,IF(BH9="home 2-1",2,IF(BH9="away",3,IF(BH9="away 1-2",3,IF(BH9="away 0-2",3,0))))))) | BI13: =COUNTIF(BI6:BI9,"rt") | BK13: =CORREL(BK6:BK11,BL5:BQ5) | BL13: =TTEST(BL6:BQ11,BL44:BQ49,1,2) | BM13: =ABS(BK13-BL12) | BN13: decision | BO13: =IF(BO12>75,"1",IF(BO12>54,"1X",IF(BO12>49,"Hadicap 2H",IF(BR6>75,"2",IF(BR6>54,"X2",IF(BR6>49,"Handiap 2A",IF(BR12>75,"X",IF(BR12>60,"likely X",IF(BR12<13,"12","don’t choose"))))))))) | BT13: BTS | BU13: =SUM(BM7:BQ11) | BV13: =SUM(BL6:BQ6,BL7:BL11) | CB13: 2 | CC13: : | CD13: 2 | CE13: =POISSON(CB13,$C$8,FALSE)*POISSON(CD13,$D$8,FALSE)*100 | CF13: =RANK(CE13,$CE$5:$CE$36,0) | CG13: =IF(CG9="draw",1,IF(CG9="draw 1-1",1,IF(CG9="home",2,IF(CG9="home 2-1",2,IF(CG9="away",3,IF(CG9="away 1-2",3,IF(CG9="away 0-2",3,0))))))) | CH13: =COUNTIF(CH6:CH9,"rt") | CJ13: 0.85794109 | CK13: =TTEST(CK6:CP11,CK44:CP49,1,2) | CL13: =ABS(CJ13-CK12) | CM13: decision | CN13: =IF(CN12>75,"1",IF(CN12>54,"1X",IF(CN12>49,"Hadicap 2H",IF(CQ6>75,"2",IF(CQ6>54,"X2",IF(CQ6>49,"Handiap 2A",IF(CQ12>75,"X",IF(CQ12>60,"likely X",IF(CQ12<13,"12","don’t choose"))))))))) | CS13: BTS | CT13: =SUM(CL7:CP11) | CU13: =SUM(CK6:CP6,CK7:CK11) | DA13: 2 | DB13: : | DC13: 2 | DD13: =POISSON(DA13,$C$9,FALSE)*POISSON(DC13,$D$9,FALSE)*100 | DE13: =RANK(DD13,$DD$5:$DD$36,0) | DF13: =IF(DF9="draw",1,IF(DF9="draw 1-1",1,IF(DF9="home",2,IF(DF9="home 2-1",2,IF(DF9="away",3,IF(DF9="away 1-2",3,IF(DF9="away 0-2",3,0))))))) | DG13: =COUNTIF(DG6:DG9,"rt") | DJ13: =TTEST(DJ6:DO11,DJ44:DO49,1,2) | DK13: =ABS(DI13-DJ12) | DL13: decision | DM13: =IF(DM12>75,"1",IF(DM12>54,"1X",IF(DM12>49,"Hadicap 2H",IF(DP6>75,"2",IF(DP6>54,"X2",IF(DP6>49,"Handiap 2A",IF(DP12>75,"X",IF(DP12>60,"likely X",IF(DP12<13,"12","don’t choose"))))))))) | DR13: BTS | DS13: =SUM(DK7:DO11) | DT13: =SUM(DJ6:DO6,DJ7:DJ11)
C14: =Sheet1!G59 | D14: =Sheet1!F59 | E14: 3 | F14: : | G14: 1 | H14: =POISSON(E14,$C$5,FALSE)*POISSON(G14,$D$5,FALSE)*100 | I14: =RANK(H14,$H$5:$H$36,0) | J14: =SUM(J10:J13) | K14: =IF(K13>0,"Rt",IF(K10>3,"u2.5",IF(AND(K10>2,K11>0),"u2.5",IF(AND(K11>K10,K11>K12),"u3.5",IF(AND(K12>K11,K12>K10),"o2.5","u4.5"))))) | L14: =Q12/M15 | M14: =T12/M15 | N14: =T6/M15 | O14: =IF(AND(O12="all met",O13<0.7),"all met","not met") | Q14: =SUM(N6:N11,O7:O11,P8:P11,Q9:Q11,R10:R11,S11) | R14: =SUM(S6:S11,R6:R10,Q6:Q9,P6:P8,O6:O7,N6) | S14: =SUM(Q14,R14) | U14: =(W7/$Y$16)*100 | V14: decision | W14: =IF(X13>0.8,"NO GG",IF(W13>0.81,"GG","run")) | Z14: =Y12-U17 | AA14: =IF(Z14<0,1,0) | AD14: 3 | AE14: =AD14+AF14 | AF14: 1 | AG14: =POISSON(AD14,$C$6,FALSE)*POISSON(AF14,$D$6,FALSE)*100 | AH14: =RANK(AG14,$AG$5:$AG$36,0) | AI14: =SUM(AI10:AI13) | AJ14: =IF(AJ13>0,"Rt",IF(AJ10>3,"u2.5",IF(AND(AJ10>2,AJ11>0),"u2.5",IF(AND(AJ11>AJ10,AJ11>AJ12),"u3.5",IF(AND(AJ12>AJ11,AJ12>AJ10),"o2.5","u4.5"))))) | AK14: =AP12/AL15 | AL14: =AS12/AL15 | AM14: =AS6/AL15 | AN14: =IF(AND(AN12="all met",AN13<0.7),"all met","not met") | AP14: =SUM(AM6:AM11,AN7:AN11,AO8:AO11,AP9:AP11,AQ10:AQ11,AR11) | AQ14: =SUM(AR6:AR11,AQ6:AQ10,AP6:AP9,AO6:AO8,AN6:AN7,AM6) | AR14: =SUM(AP14,AQ14) | AT14: =(AV7/$AX$16)*100 | AU14: decision | AV14: =IF(AW13>0.8,"NO GG",IF(AV13>0.81,"GG","run")) | AY14: =AX12-AT17 | AZ14: =IF(AY14<0,1,0) | BC14: 3 | BD14: : | BE14: 1 | BF14: =POISSON(BC14,$C$7,FALSE)*POISSON(BE14,$D$7,FALSE)*100 | BG14: =RANK(BF14,$BF$5:$BF$36,0) | BH14: =SUM(BH10:BH13) | BI14: =IF(BI13>0,"Rt",IF(BI10>3,"u2.5",IF(AND(BI10>2,BI11>0),"u2.5",IF(AND(BI11>BI10,BI11>BI12),"u3.5",IF(AND(BI12>BI11,BI12>BI10),"o2.5","u4.5"))))) | BJ14: =BO12/BK15 | BK14: =BR12/BK15 | BL14: =BR6/BK15 | BM14: =IF(AND(BM12="all met",BM13<0.7),"all met","not met") | BO14: =SUM(BL6:BL11,BM7:BM11,BN8:BN11,BO9:BO11,BP10:BP11,BQ11) | BP14: =SUM(BQ6:BQ11,BP6:BP10,BO6:BO9,BN6:BN8,BM6:BM7,BL6) | BQ14: =SUM(BO14,BP14) | BT14: decision | BU14: =IF(BV13>0.8,"NO GG",IF(BU13>0.81,"GG","run")) | CB14: 3 | CC14: : | CD14: 1 | CE14: =POISSON(CB14,$C$8,FALSE)*POISSON(CD14,$D$8,FALSE)*100 | CF14: =RANK(CE14,$CE$5:$CE$36,0) | CG14: =SUM(CG10:CG13) | CH14: =IF(CH13>0,"Rt",IF(CH10>3,"u2.5",IF(AND(CH10>2,CH11>0),"u2.5",IF(AND(CH11>CH10,CH11>CH12),"u3.5",IF(AND(CH12>CH11,CH12>CH10),"o2.5","u4.5"))))) | CI14: =CN12/CJ15 | CJ14: =CQ12/CJ15 | CK14: =CQ6/CJ15 | CL14: =IF(AND(CL12="all met",CL13<0.7),"all met","not met") | CN14: =SUM(CK6:CK11,CL7:CL11,CM8:CM11,CN9:CN11,CO10:CO11,CP11) | CO14: =SUM(CP6:CP11,CO6:CO10,CN6:CN9,CM6:CM8,CL6:CL7,CK6) | CP14: =SUM(CN14,CO14) | CS14: decision | CT14: =IF(CU13>0.8,"NO GG",IF(CT13>0.81,"GG","run")) | DA14: 3 | DB14: : | DC14: 1 | DD14: =POISSON(DA14,$C$9,FALSE)*POISSON(DC14,$D$9,FALSE)*100 | DE14: =RANK(DD14,$DD$5:$DD$36,0) | DF14: =SUM(DF10:DF13) | DG14: =IF(DG13>0,"Rt",IF(DG10>3,"u2.5",IF(AND(DG10>2,DG11>0),"u2.5",IF(AND(DG11>DG10,DG11>DG12),"u3.5",IF(AND(DG12>DG11,DG12>DG10),"o2.5","u4.5"))))) | DH14: =DM12/DI15 | DI14: =DP12/DI15 | DJ14: =DP6/DI15 | DK14: =IF(AND(DK12="all met",DK13<0.7),"all met","not met") | DM14: =SUM(DJ6:DJ11,DK7:DK11,DL8:DL11,DM9:DM11,DN10:DN11,DO11) | DN14: =SUM(DO6:DO11,DN6:DN10,DM6:DM9,DL6:DL8,DK6:DK7,DJ6) | DO14: =SUM(DM14,DN14) | DR14: decision | DS14: =IF(DT13>0.8,"NO GG",IF(DS13>0.81,"GG","run"))
C15: =Sheet1!K59 | D15: =Sheet1!J59 | E15: 3 | F15: : | G15: 0 | H15: =POISSON(E15,$C$5,FALSE)*POISSON(G15,$D$5,FALSE)*100 | I15: =RANK(H15,$H$5:$H$36,0) | J15: =IF(J10=2,3,J10) | K15: =IF((K10+K11)>3,"firm",IF((K10+K11+K12)>3,"in line","check")) | L15: =M15-(L14/100) | M15: =SUM(N6:S11) | N15: =M15-(N14/100) | P15: calc | Q15: =Q14-R14 | R15: =S15/(S15+S15)*100 | S15: =IF(Q15<0,-Q15,Q15) | U15: =(W8/$Y$16)*100 | V15: odd | W15: even | X15: =SUM(X6:X10) | Y15: =(W9/X16)*100 | Z15: =Z10-ABS(Z14) | AA15: =IF(AND(Z15<0,AY15<0),"both",IF(Z15<0,"Yes1",IF(OR(Z15<0,AY15<0),"yes","no"))) | AC15: =IF(AC16="no, no",1,IF(AC16="no, yes",2,3)) | AD15: 3 | AE15: =AD15+AF15 | AF15: 0 | AG15: =POISSON(AD15,$C$6,FALSE)*POISSON(AF15,$D$6,FALSE)*100 | AH15: =RANK(AG15,$AG$5:$AG$36,0) | AI15: =IF(AI10=2,3,AI10) | AJ15: =IF((AJ10+AJ11)>3,"firm",IF((AJ10+AJ11+AJ12)>3,"in line","check")) | AK15: =AL15-(AK14/100) | AL15: =SUM(AM6:AR11) | AM15: =AL15-(AM14/100) | AO15: calc | AP15: =AP14-AQ14 | AQ15: =AR15/(AR15+AR15)*100 | AR15: =IF(AP15<0,-AP15,AP15) | AT15: =(AV8/$AX$16)*100 | AU15: odd | AV15: even | AW15: =SUM(AW6:AW10) | AX15: =(AV7/AW16)*100 | AY15: =AY10-ABS(AY14) | BB15: =IF(BB16="no, no",1,IF(BB16="no, yes",2,3)) | BC15: 3 | BD15: : | BE15: 0 | BF15: =POISSON(BC15,$C$7,FALSE)*POISSON(BE15,$D$7,FALSE)*100 | BG15: =RANK(BF15,$BF$5:$BF$36,0) | BH15: =IF(BH10=2,3,BH10) | BI15: =IF((BI10+BI11)>3,"firm",IF((BI10+BI11+BI12)>3,"in line","check")) | BJ15: =BK15-(BJ14/100) | BK15: =SUM(BL6:BQ11) | BL15: =BK15-(BL14/100) | BN15: calc | BO15: =BO14-BP14 | BP15: =BQ15/(BQ15+BQ15)*100 | BQ15: =IF(BO15<0,-BO15,BO15) | BT15: odd | BU15: even | CA15: =IF(CA16="no, no",1,IF(CA16="no, yes",2,3)) | CB15: 3 | CC15: : | CD15: 0 | CE15: =POISSON(CB15,$C$8,FALSE)*POISSON(CD15,$D$8,FALSE)*100 | CF15: =RANK(CE15,$CE$5:$CE$36,0) | CG15: =IF(CG10=2,3,CG10) | CH15: =IF((CH10+CH11)>3,"firm",IF((CH10+CH11+CH12)>3,"in line","check")) | CI15: =CJ15-(CI14/100) | CJ15: =SUM(CK6:CP11) | CK15: =CJ15-(CK14/100) | CM15: calc | CN15: =CN14-CO14 | CO15: =CP15/(CP15+CP15)*100 | CP15: =IF(CN15<0,-CN15,CN15) | CS15: odd | CT15: even | CZ15: =IF(CZ16="no, no",1,IF(CZ16="no, yes",2,3)) | DA15: 3 | DB15: : | DC15: 0 | DD15: =POISSON(DA15,$C$9,FALSE)*POISSON(DC15,$D$9,FALSE)*100 | DE15: =RANK(DD15,$DD$5:$DD$36,0) | DF15: =IF(DF10=2,3,DF10) | DG15: =IF((DG10+DG11)>3,"firm",IF((DG10+DG11+DG12)>3,"in line","check")) | DH15: =DI15-(DH14/100) | DI15: =SUM(DJ6:DO11) | DJ15: =DI15-(DJ14/100) | DL15: calc | DM15: =DM14-DN14 | DN15: =DO15/(DO15+DO15)*100 | DO15: =IF(DM15<0,-DM15,DM15) | DR15: odd | DS15: even
