Workbook

Sheet Sheet1
A1: =IF(OR(C2>3.5,D2>3.5,D1>3.5),"wow",IF(AND(C2>2,D2>2,D1>2),"yes",IF(C2=MAX(C2,D2,D1),1,IF(D2=MAX(C2,D2,D1),2,IF(D1=MAX(C2,D2,D1),3,""))))) -> 2 | B1: =IF(OR(E2>3.5,F2>3.5,F1>3.5),"wow",IF(AND(E2>2,F2>2,F1>2),"yes",IF(E2=MAX(E2,F2,F1),1,IF(F2=MAX(E2,F2,F1),2,IF(F1=MAX(E2,F2,F1),3,""))))) -> 1 | C1: =$E46-D1 -> 0.97017496 | D1: =AVERAGE(C2,D2) -> 1.790825 | E1: =$E46-F1 -> 1.0365824 | F1: =AVERAGE(E2,F2) -> 1.7244176 | G1: =$E46-H1 -> 1.0365824 | H1: =AVERAGE(G2,H2) -> 1.7244176 | I1: =$E46-J1 -> 0.97017496 | J1: =AVERAGE(I2,J2) -> 1.790825 | K1: =$E46-L1 -> -0.17934784 | L1: =AVERAGE(K2,L2) -> 2.9403478
A2: =IF(OR(G2>3.5,H2>3.5,H1>3.5),"wow",IF(AND(G2>2,H2>2,H1>2),"yes",IF(G2=MAX(G2,H2,H1),1,IF(H2=MAX(G2,H2,H1),2,IF(H1=MAX(G2,H2,H1),3,""))))) -> 1 | B2: =IF(OR(I2>3.5,J2>3.5,J1>3.5),"wow",IF(AND(I2>2,J2>2,J1>2),"yes",IF(I2=MAX(I2,J2,J1),1,IF(J2=MAX(I2,J2,J1),2,IF(J1=MAX(I2,J2,J1),3,""))))) -> 2 | C2: =VLOOKUP(F48,$C6:$V42,14)+VLOOKUP(F48,C6:V42,16)*1.35 -> 1.6607836 | D2: =VLOOKUP(G48,$C6:$V42,16)+VLOOKUP(G48,$C6:$V42,14)*1.35 -> 1.9208664 | E2: =VLOOKUP(J48,$C6:$V42,14)+VLOOKUP(J48,$C6:$V42,16)*1.35 -> 1.7759814 | F2: =VLOOKUP(K48,$C6:$V42,16)+VLOOKUP(K48,$C6:$V42,14)*1.35 -> 1.6728537 | G2: =VLOOKUP(N48,$C6:$V42,14)+VLOOKUP(N48,$C6:$V42,16)*1.35 -> 1.7759814 | H2: =VLOOKUP(O48,$C6:$V42,16)+VLOOKUP(O48,$C6:$V42,14)*1.35 -> 1.6728537 | I2: =VLOOKUP(R48,$C6:$V42,14)+VLOOKUP(R48,$C6:$V42,16)*1.35 -> 1.6607836 | J2: =VLOOKUP(S48,$C6:$V42,16)+VLOOKUP(S48,$C6:$V42,14)*1.35 -> 1.9208664 | K2: =VLOOKUP(V48,$C6:$V42,14)+VLOOKUP(V48,$C6:$V42,16)*1.35 -> 2.8566624 | L2: =VLOOKUP(W48,$C6:$V42,16)+VLOOKUP(W48,$C6:$V42,14)*1.35 -> 3.0240332
A3: =IF(OR(K2>3.5,L2>3.5,L1>3.5),"wow",IF(AND(K2>2,L2>2,L1>2),"yes",IF(K2=MAX(K2,L2,L1),1,IF(L2=MAX(K2,L2,L1),2,IF(L1=MAX(K2,L2,L1),3,""))))) -> yes | B3: =IF(OR(A64="",Sheet2!AA15="no"),"",Sheet2!N2) -> bad | C3: Goals per match
A4: =_xlfn.TEXTJOIN(" /", ,IF(AND(A113="yes",E74=""),"+2",IF(AND(A113="yes",OR(E74="u2.5",E74="u3.5",E74="u4.5",E74="u5.5",E74="u6.5")),"+1",IF(AND(A113="yes",E74<>""),E74,"no"))),_xlfn.IFERROR(E74,""),A79,IF(Sheet2!M71="under",Sheet2!M77,Sheet2!M71)) -> no /nope /none | B4: =_xlfn.TEXTJOIN(" /", ,H104,_xlfn.IFERROR(E114,""),B115) -> low /yes /8 | D4: GP | E4: Average goals overall | I4: Average goals at home | M4: Average goals away | P4: home | Q4: home | R4: away | S4: away | T4: Home advantage | AB4: Points per game | AD4: 2.25 | AF4: 1.6 | AI4: Points per game | AK4: 2.2 | AM4: 1.03
A5: =_xlfn.TEXTJOIN("/ ", ,Sheet2!Y25,Sheet2!BW25) -> Add/ Add | B5: =IF(A74<51,"",IF(B70="","",IF(AND(T89="yes",U89="Yes"),"",_xlfn.TEXTJOIN("+ ", ,Sheet2!S3,M106,N106)))) | E5: Scored | F5: Conc. | G5: Total | I5: Scored | J5: Conc. | K5: Total | M5: Scored | N5: Conc. | O5: Total | P5: att | Q5: defend | R5: att | S5: defend | T5: HA | U5: =COUNT(C6:S6) -> 14 | AB5: % Wins | AD5: 0.75 | AF5: 0.47 | AI5: % Wins | AK5: 0.6 | AM5: 0.28
A6: =IF(Sheet2!F40="coup","just Add 1 goal","clean") -> just Add 1 goal | B6: =_xlfn.TEXTJOIN(" ,", , ,Sheet2!V25,D46) -> check ,3.8115605 | C6: Birmingham L. | D6: 10 | E6: 1.1 | F6: 1.2 | G6: 2.3 | I6: 0.67 | J6: 0.67 | K6: 1.33 | M6: 1.75 | N6: 2 | O6: 3.75 | P6: =I6/$I$44 -> 0.4160457 | Q6: =J6/$J$44 -> 0.57679063 | R6: =M6/$M$44 -> 1.5138408 | S6: =N6/$N$44 -> 1.2543904 | T6: =IF((I6-M6)/D6<0,0*(I6-M6)/D6,(I6-M6)/D6) -> 0 | V6: =IF(K6>0,AVERAGE(K6,O6)," ") -> 2.54 | AB6: % Draws | AD6: 0 | AF6: 0.18 | AI6: % Draws | AK6: 0.4 | AM6: 0.2
C7: Brooklyn FC | D7: 11 | E7: 1 | F7: 1.82 | G7: 2.82 | I7: 1 | J7: 0.83 | K7: 1.83 | M7: 1 | N7: 3 | O7: 4 | P7: =I7/$I$44 -> 0.62096374 | Q7: =J7/$J$44 -> 0.71453168 | R7: =M7/$M$44 -> 0.8650519 | S7: =N7/$N$44 -> 1.8815855 | T7: =IF((I7-M7)/D7<0,0*(I7-M7)/D7,(I7-M7)/D7) -> 0 | V7: =IF(K7>0,AVERAGE(K7,O7)," ") -> 2.915 | AB7: % Defeats | AD7: 0.25 | AF7: 0.35 | AI7: % Defeats | AK7: 0 | AM7: 0.52
C8: Charleston | D8: 10 | E8: 1.4 | F8: 1.3 | G8: 2.7 | I8: 2.4 | J8: 0.8 | K8: 3.2 | M8: 0.4 | N8: 1.8 | O8: 2.2 | P8: =I8/$I$44 -> 1.490313 | Q8: =J8/$J$44 -> 0.68870523 | R8: =M8/$M$44 -> 0.34602076 | S8: =N8/$N$44 -> 1.1289513 | T8: =IF((I8-M8)/D8<0,0*(I8-M8)/D8,(I8-M8)/D8) -> 0.2 | V8: =IF(K8>0,AVERAGE(K8,O8)," ") -> 2.7 | AB8: Goals scored per game | AD8: 1.75 | AF8: 1.97 | AI8: Goals scored per game | AK8: 1.8 | AM8: 1.2
C9: Colorado S. | D9: 10 | E9: 1.8 | F9: 1.7 | G9: 3.5 | I9: 2.5 | J9: 1.5 | K9: 4 | M9: 1.33 | N9: 1.83 | O9: 3.17 | P9: =I9/$I$44 -> 1.5524093 | Q9: =J9/$J$44 -> 1.2913223 | R9: =M9/$M$44 -> 1.150519 | S9: =N9/$N$44 -> 1.1477672 | T9: =IF((I9-M9)/D9<0,0*(I9-M9)/D9,(I9-M9)/D9) -> 0.117 | V9: =IF(K9>0,AVERAGE(K9,O9)," ") -> 3.585 | AB9: Goals conceded per game | AD9: 1.25 | AF9: 1.57 | AI9: Goals conceded per game | AK9: 0.4 | AM9: 1.57
A10: =IF(B10>AVERAGE(D6:D42),"no","yes") -> no | B10: =ROUND(((COUNTA(C6:C42)-1)*((COUNTA(C6:C42)-1)*2))/38,0) -> 30 | C10: Detroit City | D10: 11 | E10: 1.09 | F10: 0.91 | G10: 2 | I10: 1.8 | J10: 0.4 | K10: 2.2 | M10: 0.5 | N10: 1.33 | O10: 1.83 | P10: =I10/$I$44 -> 1.1177347 | Q10: =J10/$J$44 -> 0.34435262 | R10: =M10/$M$44 -> 0.43252595 | S10: =N10/$N$44 -> 0.83416959 | T10: =IF((I10-M10)/D10<0,0*(I10-M10)/D10,(I10-M10)/D10) -> 0.11818182 | V10: =IF(K10>0,AVERAGE(K10,O10)," ") -> 2.015 | AB10: % Clean sheets | AD10: 0.5 | AF10: 0.26 | AI10: % Clean sheets | AK10: 0.6 | AM10: 0.24
C11: El Paso | D11: 10 | E11: 2.1 | F11: 2 | G11: 4.1 | I11: 1.8 | J11: 3 | K11: 4.8 | M11: 2.4 | N11: 1 | O11: 3.4 | P11: =I11/$I$44 -> 1.1177347 | Q11: =J11/$J$44 -> 2.5826446 | R11: =M11/$M$44 -> 2.0761246 | S11: =N11/$N$44 -> 0.62719518 | T11: =IF((I11-M11)/D11<0,0*(I11-M11)/D11,(I11-M11)/D11) -> 0 | V11: =IF(K11>0,AVERAGE(K11,O11)," ") -> 4.1 | AB11: % Failed To Score | AD11: 0 | AF11: 0.14 | AI11: % Failed To Score | AK11: 0 | AM11: 0.34
C12: FC Tulsa | D12: 10 | E12: 1.3 | F12: 0.9 | G12: 2.2 | I12: 1.2 | J12: 0.8 | K12: 2 | M12: 1.4 | N12: 1 | O12: 2.4 | P12: =I12/$I$44 -> 0.74515648 | Q12: =J12/$J$44 -> 0.68870523 | R12: =M12/$M$44 -> 1.2110727 | S12: =N12/$N$44 -> 0.62719518 | T12: =IF((I12-M12)/D12<0,0*(I12-M12)/D12,(I12-M12)/D12) -> 0 | V12: =IF(K12>0,AVERAGE(K12,O12)," ") -> 2.2 | AB12: % Won To Nil | AD12: 0.5 | AF12: 0.24 | AI12: % Won To Nil | AK12: 0.6 | AM12: 0.17
C13: Hartford A. | D13: 10 | E13: 0.9 | F13: 1 | G13: 1.9 | I13: 0.8 | J13: 1.4 | K13: 2.2 | M13: 1 | N13: 0.6 | O13: 1.6 | P13: =I13/$I$44 -> 0.49677099 | Q13: =J13/$J$44 -> 1.2052342 | R13: =M13/$M$44 -> 0.8650519 | S13: =N13/$N$44 -> 0.37631711 | T13: =IF((I13-M13)/D13<0,0*(I13-M13)/D13,(I13-M13)/D13) -> 0 | V13: =IF(K13>0,AVERAGE(K13,O13)," ") -> 1.9 | AB13: % Lost To Nil | AD13: 0 | AF13: 0.11 | AI13: % Lost To Nil | AK13: 0 | AM13: 0.27
C14: Indy Eleven | D14: 10 | E14: 1.6 | F14: 1.1 | G14: 2.7 | I14: 2 | J14: 0.83 | K14: 2.83 | M14: 1 | N14: 1.5 | O14: 2.5 | P14: =I14/$I$44 -> 1.2419275 | Q14: =J14/$J$44 -> 0.71453168 | R14: =M14/$M$44 -> 0.8650519 | S14: =N14/$N$44 -> 0.94079277 | T14: =IF((I14-M14)/D14<0,0*(I14-M14)/D14,(I14-M14)/D14) -> 0.1 | V14: =IF(K14>0,AVERAGE(K14,O14)," ") -> 2.665 | AB14: Total goals per game | AD14: 3 | AF14: 3.54 | AI14: % Team scored first | AK14: 1 | AM14: 0.36
C15: Las Vegas L. | D15: 11 | E15: 1.45 | F15: 1.73 | G15: 3.18 | I15: 1.2 | J15: 0.4 | K15: 1.6 | M15: 1.67 | N15: 2.83 | O15: 4.5 | P15: =I15/$I$44 -> 0.74515648 | Q15: =J15/$J$44 -> 0.34435262 | R15: =M15/$M$44 -> 1.4446367 | S15: =N15/$N$44 -> 1.7749624 | T15: =IF((I15-M15)/D15<0,0*(I15-M15)/D15,(I15-M15)/D15) -> 0 | V15: =IF(K15>0,AVERAGE(K15,O15)," ") -> 3.05 | AB15: % over 1.5 goals | AD15: 0.75 | AF15: 0.88 | AI15: % Opponent scored first | AK15: 0 | AM15: 0.57
C16: Lexington | D16: 11 | E16: 1.36 | F16: 1.36 | G16: 2.73 | I16: 1.6 | J16: 1.2 | K16: 2.8 | M16: 1.17 | N16: 1.5 | O16: 2.67 | P16: =I16/$I$44 -> 0.99354198 | Q16: =J16/$J$44 -> 1.0330579 | R16: =M16/$M$44 -> 1.0121107 | S16: =N16/$N$44 -> 0.94079277 | T16: =IF((I16-M16)/D16<0,0*(I16-M16)/D16,(I16-M16)/D16) -> 0.039090909 | V16: =IF(K16>0,AVERAGE(K16,O16)," ") -> 2.735 | AB16: % over 2.5 goals | AD16: 0.5 | AF16: 0.74 | AI16: Total goals per game | AK16: 2.2 | AM16: 2.77
C17: Loudoun Utd | D17: 10 | E17: 1.2 | F17: 1.7 | G17: 2.9 | I17: 1.5 | J17: 1.67 | K17: 3.17 | M17: 0.75 | N17: 1.75 | O17: 2.5 | P17: =I17/$I$44 -> 0.9314456 | Q17: =J17/$J$44 -> 1.4376722 | R17: =M17/$M$44 -> 0.64878893 | S17: =N17/$N$44 -> 1.0975916 | T17: =IF((I17-M17)/D17<0,0*(I17-M17)/D17,(I17-M17)/D17) -> 0.075 | V17: =IF(K17>0,AVERAGE(K17,O17)," ") -> 2.835 | AB17: % over 3.5 goals | AD17: 0.25 | AF17: 0.51 | AI17: % over 1.5 goals | AK17: 0.8 | AM17: 0.76
C18: Louisville City | D18: 12 | E18: 1.67 | F18: 1.67 | G18: 3.33 | I18: 1.5 | J18: 1.5 | K18: 3 | M18: 1.83 | N18: 1.83 | O18: 3.67 | P18: =I18/$I$44 -> 0.9314456 | Q18: =J18/$J$44 -> 1.2913223 | R18: =M18/$M$44 -> 1.583045 | S18: =N18/$N$44 -> 1.1477672 | T18: =IF((I18-M18)/D18<0,0*(I18-M18)/D18,(I18-M18)/D18) -> 0 | V18: =IF(K18>0,AVERAGE(K18,O18)," ") -> 3.335 | AB18: % both teams scored | AD18: 0.5 | AF18: 0.62 | AI18: % over 2.5 goals | AK18: 0.4 | AM18: 0.55
C19: Miami FC | D19: 12 | E19: 1.25 | F19: 1.58 | G19: 2.83 | I19: 1.8 | J19: 1.8 | K19: 3.6 | M19: 0.86 | N19: 1.43 | O19: 2.29 | P19: =I19/$I$44 -> 1.1177347 | Q19: =J19/$J$44 -> 1.5495868 | R19: =M19/$M$44 -> 0.74394464 | S19: =N19/$N$44 -> 0.89688911 | T19: =IF((I19-M19)/D19<0,0*(I19-M19)/D19,(I19-M19)/D19) -> 0.078333333 | V19: =IF(K19>0,AVERAGE(K19,O19)," ") -> 2.945 | AB19: % Team scored first | AD19: 0.5 | AF19: 0.56 | AI19: % over 3.5 goals | AK19: 0 | AM19: 0.29
C20: Monterey Bay | D20: 11 | E20: 1 | F20: 1.73 | G20: 2.73 | I20: 1.17 | J20: 1.17 | K20: 2.33 | M20: 0.8 | N20: 2.4 | O20: 3.2 | P20: =I20/$I$44 -> 0.72652757 | Q20: =J20/$J$44 -> 1.0072314 | R20: =M20/$M$44 -> 0.69204152 | S20: =N20/$N$44 -> 1.5052684 | T20: =IF((I20-M20)/D20<0,0*(I20-M20)/D20,(I20-M20)/D20) -> 0.033636364 | V20: =IF(K20>0,AVERAGE(K20,O20)," ") -> 2.765 | AB20: % Opponent scored first | AD20: 0.5 | AF20: 0.42 | AI20: % both teams scored | AK20: 0.4 | AM20: 0.49
C21: New Mexico | D21: 10 | E21: 1.1 | F21: 1.2 | G21: 2.3 | I21: 1.8 | J21: 1.2 | K21: 3 | M21: 0.4 | N21: 1.2 | O21: 1.6 | P21: =I21/$I$44 -> 1.1177347 | Q21: =J21/$J$44 -> 1.0330579 | R21: =M21/$M$44 -> 0.34602076 | S21: =N21/$N$44 -> 0.75263422 | T21: =IF((I21-M21)/D21<0,0*(I21-M21)/D21,(I21-M21)/D21) -> 0.14 | V21: =IF(K21>0,AVERAGE(K21,O21)," ") -> 2.3 | AB21: Average minute scored first | AD21: 48 | AF21: 24
C22: Oakland Roots | D22: 11 | E22: 1.64 | F22: 1.45 | G22: 3.09 | I22: 1.5 | J22: 1.17 | K22: 2.67 | M22: 1.8 | N22: 1.8 | O22: 3.6 | P22: =I22/$I$44 -> 0.9314456 | Q22: =J22/$J$44 -> 1.0072314 | R22: =M22/$M$44 -> 1.5570934 | S22: =N22/$N$44 -> 1.1289513 | T22: =IF((I22-M22)/D22<0,0*(I22-M22)/D22,(I22-M22)/D22) -> 0 | V22: =IF(K22>0,AVERAGE(K22,O22)," ") -> 3.135 | AB22: Average minute conceded first | AD22: 13 | AF22: 27
C23: Orange County | D23: 11 | E23: 1.27 | F23: 0.91 | G23: 2.18 | I23: 1.17 | J23: 0.67 | K23: 1.83 | M23: 1.4 | N23: 1.2 | O23: 2.6 | P23: =I23/$I$44 -> 0.72652757 | Q23: =J23/$J$44 -> 0.57679063 | R23: =M23/$M$44 -> 1.2110727 | S23: =N23/$N$44 -> 0.75263422 | T23: =IF((I23-M23)/D23<0,0*(I23-M23)/D23,(I23-M23)/D23) -> 0 | V23: =IF(K23>0,AVERAGE(K23,O23)," ") -> 2.215 | AB23: Lead-defending rate | AD23: 0.75 | AF23: 0.6
C24: Phoenix Rising | D24: 11 | E24: 1.36 | F24: 1.09 | G24: 2.45 | I24: 1.8 | J24: 0.8 | K24: 2.6 | M24: 1 | N24: 1.33 | O24: 2.33 | P24: =I24/$I$44 -> 1.1177347 | Q24: =J24/$J$44 -> 0.68870523 | R24: =M24/$M$44 -> 0.8650519 | S24: =N24/$N$44 -> 0.83416959 | T24: =IF((I24-M24)/D24<0,0*(I24-M24)/D24,(I24-M24)/D24) -> 0.072727273 | V24: =IF(K24>0,AVERAGE(K24,O24)," ") -> 2.465 | AB24: Equalizing rate | AD24: 0.67 | AF24: 0.43
C25: Pittsburgh | D25: 10 | E25: 1.4 | F25: 1.3 | G25: 2.7 | I25: 1.75 | J25: 1 | K25: 2.75 | M25: 1.17 | N25: 1.5 | O25: 2.67 | P25: =I25/$I$44 -> 1.0866865 | Q25: =J25/$J$44 -> 0.86088154 | R25: =M25/$M$44 -> 1.0121107 | S25: =N25/$N$44 -> 0.94079277 | T25: =IF((I25-M25)/D25<0,0*(I25-M25)/D25,(I25-M25)/D25) -> 0.058 | V25: =IF(K25>0,AVERAGE(K25,O25)," ") -> 2.71 | AB25: % Time leading | AD25: 0.4 | AF25: 0.37
C26: Rhode Island | D26: 10 | E26: 1.7 | F26: 1.4 | G26: 3.1 | I26: 1.83 | J26: 1 | K26: 2.83 | M26: 1.5 | N26: 2 | O26: 3.5 | P26: =I26/$I$44 -> 1.1363636 | Q26: =J26/$J$44 -> 0.86088154 | R26: =M26/$M$44 -> 1.2975779 | S26: =N26/$N$44 -> 1.2543904 | T26: =IF((I26-M26)/D26<0,0*(I26-M26)/D26,(I26-M26)/D26) -> 0.033 | V26: =IF(K26>0,AVERAGE(K26,O26)," ") -> 3.165 | AB26: % Time level in goals | AD26: 0.47 | AF26: 0.4
C27: Sacramento R. | D27: 10 | E27: 1.2 | F27: 1.1 | G27: 2.3 | I27: 1.8 | J27: 1 | K27: 2.8 | M27: 0.6 | N27: 1.2 | O27: 1.8 | P27: =I27/$I$44 -> 1.1177347 | Q27: =J27/$J$44 -> 0.86088154 | R27: =M27/$M$44 -> 0.51903114 | S27: =N27/$N$44 -> 0.75263422 | T27: =IF((I27-M27)/D27<0,0*(I27-M27)/D27,(I27-M27)/D27) -> 0.12 | V27: =IF(K27>0,AVERAGE(K27,O27)," ") -> 2.3 | AB27: % Time trailing | AD27: 0.13 | AF27: 0.23
C28: San Antonio | D28: 12 | E28: 1.5 | F28: 1.17 | G28: 2.67 | I28: 1.67 | J28: 0.83 | K28: 2.5 | M28: 1.33 | N28: 1.5 | O28: 2.83 | P28: =I28/$I$44 -> 1.0370094 | Q28: =J28/$J$44 -> 0.71453168 | R28: =M28/$M$44 -> 1.150519 | S28: =N28/$N$44 -> 0.94079277 | T28: =IF((I28-M28)/D28<0,0*(I28-M28)/D28,(I28-M28)/D28) -> 0.028333333 | V28: =IF(K28>0,AVERAGE(K28,O28)," ") -> 2.665 | AB28: PPG when scored first | AD28: 3 | AF28: 2.23
C29: Sporting JAX | D29: 11 | E29: 1.09 | F29: 2.36 | G29: 3.45 | I29: 1.6 | J29: 2.8 | K29: 4.4 | M29: 0.67 | N29: 2 | O29: 2.67 | P29: =I29/$I$44 -> 0.99354198 | Q29: =J29/$J$44 -> 2.4104683 | R29: =M29/$M$44 -> 0.57958478 | S29: =N29/$N$44 -> 1.2543904 | T29: =IF((I29-M29)/D29<0,0*(I29-M29)/D29,(I29-M29)/D29) -> 0.084545455 | V29: =IF(K29>0,AVERAGE(K29,O29)," ") -> 3.535 | AB29: PPG when conceded first | AD29: 1.5 | AF29: 0.8
C30: Tampa Bay | D30: 11 | E30: 1.73 | F30: 0.45 | G30: 2.18 | I30: 2.4 | J30: 0.6 | K30: 3 | M30: 1.17 | N30: 0.33 | O30: 1.5 | P30: =I30/$I$44 -> 1.490313 | Q30: =J30/$J$44 -> 0.51652893 | R30: =M30/$M$44 -> 1.0121107 | S30: =N30/$N$44 -> 0.20697441 | T30: =IF((I30-M30)/D30<0,0*(I30-M30)/D30,(I30-M30)/D30) -> 0.11181818 | V30: =IF(K30>0,AVERAGE(K30,O30)," ") -> 2.25
P31: =I31/$I$44 -> 0 | Q31: =J31/$J$44 -> 0 | R31: =M31/$M$44 -> 0 | S31: =N31/$N$44 -> 0 | T31: =IF((I31-M31)/D31<0,0*(I31-M31)/D31,(I31-M31)/D31) -> #DIV/0! | V31: =IF(K31>0,AVERAGE(K31,O31)," ")
P32: =I32/$I$44 -> 0 | Q32: =J32/$J$44 -> 0 | R32: =M32/$M$44 -> 0 | S32: =N32/$N$44 -> 0 | T32: =IF((I32-M32)/D32<0,0*(I32-M32)/D32,(I32-M32)/D32) -> #DIV/0! | V32: =IF(K32>0,AVERAGE(K32,O32)," ")
P33: =I33/$I$44 -> 0 | Q33: =J33/$J$44 -> 0 | R33: =M33/$M$44 -> 0 | S33: =N33/$N$44 -> 0 | T33: =IF((I33-M33)/D33<0,0*(I33-M33)/D33,(I33-M33)/D33) -> #DIV/0! | V33: =IF(K33>0,AVERAGE(K33,O33)," ")
P34: =I34/$I$44 -> 0 | Q34: =J34/$J$44 -> 0 | R34: =M34/$M$44 -> 0 | S34: =N34/$N$44 -> 0 | T34: =IF((I34-M34)/D34<0,0*(I34-M34)/D34,(I34-M34)/D34) -> #DIV/0! | V34: =IF(K34>0,AVERAGE(K34,O34)," ")
P35: =I35/$I$44 -> 0 | Q35: =J35/$J$44 -> 0 | R35: =M35/$M$44 -> 0 | S35: =N35/$N$44 -> 0 | T35: =IF((I35-M35)/D35<0,0*(I35-M35)/D35,(I35-M35)/D35) -> #DIV/0! | V35: =IF(K35>0,AVERAGE(K35,O35)," ")
P36: =I36/$I$44 -> 0 | Q36: =J36/$J$44 -> 0 | R36: =M36/$M$44 -> 0 | S36: =N36/$N$44 -> 0 | T36: =IF((I36-M36)/D36<0,0*(I36-M36)/D36,(I36-M36)/D36) -> #DIV/0! | V36: =IF(K36>0,AVERAGE(K36,O36)," ")
P37: =I37/$I$44 -> 0 | Q37: =J37/$J$44 -> 0 | R37: =M37/$M$44 -> 0 | S37: =N37/$N$44 -> 0 | T37: =IF((I37-M37)/D37<0,0*(I37-M37)/D37,(I37-M37)/D37) -> #DIV/0! | V37: =IF(K37>0,AVERAGE(K37,O37)," ")
P38: =I38/$I$44 -> 0 | Q38: =J38/$J$44 -> 0 | R38: =M38/$M$44 -> 0 | S38: =N38/$N$44 -> 0 | T38: =IF((I38-M38)/D38<0,0*(I38-M38)/D38,(I38-M38)/D38) -> #DIV/0! | V38: =IF(K38>0,AVERAGE(K38,O38)," ")
P39: =I39/$I$44 -> 0 | Q39: =J39/$J$44 -> 0 | R39: =M39/$M$44 -> 0 | S39: =N39/$N$44 -> 0 | T39: =IF((I39-M39)/D39<0,0*(I39-M39)/D39,(I39-M39)/D39) -> #DIV/0! | V39: =IF(K39>0,AVERAGE(K39,O39)," ")
P40: =I40/$I$44 -> 0 | Q40: =J40/$J$44 -> 0 | R40: =M40/$M$44 -> 0 | S40: =N40/$N$44 -> 0 | T40: =IF((I40-M40)/D40<0,0*(I40-M40)/D40,(I40-M40)/D40) -> #DIV/0! | V40: =IF(K40>0,AVERAGE(K40,O40)," ")
...

Sheet Sheet2
Q1: =AVERAGE(N8:O11,N7,P9,P10,P11,Q10,Q11,R11) -> 0.032421813 | R1: =AVERAGE(N6,O7,P8,Q9,R10,S11) -> 0.04736083 | S1: =AVERAGE(R6:S9,S10,Q6,Q7,Q8,P7,P6,O6) -> 0.015126798 | U1: 0 | V1: =U1+1 -> 1 | W1: =V1+1 -> 2 | X1: =W1+1 -> 3 | Y1: =X1+1 -> 4 | AP1: =AVERAGE(AM8:AN11,AM7,AO9,AO10,AO11,AP10,AP11,AQ11) -> 0.024571383 | AQ1: =AVERAGE(AM6,AN7,AO8,AP9,AQ10,AR11) -> 0.032121981 | AR1: =AVERAGE(AQ6:AR9,AR10,AP6,AP7,AP8,AO7,AO6,AN6) -> 0.025501746 | AT1: 0 | AU1: =AT1+1 -> 1 | AV1: =AU1+1 -> 2 | AW1: =AV1+1 -> 3 | AX1: =AW1+1 -> 4 | BS1: 0 | BT1: =BS1+1 -> 1 | BU1: =BT1+1 -> 2 | BV1: =BU1+1 -> 3 | BW1: =BV1+1 -> 4 | CR1: 0 | CS1: =CR1+1 -> 1 | CT1: =CS1+1 -> 2 | CU1: =CT1+1 -> 3 | CV1: =CU1+1 -> 4 | DQ1: 0 | DR1: =DQ1+1 -> 1 | DS1: =DR1+1 -> 2 | DT1: =DS1+1 -> 3 | DU1: =DT1+1 -> 4
N2: =IF(AND(O3<>"bad",O16>67,Sheet1!H104<>"high",Y25<>"D'over",OR(Sheet1!B5="",Sheet1!B70="")),"good+1",IF(AND(O3<>"bad",O16>67,Sheet1!H104<>"high",Y25<>"D'over"),"good","bad")) -> bad | O2: =IF(AND(Sheet1!E114="yes",Sheet1!B115<14),"ok","no") -> ok | P2: 1 | Q2: =AVERAGE(C5,Q1) -> 0.67701573 | R2: =(Sheet1!N105/1000)+Q3 -> 0.06836053 | S2: =AVERAGE(S1,D5) -> 0.40896777 | T2: =AVERAGE(C5,D5) -> 1.0622092 | U2: =POISSON(U1,$T$2,FALSE)*100 -> 34.569127 | V2: =POISSON(V1,$T$2,FALSE)*100 -> 36.719644 | W2: =POISSON(W1,$T$2,FALSE)*100 -> 19.501972 | X2: =POISSON(X1,$T$2,FALSE)*100 -> 6.9050579 | Y2: =POISSON(Y1,$T$2,FALSE)*100 -> 1.833654 | Z2: =SUM(U2:Y2,U4:Y4) -> 99.999981 | AN2: 2 | AP2: =AVERAGE(AP1,C6) -> 1.1368937 | AR2: =AVERAGE(AR1,D6) -> 1.1597668 | AS2: =AVERAGE(C6,D6) -> 2.2716239 | AT2: =POISSON(AT1,$AS$2,FALSE)*100 -> 10.314454 | AU2: =POISSON(AU1,$AS$2,FALSE)*100 -> 23.430561 | AV2: =POISSON(AV1,$AS$2,FALSE)*100 -> 26.612712 | AW2: =POISSON(AW1,$AS$2,FALSE)*100 -> 20.151358 | AX2: =POISSON(AX1,$AS$2,FALSE)*100 -> 11.444077 | AY2: =SUM(AT2:AX2,AT4:AX4) -> 99.986961 | BM2: 3 | BR2: =AVERAGE(C7,D7) -> 2.2716239 | BS2: =POISSON(BS1,$BR$2,FALSE)*100 -> 10.314454 | BT2: =POISSON(BT1,$BR$2,FALSE)*100 -> 23.430561 | BU2: =POISSON(BU1,$BR$2,FALSE)*100 -> 26.612712 | BV2: =POISSON(BV1,$BR$2,FALSE)*100 -> 20.151358 | BW2: =POISSON(BW1,$BR$2,FALSE)*100 -> 11.444077 | BX2: =SUM(BS2:BW2,BS4:BW4) -> 99.986961 | CL2: 4 | CQ2: =AVERAGE(C8,D8) -> 1.0622092 | CR2: =POISSON(CR1,$CQ$2,FALSE)*100 -> 34.569127 | CS2: =POISSON(CS1,$CQ$2,FALSE)*100 -> 36.719644 | CT2: =POISSON(CT1,$CQ$2,FALSE)*100 -> 19.501972 | CU2: =POISSON(CU1,$CQ$2,FALSE)*100 -> 6.9050579 | CV2: =POISSON(CV1,$CQ$2,FALSE)*100 -> 1.833654 | CW2: =SUM(CR2:CV2,CR4:CV4) -> 99.999981 | DK2: 5 | DP2: =AVERAGE(C9,D9) -> #N/A | DQ2: =POISSON(DQ1,$DP$2,FALSE)*100 -> #N/A | DR2: =POISSON(DR1,$DP$2,FALSE)*100 -> #N/A | DS2: =POISSON(DS1,$DP$2,FALSE)*100 -> #N/A | DT2: =POISSON(DT1,$DP$2,FALSE)*100 -> #N/A | DU2: =POISSON(DU1,$DP$2,FALSE)*100 -> #N/A | DV2: =SUM(DQ2:DU2,DQ4:DU4) -> #N/A
F3: 1 | O3: =IF(AND(O2="ok",P3="yes1"),"wow",IF(AND(O2="ok",P3="yes"),"good","bad")) -> bad | P3: =IF(AND(Sheet1!M106<>"F",S3="F"),"yes1",IF(AND(S3<>"F",Sheet1!M106<>"F"),"yes","no")) -> no | Q3: =AR3-AP3 -> 0.14546053 | R3: =(ABS(R2))*100+(Sheet1!I106)*10 -> 24.650267 | S3: =IF(R3<30,"A",IF(R3<34,"B",IF(R3<40,"C","F"))) -> A | T3: =C5-D5 -> 0.51880091 | U3: 5 | V3: =U3+1 -> 6 | W3: =V3+1 -> 7 | X3: =W3+1 -> 8 | Y3: =X3+1 -> 9 | Z3: 0 | AA3: =U2 -> 34.569127 | AB3: =AA4-AA3 -> 36.719644 | AC3: 9.8187575 | AE3: 2 | AP3: =AVERAGE(AP2,S2) -> 0.77293074 | AR3: =AVERAGE(AR2,Q2) -> 0.91839127 | AS3: =C6-D6 -> -0.04481583 | AT3: 5 | AU3: =AT3+1 -> 6 | AV3: =AU3+1 -> 7 | AW3: =AV3+1 -> 8 | AX3: =AW3+1 -> 9 | AY3: 0 | AZ3: =AT2 -> 10.314454 | BA3: =AZ4-AZ3 -> 23.430561 | BB3: 9.8187575 | BD3: 3 | BR3: =C7-D7 -> -0.04481583 | BS3: 5 | BT3: =BS3+1 -> 6 | BU3: =BT3+1 -> 7 | BV3: =BU3+1 -> 8 | BW3: =BV3+1 -> 9 | BX3: 0 | BY3: =BS2 -> 10.314454 | BZ3: =BY4-BY3 -> 23.430561 | CA3: =BZ3-BZ4 -> -3.1821507 | CC3: 4 | CQ3: =C8-D8 -> 0.51880091 | CR3: 5 | CS3: =CR3+1 -> 6 | CT3: =CS3+1 -> 7 | CU3: =CT3+1 -> 8 | CV3: =CU3+1 -> 9 | CW3: 0 | CX3: =CR2 -> 34.569127 | CY3: =CX4-CX3 -> 36.719644 | CZ3: =CY3-CY4 -> 17.217672 | DB3: 5 | DP3: =C9-D9 -> #N/A | DQ3: 5 | DR3: =DQ3+1 -> 6 | DS3: =DR3+1 -> 7 | DT3: =DS3+1 -> 8 | DU3: =DT3+1 -> 9 | DV3: 0 | DW3: =DQ2 -> #N/A | DX3: =DW4-DW3 -> #N/A | DY3: =DX3-DX4 -> #N/A
C4: home | D4: away | E4: =Sheet1!F48 -> Monterey Bay | G4: =Sheet1!G48 -> Sporting JAX | H4: chances | L4: no. of goals | M4: =G4 -> Sporting JAX | N4: 0 | O4: =N4+1 -> 1 | P4: =O4+1 -> 2 | Q4: =P4+1 -> 3 | R4: =Q4+1 -> 4 | S4: =R4+1 -> 5 | U4: =POISSON(U3,$T$2,FALSE)*100 -> 0.38954483 | V4: =POISSON(V3,$T$2,FALSE)*100 -> 0.068963016 | W4: =POISSON(W3,$T$2,FALSE)*100 -> 0.010464736 | X4: =POISSON(X3,$T$2,FALSE)*100 -> 0.0013894673 | Y4: =POISSON(Y3,$T$2,FALSE)*100 -> 0.00016398944 | Z4: =Z3+1 -> 1 | AA4: =SUM(U2,V2) -> 71.288771 | AB4: =AA5-AA4 -> 19.501972 | AC4: 12.814904 | AD4: =Sheet1!J48 -> Sporting JAX | AF4: =Sheet1!K48 -> Monterey Bay | AG4: chances | AK4: no. of goals | AL4: =AF4 -> Monterey Bay | AM4: 0 | AN4: =AM4+1 -> 1 | AO4: =AN4+1 -> 2 | AP4: =AO4+1 -> 3 | AQ4: =AP4+1 -> 4 | AR4: =AQ4+1 -> 5 | AT4: =POISSON(AT3,$AS$2,FALSE)*100 -> 5.1993278 | AU4: =POISSON(AU3,$AS$2,FALSE)*100 -> 1.9684862 | AV4: =POISSON(AV3,$AS$2,FALSE)*100 -> 0.63880864 | AW4: =POISSON(AW3,$AS$2,FALSE)*100 -> 0.18139163 | AX4: =POISSON(AX3,$AS$2,FALSE)*100 -> 0.045783729 | AY4: =AY3+1 -> 1 | AZ4: =SUM(AT2,AU2) -> 33.745016 | BA4: =AZ5-AZ4 -> 26.612712 | BB4: 12.814904 | BC4: =Sheet1!N48 -> Sporting JAX | BE4: =Sheet1!O48 -> Monterey Bay | BF4: chances | BJ4: no. of goals | BK4: =BE4 -> Monterey Bay | BL4: 0 | BM4: =BL4+1 -> 1 | BN4: =BM4+1 -> 2 | BO4: =BN4+1 -> 3 | BP4: =BO4+1 -> 4 | BQ4: =BP4+1 -> 5 | BS4: =POISSON(BS3,$BR$2,FALSE)*100 -> 5.1993278 | BT4: =POISSON(BT3,$BR$2,FALSE)*100 -> 1.9684862 | BU4: =POISSON(BU3,$BR$2,FALSE)*100 -> 0.63880864 | BV4: =POISSON(BV3,$BR$2,FALSE)*100 -> 0.18139163 | BW4: =POISSON(BW3,$BR$2,FALSE)*100 -> 0.045783729 | BX4: =BX3+1 -> 1 | BY4: =SUM(BS2,BT2) -> 33.745016 | BZ4: =BY5-BY4 -> 26.612712 | CA4: =BZ4-BZ5 -> 6.4613541 | CB4: =Sheet1!R48 -> Monterey Bay | CD4: =Sheet1!S48 -> Sporting JAX | CE4: chances | CI4: no. of goals | CJ4: =CD4 -> Sporting JAX | CK4: 0 | CL4: =CK4+1 -> 1 | CM4: =CL4+1 -> 2 | CN4: =CM4+1 -> 3 | CO4: =CN4+1 -> 4 | CP4: =CO4+1 -> 5 | CR4: =POISSON(CR3,$CQ$2,FALSE)*100 -> 0.38954483 | CS4: =POISSON(CS3,$CQ$2,FALSE)*100 -> 0.068963016 | CT4: =POISSON(CT3,$CQ$2,FALSE)*100 -> 0.010464736 | CU4: =POISSON(CU3,$CQ$2,FALSE)*100 -> 0.0013894673 | CV4: =POISSON(CV3,$CQ$2,FALSE)*100 -> 0.00016398944 | CW4: =CW3+1 -> 1 | CX4: =SUM(CR2,CS2) -> 71.288771 | CY4: =CX5-CX4 -> 19.501972 | CZ4: =CY4-CY5 -> 12.596914 | DA4: =Sheet1!V48 -> Galway Utd | DC4: =Sheet1!W48 -> Cork City | DD4: chances | DH4: no. of goals | DI4: =DC4 -> Cork City | DJ4: 0 | DK4: =DJ4+1 -> 1 | DL4: =DK4+1 -> 2 | DM4: =DL4+1 -> 3 | DN4: =DM4+1 -> 4 | DO4: =DN4+1 -> 5 | DQ4: =POISSON(DQ3,$DP$2,FALSE)*100 -> #N/A | DR4: =POISSON(DR3,$DP$2,FALSE)*100 -> #N/A | DS4: =POISSON(DS3,$DP$2,FALSE)*100 -> #N/A | DT4: =POISSON(DT3,$DP$2,FALSE)*100 -> #N/A | DU4: =POISSON(DU3,$DP$2,FALSE)*100 -> #N/A | DV4: =DV3+1 -> 1 | DW4: =SUM(DQ2,DR2) -> #N/A | DX4: =DW5-DW4 -> #N/A | DY4: =DX4-DX5 -> #N/A
B5: 1 | C5: =Sheet1!F52 -> 1.3216097 | D5: =Sheet1!G52 -> 0.80280874 | E5: 0 | F5: : | G5: 0 | H5: =POISSON(E5,$C$5,FALSE)*POISSON(G5,$D$5,FALSE)*100 -> 11.950245 | I5: =RANK(H5,$H$5:$H$36,0) -> 3 | J5: =IF(J24="away",J19-(J23*3),IF(J24="home",J19-(J22*3),J19)) -> 8 | L5: =E4 -> Monterey Bay | M5: probablity | N5: =POISSON(N4,$D$5,FALSE) -> 0.44806869 | O5: =POISSON(O4,$D$5,FALSE) -> 0.35971346 | P5: =POISSON(P4,$D$5,FALSE) -> 0.14439055 | Q5: =POISSON(Q4,$D$5,FALSE) -> 0.038639333 | R5: =POISSON(R4,$D$5,FALSE) -> 0.0077549985 | S5: =POISSON(S4,$D$5,FALSE) -> 0.0012451561 | W5: under | X5: over | Z5: =Z4+1 -> 2 | AA5: =SUM(U2,V2,W2) -> 90.790743 | AB5: =AA6-AA5 -> 6.9050579 | AC5: 7.47612 | AD5: 0 | AE5: =AD5+AF5 -> 0 | AF5: 0 | AG5: =POISSON(AD5,$C$6,FALSE)*POISSON(AF5,$D$6,FALSE)*100 -> 1.0638797 | AH5: =RANK(AG5,$AG$5:$AG$36,0) -> 27 | AI5: =IF(AI24="away",AI19-(AI23*3),IF(AI24="home",AI19-(AI22*3),AI19)) -> 7 | AK5: =AD4 -> Sporting JAX | AL5: probablity | AM5: =POISSON(AM4,$D$6,FALSE) -> 0.10085899 | AN5: =POISSON(AN4,$D$6,FALSE) -> 0.23137374 | AO5: =POISSON(AO4,$D$6,FALSE) -> 0.26538937 | AP5: =POISSON(AP4,$D$6,FALSE) -> 0.20293722 | AQ5: =POISSON(AQ4,$D$6,FALSE) -> 0.11638611 | AR5: =POISSON(AR4,$D$6,FALSE) -> 0.05339869 | AV5: under | AW5: over | AY5: =AY4+1 -> 2 | AZ5: =SUM(AT2,AU2,AV2) -> 60.357728 | BA5: =AZ6-AZ5 -> 20.151358 | BB5: 7.47612 | BC5: 0 | BD5: : | BE5: 0 | BF5: =POISSON(BC5,$C$7,FALSE)*POISSON(BE5,$D$7,FALSE)*100 -> 1.0638797 | BG5: =RANK(BF5,$BF$5:$BF$36,0) -> 27 | BH5: =IF(BH24="away",BH19-(BH23*3),IF(BH24="home",BH19-(BH22*3),BH19)) -> 7 | BJ5: =BC4 -> Sporting JAX | BK5: probablity | BL5: =POISSON(BL4,$D$7,FALSE) -> 0.10085899 | BM5: =POISSON(BM4,$D$7,FALSE) -> 0.23137374 | BN5: =POISSON(BN4,$D$7,FALSE) -> 0.26538937 | BO5: =POISSON(BO4,$D$7,FALSE) -> 0.20293722 | BP5: =POISSON(BP4,$D$7,FALSE) -> 0.11638611 | BQ5: =POISSON(BQ4,$D$7,FALSE) -> 0.05339869 | BU5: under | BV5: over | BX5: =BX4+1 -> 2 | BY5: =SUM(BS2,BT2,BU2) -> 60.357728 | BZ5: =BY6-BY5 -> 20.151358 | CA5: =BZ5-BZ6 -> 8.7072812 | CB5: 0 | CC5: : | CD5: 0 | CE5: =POISSON(CB5,$C$8,FALSE)*POISSON(CD5,$D$8,FALSE)*100 -> 11.950245 | CF5: =RANK(CE5,$CE$5:$CE$36,0) -> 3 | CG5: =IF(CG24="away",CG19-(CG23*3),IF(CG24="home",CG19-(CG22*3),CG19)) -> 8 | CI5: =CB4 -> Monterey Bay | CJ5: probablity | CK5: =POISSON(CK4,$D$8,FALSE) -> 0.44806869 | CL5: =POISSON(CL4,$D$8,FALSE) -> 0.35971346 | CM5: =POISSON(CM4,$D$8,FALSE) -> 0.14439055 | CN5: =POISSON(CN4,$D$8,FALSE) -> 0.038639333 | CO5: =POISSON(CO4,$D$8,FALSE) -> 0.0077549985 | CP5: =POISSON(CP4,$D$8,FALSE) -> 0.0012451561 | CT5: under | CU5: over | CW5: =CW4+1 -> 2 | CX5: =SUM(CR2,CS2,CT2) -> 90.790743 | CY5: =CX6-CX5 -> 6.9050579 | CZ5: =CY5-CY6 -> 5.0714039 | DA5: 0 | DB5: : | DC5: 0 | DD5: =POISSON(DA5,$C$9,FALSE)*POISSON(DC5,$D$9,FALSE)*100 -> #N/A | DE5: =RANK(DD5,$DD$5:$DD$36,0) -> #N/A | DF5: =IF(DF24="away",DF19-(DF23*3),IF(DF24="home",DF19-(DF22*3),DF19)) -> #N/A | DH5: =DA4 -> Galway Utd | DI5: probablity | DJ5: =POISSON(DJ4,$D$9,FALSE) -> #N/A | DK5: =POISSON(DK4,$D$9,FALSE) -> #N/A | DL5: =POISSON(DL4,$D$9,FALSE) -> #N/A | DM5: =POISSON(DM4,$D$9,FALSE) -> #N/A | DN5: =POISSON(DN4,$D$9,FALSE) -> #N/A | DO5: =POISSON(DO4,$D$9,FALSE) -> #N/A | DS5: under | DT5: over | DV5: =DV4+1 -> 2 | DW5: =SUM(DQ2,DR2,DS2) -> #N/A | DX5: =DW6-DW5 -> #N/A | DY5: =DX5-DX6 -> #N/A
B6: =B5+1 -> 2 | C6: =Sheet1!J52 -> 2.249216 | D6: =Sheet1!K52 -> 2.2940319 | E6: 0 | F6: : | G6: 1 | H6: =POISSON(E6,$C$5,FALSE)*POISSON(G6,$D$5,FALSE)*100 -> 9.5937613 | I6: =RANK(H6,$H$5:$H$36,0) -> 4 | J6: =IF(I5=1,"draw",IF(I6=1,"away",IF(I7=1,"draw 1-1",IF(I8=1,"home",IF(I9=1,"away 0-2",IF(I10=1,"away 1-2",IF(I11=1,"home 2-1","rountime"))))))) -> home | K6: =IF(OR(J6="away",J6="home",J6="draw"),"small",IF(OR(J6="away",J6="home",J6="draw",J6="draw 1-1",J6="away 0-2"),"under",IF(J6="rountime","RT",0))) -> small | L6: 0 | M6: =POISSON(L6,$C$5,FALSE) -> 0.26670565 | N6: =$N$5*M6 -> 0.11950245 | O6: =$O$5*M6 -> 0.095937613 | P6: =$P$5*M6 -> 0.038509777 | Q6: =$Q$5*M6 -> 0.010305328 | R6: =$R$5*M6 -> 0.0020683019 | S6: =$S$5*M6 -> 0.00033209017 | T6: =SUM(R6:S9,S10,Q6,Q7,Q8,P7,P6,O6)*100 -> 22.690196 | V6: 0.5 | W6: =N6 -> 0.11950245 | X6: =(Y6-W6) -> 0.87789168 | Y6: =SUM(N6:S11) -> 0.99739414 | Z6: =Z5+1 -> 3 | AA6: =SUM(U2,V2,W2,X2) -> 97.695801 | AB6: =AA7-AA6 -> 1.833654 | AC6: =IF(AND(AC4>AC3,AC5),2.5,IF(AND(AC3>AC4,AC5),1.5,IF(AND(AC5>AC3,AC4),3.5))) -> 2.5 | AD6: 0 | AE6: =AD6+AF6 -> 1 | AF6: 1 | AG6: =POISSON(AD6,$C$6,FALSE)*POISSON(AF6,$D$6,FALSE)*100 -> 2.4405739 | AH6: =RANK(AG6,$AG$5:$AG$36,0) -> 15 | AI6: =IF(AH5=1,"draw",IF(AH6=1,"away",IF(AH7=1,"draw 1-1",IF(AH8=1,"home",IF(AH9=1,"away 0-2",IF(AH10=1,"away 1-2",IF(AH11=1,"home 2-1","rountime"))))))) -> rountime | AJ6: =IF(OR(AI6="away",AI6="home",AI6="draw"),"small",IF(OR(AI6="away",AI6="home",AI6="draw",AI6="draw 1-1",AI6="away 0-2"),"under",IF(AI6="rountime","RT",0))) -> RT | AK6: 0 | AL6: =POISSON(AK6,$C$6,FALSE) -> 0.10548189 | AM6: =$AM$5*AL6 -> 0.010638797 | AN6: =$AN$5*AL6 -> 0.024405739 | AO6: =$AO$5*AL6 -> 0.027993771 | AP6: =$AP$5*AL6 -> 0.021406201 | AQ6: =$AQ$5*AL6 -> 0.012276627 | AR6: =$AR$5*AL6 -> 0.0056325946 | AS6: =SUM(AQ6:AR9,AR10,AP6,AP7,AP8,AO7,AO6,AN6)*100 -> 38.252619 | AU6: 0.5 | AV6: =AM6 -> 0.010638797 | AW6: =(AX6-AV6) -> 0.93319002 | AX6: =SUM(AM6:AR11) -> 0.94382882 | AY6: =AY5+1 -> 3 | AZ6: =SUM(AT2,AU2,AV2,AW2) -> 80.509086 | BA6: =AZ7-AZ6 -> 11.444077 | BB6: =IF(AND(BB4>BB3,BB5),2.5,IF(AND(BB3>BB4,BB5),1.5,IF(AND(BB5>BB3,BB4),3.5))) -> 2.5 | BC6: 0 | BD6: : | BE6: 1 | BF6: =POISSON(BC6,$C$7,FALSE)*POISSON(BE6,$D$7,FALSE)*100 -> 2.4405739 | BG6: =RANK(BF6,$BF$5:$BF$36,0) -> 15 | BH6: =IF(BG5=1,"draw",IF(BG6=1,"away",IF(BG7=1,"draw 1-1",IF(BG8=1,"home",IF(BG9=1,"away 0-2",IF(BG10=1,"away 1-2",IF(BG11=1,"home 2-1","rountime"))))))) -> rountime | BI6: =IF(OR(BH6="away",BH6="home",BH6="draw"),"small",IF(OR(BH6="away",BH6="home",BH6="draw",BH6="draw 1-1",BH6="away 0-2"),"under",IF(BH6="rountime","RT",0))) -> RT | BJ6: 0 | BK6: =POISSON(BJ6,$C$7,FALSE) -> 0.10548189 | BL6: =$BL$5*BK6 -> 0.010638797 | BM6: =$BM$5*BK6 -> 0.024405739 | BN6: =$BN$5*BK6 -> 0.027993771 | BO6: =$BO$5*BK6 -> 0.021406201 | BP6: =$BP$5*BK6 -> 0.012276627 | BQ6: =$BQ$5*BK6 -> 0.0056325946 | BR6: =SUM(BP6:BQ9,BQ10,BO6,BO7,BO8,BN7,BN6,BM6)*100 -> 38.252619 | BT6: 0.5 | BU6: =BL6 -> 0.010638797 | BV6: =(BW6-BU6) -> 0.93319002 | BW6: =SUM(BL6:BQ11) -> 0.94382882 | BX6: =BX5+1 -> 3 | BY6: =SUM(BS2,BT2,BU2,BV2) -> 80.509086 | BZ6: =BY7-BY6 -> 11.444077 | CA6: =IF(AND(CA4>CA3,CA5),2.5,IF(AND(CA3>CA4,CA5),1.5,IF(AND(CA5>CA3,CA4),3.5))) -> 2.5 | CB6: 0 | CC6: : | CD6: 1 | CE6: =POISSON(CB6,$C$8,FALSE)*POISSON(CD6,$D$8,FALSE)*100 -> 9.5937613 | CF6: =RANK(CE6,$CE$5:$CE$36,0) -> 4 | CG6: =IF(CF5=1,"draw",IF(CF6=1,"away",IF(CF7=1,"draw 1-1",IF(CF8=1,"home",IF(CF9=1,"away 0-2",IF(CF10=1,"away 1-2",IF(CF11=1,"home 2-1","rountime"))))))) -> home | CH6: =IF(OR(CG6="away",CG6="home",CG6="draw"),"small",IF(OR(CG6="away",CG6="home",CG6="draw",CG6="draw 1-1",CG6="away 0-2"),"under",IF(CG6="rountime","RT",0))) -> small | CI6: 0 | CJ6: =POISSON(CI6,$C$8,FALSE) -> 0.26670565 | CK6: =$CK$5*CJ6 -> 0.11950245 | CL6: =$CL$5*CJ6 -> 0.095937613 | CM6: =$CM$5*CJ6 -> 0.038509777 | CN6: =$CN$5*CJ6 -> 0.010305328 | CO6: =$CO$5*CJ6 -> 0.0020683019 | CP6: =$CP$5*CJ6 -> 0.00033209017 | CQ6: =SUM(CO6:CP9,CP10,CN6,CN7,CN8,CM7,CM6,CL6)*100 -> 22.690196 | CS6: 0.5 | CT6: =CK6 -> 0.11950245 | CU6: =(CV6-CT6) -> 0.87789168 | CV6: =SUM(CK6:CP11) -> 0.99739414 | CW6: =CW5+1 -> 3 | CX6: =SUM(CR2,CS2,CT2,CU2) -> 97.695801 | CY6: =CX7-CX6 -> 1.833654 | CZ6: =IF(AND(CZ4>CZ3,CZ5),2.5,IF(AND(CZ3>CZ4,CZ5),1.5,IF(AND(CZ5>CZ3,CZ4),3.5))) -> 1.5 | DA6: 0 | DB6: : | DC6: 1 | DD6: =POISSON(DA6,$C$9,FALSE)*POISSON(DC6,$D$9,FALSE)*100 -> #N/A | DE6: =RANK(DD6,$DD$5:$DD$36,0) -> #N/A | DF6: =IF(DE5=1,"draw",IF(DE6=1,"away",IF(DE7=1,"draw 1-1",IF(DE8=1,"home",IF(DE9=1,"away 0-2",IF(DE10=1,"away 1-2",IF(DE11=1,"home 2-1","rountime"))))))) -> #N/A | DG6: =IF(OR(DF6="away",DF6="home",DF6="draw"),"small",IF(OR(DF6="away",DF6="home",DF6="draw",DF6="draw 1-1",DF6="away 0-2"),"under",IF(DF6="rountime","RT",0))) -> #N/A | DH6: 0 | DI6: =POISSON(DH6,$C$9,FALSE) -> #N/A | DJ6: =$DJ$5*DI6 -> #N/A | DK6: =$DK$5*DI6 -> #N/A | DL6: =$DL$5*DI6 -> #N/A | DM6: =$DM$5*DI6 -> #N/A | DN6: =$DN$5*DI6 -> #N/A | DO6: =$DO$5*DI6 -> #N/A | DP6: =SUM(DN6:DO9,DO10,DM6,DM7,DM8,DL7,DL6,DK6)*100 -> #N/A | DR6: 0.5 | DS6: =DJ6 -> #N/A | DT6: =(DU6-DS6) -> #N/A | DU6: =SUM(DJ6:DO11) -> #N/A | DV6: =DV5+1 -> 3 | DW6: =SUM(DQ2,DR2,DS2,DT2) -> #N/A | DX6: =DW7-DW6 -> #N/A | DY6: =IF(AND(DY4>DY3,DY5),2.5,IF(AND(DY3>DY4,DY5),1.5,IF(AND(DY5>DY3,DY4),3.5))) -> #N/A
B7: =B6+1 -> 3 | C7: =Sheet1!N52 -> 2.249216 | D7: =Sheet1!O52 -> 2.2940319 | E7: 1 | F7: : | G7: 1 | H7: =POISSON(E7,$C$5,FALSE)*POISSON(G7,$D$5,FALSE)*100 -> 12.679207 | I7: =RANK(H7,$H$5:$H$36,0) -> 2 | J7: =IF(I5=2,"draw",IF(I6=2,"away",IF(I7=2,"draw 1-1",IF(I8=2,"home",IF(I9=2,"away 0-2",IF(I10=2,"away 1-2",IF(I11=2,"home 2-1","rountime"))))))) -> draw 1-1 | K7: =IF(OR(J7="away",J7="home",J7="draw"),"small",IF(OR(J7="away",J7="home",J7="draw",J7="draw 1-1",J7="away 0-2"),"under",IF(J7="rountime","RT",0))) -> under | L7: =L6+1 -> 1 | M7: =POISSON(L7,$C$5,FALSE) -> 0.35248077 | N7: =$N$5*M7 -> 0.15793559 | O7: =$O$5*M7 -> 0.12679207 | P7: =$P$5*M7 -> 0.050894893 | Q7: =$Q$5*M7 -> 0.013619622 | R7: =$R$5*M7 -> 0.0027334878 | S7: =$S$5*M7 -> 0.00043889358 | V7: =V6+1 -> 1.5 | W7: =SUM(N6,O6,N7) -> 0.37337566 | X7: =(Y6-W7) -> 0.62401848 | Z7: =Z6+1 -> 4 | AA7: =SUM(U2,V2,W2,X2,Y2) -> 99.529455 | AC7: =IF(AC6=AC44,AC6+1,AC6+AC44+0.5) -> 4.5 | AD7: 1 | AE7: =AD7+AF7 -> 2 | AF7: 1 | AG7: =POISSON(AD7,$C$6,FALSE)*POISSON(AF7,$D$6,FALSE)*100 -> 5.4893779 | AH7: =RANK(AG7,$AG$5:$AG$36,0) -> 4 | AI7: =IF(AH5=2,"draw",IF(AH6=2,"away",IF(AH7=2,"draw 1-1",IF(AH8=2,"home",IF(AH9=2,"away 0-2",IF(AH10=2,"away 1-2",IF(AH11=2,"home 2-1","rountime"))))))) -> away 1-2 | AJ7: =IF(OR(AI7="away",AI7="home",AI7="draw"),"small",IF(OR(AI7="away",AI7="home",AI7="draw",AI7="draw 1-1",AI7="away 0-2"),"under",IF(AI7="rountime","RT",0))) -> 0 | AK7: =AK6+1 -> 1 | AL7: =POISSON(AK7,$C$6,FALSE) -> 0.23725155 | AM7: =$AM$5*AL7 -> 0.023928952 | AN7: =$AN$5*AL7 -> 0.054893779 | AO7: =$AO$5*AL7 -> 0.062964039 | AP7: =$AP$5*AL7 -> 0.04814717 | AQ7: =$AQ$5*AL7 -> 0.027612786 | AR7: =$AR$5*AL7 -> 0.012668922 | AU7: =AU6+1 -> 1.5 | AV7: =SUM(AM6,AN6,AM7) -> 0.058973488 | AW7: =(AX6-AV7) -> 0.88485533 | AY7: =AY6+1 -> 4 | AZ7: =SUM(AT2,AU2,AV2,AW2,AX2) -> 91.953163 | BB7: =IF(BB6=BB44,BB6+1,BB6+BB44+0.5) -> 4.5 | BC7: 1 | BD7: : | BE7: 1 | BF7: =POISSON(BC7,$C$7,FALSE)*POISSON(BE7,$D$7,FALSE)*100 -> 5.4893779 | BG7: =RANK(BF7,$BF$5:$BF$36,0) -> 4 | BH7: =IF(BG5=2,"draw",IF(BG6=2,"away",IF(BG7=2,"draw 1-1",IF(BG8=2,"home",IF(BG9=2,"away 0-2",IF(BG10=2,"away 1-2",IF(BG11=2,"home 2-1","rountime"))))))) -> away 1-2 | BI7: =IF(OR(BH7="away",BH7="home",BH7="draw"),"small",IF(OR(BH7="away",BH7="home",BH7="draw",BH7="draw 1-1",BH7="away 0-2"),"under",IF(BH7="rountime","RT",0))) -> 0 | BJ7: =BJ6+1 -> 1 | BK7: =POISSON(BJ7,$C$7,FALSE) -> 0.23725155 | BL7: =$BL$5*BK7 -> 0.023928952 | BM7: =$BM$5*BK7 -> 0.054893779 | BN7: =$BN$5*BK7 -> 0.062964039 | BO7: =$BO$5*BK7 -> 0.04814717 | BP7: =$BP$5*BK7 -> 0.027612786 | BQ7: =$BQ$5*BK7 -> 0.012668922 | BT7: =BT6+1 -> 1.5 | BU7: =SUM(BL6,BM6,BL7) -> 0.058973488 | BV7: =(BW6-BU7) -> 0.88485533 | BX7: =BX6+1 -> 4 | BY7: =SUM(BS2,BT2,BU2,BV2,BW2) -> 91.953163 | CA7: =IF(CA6=CA44,CA6+1,CA6+CA44+0.5) -> 4.5 | CB7: 1 | CC7: : | CD7: 1 | CE7: =POISSON(CB7,$C$8,FALSE)*POISSON(CD7,$D$8,FALSE)*100 -> 12.679207 | CF7: =RANK(CE7,$CE$5:$CE$36,0) -> 2 | CG7: =IF(CF5=2,"draw",IF(CF6=2,"away",IF(CF7=2,"draw 1-1",IF(CF8=2,"home",IF(CF9=2,"away 0-2",IF(CF10=2,"away 1-2",IF(CF11=2,"home 2-1","rountime"))))))) -> draw 1-1 | CH7: =IF(OR(CG7="away",CG7="home",CG7="draw"),"small",IF(OR(CG7="away",CG7="home",CG7="draw",CG7="draw 1-1",CG7="away 0-2"),"under",IF(CG7="rountime","RT",0))) -> under | CI7: =CI6+1 -> 1 | CJ7: =POISSON(CI7,$C$8,FALSE) -> 0.35248077 | CK7: =$CK$5*CJ7 -> 0.15793559 | CL7: =$CL$5*CJ7 -> 0.12679207 | CM7: =$CM$5*CJ7 -> 0.050894893 | CN7: =$CN$5*CJ7 -> 0.013619622 | CO7: =$CO$5*CJ7 -> 0.0027334878 | CP7: =$CP$5*CJ7 -> 0.00043889358 | CS7: =CS6+1 -> 1.5 | CT7: =SUM(CK6,CL6,CK7) -> 0.37337566 | CU7: =(CV6-CT7) -> 0.62401848 | CW7: =CW6+1 -> 4 | CX7: =SUM(CR2,CS2,CT2,CU2,CV2) -> 99.529455 | CZ7: =IF(CZ6=CZ44,CZ6+1,CZ6+CZ44+0.5) -> 4.5 | DA7: 1 | DB7: : | DC7: 1 | DD7: =POISSON(DA7,$C$9,FALSE)*POISSON(DC7,$D$9,FALSE)*100 -> #N/A | DE7: =RANK(DD7,$DD$5:$DD$36,0) -> #N/A | DF7: =IF(DE5=2,"draw",IF(DE6=2,"away",IF(DE7=2,"draw 1-1",IF(DE8=2,"home",IF(DE9=2,"away 0-2",IF(DE10=2,"away 1-2",IF(DE11=2,"home 2-1","rountime"))))))) -> #N/A | DG7: =IF(OR(DF7="away",DF7="home",DF7="draw"),"small",IF(OR(DF7="away",DF7="home",DF7="draw",DF7="draw 1-1",DF7="away 0-2"),"under",IF(DF7="rountime","RT",0))) -> #N/A | DH7: =DH6+1 -> 1 | DI7: =POISSON(DH7,$C$9,FALSE) -> #N/A | DJ7: =$DJ$5*DI7 -> #N/A | DK7: =$DK$5*DI7 -> #N/A | DL7: =$DL$5*DI7 -> #N/A | DM7: =$DM$5*DI7 -> #N/A | DN7: =$DN$5*DI7 -> #N/A | DO7: =$DO$5*DI7 -> #N/A | DR7: =DR6+1 -> 1.5 | DS7: =SUM(DJ6,DK6,DJ7) -> #N/A | DT7: =(DU6-DS7) -> #N/A | DV7: =DV6+1 -> 4 | DW7: =SUM(DQ2,DR2,DS2,DT2,DU2) -> #N/A | DY7: =IF(DY6=DY44,DY6+1,DY6+DY44+0.5) -> #N/A
B8: =B7+1 -> 4 | C8: =Sheet1!R52 -> 1.3216097 | D8: =Sheet1!S52 -> 0.80280874 | E8: 1 | F8: : | G8: 0 | H8: =POISSON(E8,$C$5,FALSE)*POISSON(G8,$D$5,FALSE)*100 -> 15.793559 | I8: =RANK(H8,$H$5:$H$36,0) -> 1 | J8: =IF(I5=3,"draw",IF(I6=3,"away",IF(I7=3,"draw 1-1",IF(I8=3,"home",IF(I9=3,"away 0-2",IF(I10=3,"away 1-2",IF(I11=3,"home 2-1","rountime"))))))) -> draw | K8: =IF(OR(J8="away",J8="home",J8="draw"),"small",IF(OR(J8="away",J8="home",J8="draw",J8="draw 1-1",J8="away 0-2"),"under",IF(J8="rountime","RT",0))) -> small | L8: =L7+1 -> 2 | M8: =POISSON(L8,$C$5,FALSE) -> 0.23292099 | N8: =$N$5*M8 -> 0.1043646 | O8: =$O$5*M8 -> 0.083784815 | P8: =$P$5*M8 -> 0.033631591 | Q8: =$Q$5*M8 -> 0.0089999116 | R8: =$R$5*M8 -> 0.0018063019 | S8: =$S$5*M8 -> 0.00029002299 | T8: =IF(T2<0.6,"low",IF(T2<1.38,"medium","high")) -> medium | V8: =V7+1 -> 2.5 | W8: =SUM(N6,O6,P6,N7,N8,O7) -> 0.64304211 | X8: =(Y6-W8) -> 0.35435202 | Y8: =(X6/$Y$16)*100 -> 35.207413 | Z8: remain | AA8: =Z2-AA7 -> 0.47052604 | AB8: =IF(AA9<0.6,"Under",IF(AA9<0.9,"under+",IF(AND(AA8<0.9,AA9>1,AA9<2.9),"under",IF(AND(AA8<1.5,AA9>0.9,AA9<1.75),"under+","over")))) -> Under | AC8: =AVERAGE(AC6,AC7,AC44)+0.666667 -> 3.5000003 | AD8: 1 | AE8: =AD8+AF8 -> 1 | AF8: 0 | AG8: =POISSON(AD8,$C$6,FALSE)*POISSON(AF8,$D$6,FALSE)*100 -> 2.3928952 | AH8: =RANK(AG8,$AG$5:$AG$36,0) -> 16 | AI8: =IF(AH5=3,"draw",IF(AH6=3,"away",IF(AH7=3,"draw 1-1",IF(AH8=3,"home",IF(AH9=3,"away 0-2",IF(AH10=3,"away 1-2",IF(AH11=3,"home 2-1","rountime"))))))) -> home 2-1 | AJ8: =IF(OR(AI8="away",AI8="home",AI8="draw"),"small",IF(OR(AI8="away",AI8="home",AI8="draw",AI8="draw 1-1",AI8="away 0-2"),"under",IF(AI8="rountime","RT",0))) -> 0 | AK8: =AK7+1 -> 2 | AL8: =POISSON(AK8,$C$6,FALSE) -> 0.266815 | AM8: =$AM$5*AL8 -> 0.026910691 | AN8: =$AN$5*AL8 -> 0.061733984 | AO8: =$AO$5*AL8 -> 0.070809862 | AP8: =$AP$5*AL8 -> 0.054146693 | AQ8: =$AQ$5*AL8 -> 0.03105356 | AR8: =$AR$5*AL8 -> 0.014247571 | AS8: =IF(AS2<0.6,"low",IF(AS2<1.38,"medium","high")) -> high | AU8: =AU7+1 -> 2.5 | AV8: =SUM(AM6,AN6,AO6,AM7,AM8,AN7) -> 0.16877173 | AW8: =(AX6-AV8) -> 0.77505709 | AX8: =(AW6/$AX$16)*100 -> 39.549122 | AY8: remain | AZ8: =AY2-AZ7 -> 8.033798 | BA8: =IF(AZ9<0.6,"Under",IF(AZ9<0.9,"under+",IF(AND(AZ8<0.9,AZ9>1,AZ9<2.9),"under",IF(AND(AZ8<1.5,AZ9>0.9,AZ9<1.75),"under+","over")))) -> over | BB8: =AVERAGE(BB6,BB7,BB44)+0.666667 -> 3.5000003 | BC8: 1 | BD8: : | BE8: 0 | BF8: =POISSON(BC8,$C$7,FALSE)*POISSON(BE8,$D$7,FALSE)*100 -> 2.3928952 | BG8: =RANK(BF8,$BF$5:$BF$36,0) -> 16 | BH8: =IF(BG5=3,"draw",IF(BG6=3,"away",IF(BG7=3,"draw 1-1",IF(BG8=3,"home",IF(BG9=3,"away 0-2",IF(BG10=3,"away 1-2",IF(BG11=3,"home 2-1","rountime"))))))) -> home 2-1 | BI8: =IF(OR(BH8="away",BH8="home",BH8="draw"),"small",IF(OR(BH8="away",BH8="home",BH8="draw",BH8="draw 1-1",BH8="away 0-2"),"under",IF(BH8="rountime","RT",0))) -> 0 | BJ8: =BJ7+1 -> 2 | BK8: =POISSON(BJ8,$C$7,FALSE) -> 0.266815 | BL8: =$BL$5*BK8 -> 0.026910691 | BM8: =$BM$5*BK8 -> 0.061733984 | BN8: =$BN$5*BK8 -> 0.070809862 | BO8: =$BO$5*BK8 -> 0.054146693 | BP8: =$BP$5*BK8 -> 0.03105356 | BQ8: =$BQ$5*BK8 -> 0.014247571 | BR8: =IF(BR2<0.6,"low",IF(BR2<1.38,"medium","high")) -> high | BT8: =BT7+1 -> 2.5 | BU8: =SUM(BL6,BM6,BN6,BL7,BL8,BM7) -> 0.16877173 | BV8: =(BW6-BU8) -> 0.77505709 | BX8: remain | BY8: =BX2-BY7 -> 8.033798 | BZ8: =IF(BY9<0.6,"Under",IF(BY9<0.9,"under+",IF(AND(BY8<0.9,BY9>1,BY9<2.9),"under",IF(AND(BY8<1.5,BY9>0.9,BY9<1.75),"under+","over")))) -> over | CA8: =AVERAGE(CA6,CA7,CA44)+0.666667 -> 3.5000003 | CB8: 1 | CC8: : | CD8: 0 | CE8: =POISSON(CB8,$C$8,FALSE)*POISSON(CD8,$D$8,FALSE)*100 -> 15.793559 | CF8: =RANK(CE8,$CE$5:$CE$36,0) -> 1 | CG8: =IF(CF5=3,"draw",IF(CF6=3,"away",IF(CF7=3,"draw 1-1",IF(CF8=3,"home",IF(CF9=3,"away 0-2",IF(CF10=3,"away 1-2",IF(CF11=3,"home 2-1","rountime"))))))) -> draw | CH8: =IF(OR(CG8="away",CG8="home",CG8="draw"),"small",IF(OR(CG8="away",CG8="home",CG8="draw",CG8="draw 1-1",CG8="away 0-2"),"under",IF(CG8="rountime","RT",0))) -> small | CI8: =CI7+1 -> 2 | CJ8: =POISSON(CI8,$C$8,FALSE) -> 0.23292099 | CK8: =$CK$5*CJ8 -> 0.1043646 | CL8: =$CL$5*CJ8 -> 0.083784815 | CM8: =$CM$5*CJ8 -> 0.033631591 | CN8: =$CN$5*CJ8 -> 0.0089999116 | CO8: =$CO$5*CJ8 -> 0.0018063019 | CP8: =$CP$5*CJ8 -> 0.00029002299 | CQ8: =IF(CQ2<0.6,"low",IF(CQ2<1.38,"medium","high")) -> medium | CS8: =CS7+1 -> 2.5 | CT8: =SUM(CK6,CL6,CM6,CK7,CK8,CL7) -> 0.64304211 | CU8: =(CV6-CT8) -> 0.35435202 | CW8: remain | CX8: =CW2-CX7 -> 0.47052604 | CY8: =IF(CX9<0.6,"Under",IF(CX9<0.9,"under+",IF(AND(CX8<0.9,CX9>1,CX9<2.9),"under",IF(AND(CX8<1.5,CX9>0.9,CX9<1.75),"under+","over")))) -> over | CZ8: =AVERAGE(CZ6,CZ7,CZ44)+0.666667 -> 3.5000003 | DA8: 1 | DB8: : | DC8: 0 | DD8: =POISSON(DA8,$C$9,FALSE)*POISSON(DC8,$D$9,FALSE)*100 -> #N/A | DE8: =RANK(DD8,$DD$5:$DD$36,0) -> #N/A | DF8: =IF(DE5=3,"draw",IF(DE6=3,"away",IF(DE7=3,"draw 1-1",IF(DE8=3,"home",IF(DE9=3,"away 0-2",IF(DE10=3,"away 1-2",IF(DE11=3,"home 2-1","rountime"))))))) -> #N/A | DG8: =IF(OR(DF8="away",DF8="home",DF8="draw"),"small",IF(OR(DF8="away",DF8="home",DF8="draw",DF8="draw 1-1",DF8="away 0-2"),"under",IF(DF8="rountime","RT",0))) -> #N/A | DH8: =DH7+1 -> 2 | DI8: =POISSON(DH8,$C$9,FALSE) -> #N/A | DJ8: =$DJ$5*DI8 -> #N/A | DK8: =$DK$5*DI8 -> #N/A | DL8: =$DL$5*DI8 -> #N/A | DM8: =$DM$5*DI8 -> #N/A | DN8: =$DN$5*DI8 -> #N/A | DO8: =$DO$5*DI8 -> #N/A | DP8: =IF(DP2<0.6,"low",IF(DP2<1.38,"medium","high")) -> #N/A | DR8: =DR7+1 -> 2.5 | DS8: =SUM(DJ6,DK6,DL6,DJ7,DJ8,DK7) -> #N/A | DT8: =(DU6-DS8) -> #N/A | DV8: remain | DW8: =DV2-DW7 -> #N/A | DX8: =IF(DW9<0.6,"Under",IF(DW9<0.9,"under+",IF(AND(DW8<0.9,DW9>1,DW9<2.9),"under",IF(AND(DW8<1.5,DW9>0.9,DW9<1.75),"under+","over")))) -> #N/A | DY8: =AVERAGE(DY6,DY7,DY44)+0.666667 -> #N/A
B9: =B8+1 -> 5 | C9: =Sheet1!V52 -> #N/A | D9: =Sheet1!W52 -> #N/A | E9: 0 | F9: : | G9: 2 | H9: =POISSON(E9,$C$5,FALSE)*POISSON(G9,$D$5,FALSE)*100 -> 3.8509777 | I9: =RANK(H9,$H$5:$H$36,0) -> 8 | J9: =IF(I5=4,"draw",IF(I6=4,"away",IF(I7=4,"draw 1-1",IF(I8=4,"home",IF(I9=4,"away 0-2",IF(I10=4,"away 1-2",IF(I11=4,"home 2-1","rountime"))))))) -> away | K9: =IF(OR(J9="away",J9="home",J9="draw"),"small",IF(OR(J9="away",J9="home",J9="draw",J9="draw 1-1",J9="away 0-2"),"under",IF(J9="rountime","RT",0))) -> small | L9: =L8+1 -> 3 | M9: =POISSON(L9,$C$5,FALSE) -> 0.10261021 | N9: =$N$5*M9 -> 0.045976422 | O9: =$O$5*M9 -> 0.036910273 | P9: =$P$5*M9 -> 0.014815945 | Q9: =$Q$5*M9 -> 0.00396479 | R9: =$R$5*M9 -> 0.00079574202 | S9: =$S$5*M9 -> 0.00012776573 | T9: =IF(W6>0.38,"u0.5",IF(W7>0.352,"U1.5",IF(W8>0.5885,"u2.5",IF(W9>0.6871,"U3.5",IF(W10>0.6993,"u4.5","Run"))))) -> U1.5 | U9: =IF(X10>0.34,"O4.5",IF(X9>0.6155,"O3.5",IF(X8>0.5063,"O2.5",IF(X7>0.74,"O1.5",IF(X6>0.95,"O0.5","Run"))))) -> Run | V9: =V8+1 -> 3.5 | W9: =SUM(N6,N7,O6,P6,O7,N8,N9,O8,P7,Q6) -> 0.83400357 | X9: =(Y6-W9) -> 0.16339057 | Y9: =(X7/$Y$16)*100 -> 25.025953 | AA9: =AA47 -> 0.39946182 | AD9: 0 | AE9: =AD9+AF9 -> 2 | AF9: 2 | AG9: =POISSON(AD9,$C$6,FALSE)*POISSON(AF9,$D$6,FALSE)*100 -> 2.7993771 | AH9: =RANK(AG9,$AG$5:$AG$36,0) -> 12 | AI9: =IF(AH5=4,"draw",IF(AH6=4,"away",IF(AH7=4,"draw 1-1",IF(AH8=4,"home",IF(AH9=4,"away 0-2",IF(AH10=4,"away 1-2",IF(AH11=4,"home 2-1","rountime"))))))) -> draw 1-1 | AJ9: =IF(OR(AI9="away",AI9="home",AI9="draw"),"small",IF(OR(AI9="away",AI9="home",AI9="draw",AI9="draw 1-1",AI9="away 0-2"),"under",IF(AI9="rountime","RT",0))) -> under | AK9: =AK8+1 -> 3 | AL9: =POISSON(AK9,$C$6,FALSE) -> 0.20004152 | AM9: =$AM$5*AL9 -> 0.020175986 | AN9: =$AN$5*AL9 -> 0.046284355 | AO9: =$AO$5*AL9 -> 0.053088893 | AP9: =$AP$5*AL9 -> 0.04059587 | AQ9: =$AQ$5*AL9 -> 0.023282055 | AR9: =$AR$5*AL9 -> 0.010681955 | AS9: =IF(AV6>0.38,"u0.5",IF(AV7>0.352,"U1.5",IF(AV8>0.5885,"u2.5",IF(AV9>0.6871,"U3.5",IF(AV10>0.6993,"u4.5","Run"))))) -> Run | AT9: =IF(AW10>0.34,"O4.5",IF(AW9>0.6155,"O3.5",IF(AW8>0.5063,"O2.5",IF(AW7>0.74,"O1.5",IF(AW6>0.95,"O0.5","Run"))))) -> O4.5 | AU9: =AU8+1 -> 3.5 | AV9: =SUM(AM6,AM7,AN6,AO6,AN7,AM8,AM9,AN8,AO7,AP6) -> 0.33505194 | AW9: =(AX6-AV9) -> 0.60877688 | AX9: =(AW7/$AX$16)*100 -> 37.50067 | AZ9: =AZ47 -> 4.2467056 | BC9: 0 | BD9: : | BE9: 2 | BF9: =POISSON(BC9,$C$7,FALSE)*POISSON(BE9,$D$7,FALSE)*100 -> 2.7993771 | BG9: =RANK(BF9,$BF$5:$BF$36,0) -> 12 | BH9: =IF(BG5=4,"draw",IF(BG6=4,"away",IF(BG7=4,"draw 1-1",IF(BG8=4,"home",IF(BG9=4,"away 0-2",IF(BG10=4,"away 1-2",IF(BG11=4,"home 2-1","rountime"))))))) -> draw 1-1 | BI9: =IF(OR(BH9="away",BH9="home",BH9="draw"),"small",IF(OR(BH9="away",BH9="home",BH9="draw",BH9="draw 1-1",BH9="away 0-2"),"under",IF(BH9="rountime","RT",0))) -> under | BJ9: =BJ8+1 -> 3 | BK9: =POISSON(BJ9,$C$7,FALSE) -> 0.20004152 | BL9: =$BL$5*BK9 -> 0.020175986 | BM9: =$BM$5*BK9 -> 0.046284355 | BN9: =$BN$5*BK9 -> 0.053088893 | BO9: =$BO$5*BK9 -> 0.04059587 | BP9: =$BP$5*BK9 -> 0.023282055 | BQ9: =$BQ$5*BK9 -> 0.010681955 | BR9: =IF(BU6>0.38,"u0.5",IF(BU7>0.352,"U1.5",IF(BU8>0.5885,"u2.5",IF(BU9>0.6871,"U3.5",IF(BU10>0.6993,"u4.5","Run"))))) -> Run | BS9: =IF(BV10>0.34,"O4.5",IF(BV9>0.6155,"O3.5",IF(BV8>0.5063,"O2.5",IF(BV7>0.74,"O1.5",IF(BV6>0.95,"O0.5","Run"))))) -> O4.5 | BT9: =BT8+1 -> 3.5 | BU9: =SUM(BL6,BL7,BM6,BN6,BM7,BL8,BL9,BM8,BN7,BO6) -> 0.33505194 | BV9: =(BW6-BU9) -> 0.60877688 | BY9: =BY47 -> 4.2467056 | CB9: 0 | CC9: : | CD9: 2 | CE9: =POISSON(CB9,$C$8,FALSE)*POISSON(CD9,$D$8,FALSE)*100 -> 3.8509777 | CF9: =RANK(CE9,$CE$5:$CE$36,0) -> 8 | CG9: =IF(CF5=4,"draw",IF(CF6=4,"away",IF(CF7=4,"draw 1-1",IF(CF8=4,"home",IF(CF9=4,"away 0-2",IF(CF10=4,"away 1-2",IF(CF11=4,"home 2-1","rountime"))))))) -> away | CH9: =IF(OR(CG9="away",CG9="home",CG9="draw"),"small",IF(OR(CG9="away",CG9="home",CG9="draw",CG9="draw 1-1",CG9="away 0-2"),"under",IF(CG9="rountime","RT",0))) -> small | CI9: =CI8+1 -> 3 | CJ9: =POISSON(CI9,$C$8,FALSE) -> 0.10261021 | CK9: =$CK$5*CJ9 -> 0.045976422 | CL9: =$CL$5*CJ9 -> 0.036910273 | CM9: =$CM$5*CJ9 -> 0.014815945 | CN9: =$CN$5*CJ9 -> 0.00396479 | CO9: =$CO$5*CJ9 -> 0.00079574202 | CP9: =$CP$5*CJ9 -> 0.00012776573 | CQ9: =IF(CT6>0.38,"u0.5",IF(CT7>0.352,"U1.5",IF(CT8>0.5885,"u2.5",IF(CT9>0.6871,"U3.5",IF(CT10>0.6993,"u4.5","Run"))))) -> U1.5 | CR9: =IF(CU10>0.34,"O4.5",IF(CU9>0.6155,"O3.5",IF(CU8>0.5063,"O2.5",IF(CU7>0.74,"O1.5",IF(CU6>0.95,"O0.5","Run"))))) -> Run | CS9: =CS8+1 -> 3.5 | CT9: =SUM(CK6,CK7,CL6,CM6,CL7,CK8,CK9,CL8,CM7,CN6) -> 0.83400357 | CU9: =(CV6-CT9) -> 0.16339057 | CX9: =CX47 -> 4.2148055 | DA9: 0 | DB9: : | DC9: 2 | DD9: =POISSON(DA9,$C$9,FALSE)*POISSON(DC9,$D$9,FALSE)*100 -> #N/A | DE9: =RANK(DD9,$DD$5:$DD$36,0) -> #N/A | DF9: =IF(DE5=4,"draw",IF(DE6=4,"away",IF(DE7=4,"draw 1-1",IF(DE8=4,"home",IF(DE9=4,"away 0-2",IF(DE10=4,"away 1-2",IF(DE11=4,"home 2-1","rountime"))))))) -> #N/A | DG9: =IF(OR(DF9="away",DF9="home",DF9="draw"),"small",IF(OR(DF9="away",DF9="home",DF9="draw",DF9="draw 1-1",DF9="away 0-2"),"under",IF(DF9="rountime","RT",0))) -> #N/A | DH9: =DH8+1 -> 3 | DI9: =POISSON(DH9,$C$9,FALSE) -> #N/A | DJ9: =$DJ$5*DI9 -> #N/A | DK9: =$DK$5*DI9 -> #N/A | DL9: =$DL$5*DI9 -> #N/A | DM9: =$DM$5*DI9 -> #N/A | DN9: =$DN$5*DI9 -> #N/A | DO9: =$DO$5*DI9 -> #N/A | DP9: =IF(DS6>0.38,"u0.5",IF(DS7>0.352,"U1.5",IF(DS8>0.5885,"u2.5",IF(DS9>0.6871,"U3.5",IF(DS10>0.6993,"u4.5","Run"))))) -> #N/A | DQ9: =IF(DT10>0.34,"O4.5",IF(DT9>0.6155,"O3.5",IF(DT8>0.5063,"O2.5",IF(DT7>0.74,"O1.5",IF(DT6>0.95,"O0.5","Run"))))) -> #N/A | DR9: =DR8+1 -> 3.5 | DS9: =SUM(DJ6,DJ7,DK6,DL6,DK7,DJ8,DJ9,DK8,DL7,DM6) -> #N/A | DT9: =(DU6-DS9) -> #N/A | DW9: =DW47 -> #N/A
C10: avrrage | D10: =Sheet1!E45 -> 1.3668 | E10: 1 | F10: : | G10: 2 | H10: =POISSON(E10,$C$5,FALSE)*POISSON(G10,$D$5,FALSE)*100 -> 5.0894893 | I10: =RANK(H10,$H$5:$H$36,0) -> 6 | J10: =IF(J6="draw",1,IF(J6="draw 1-1",1,IF(J6="home",2,IF(J6="home 2-1",2,IF(J6="away",3,IF(J6="away 1-2",3,IF(J6="away 0-2",3,0))))))) -> 2 | K10: =COUNTIF(K6:K9,"small") -> 3 | L10: =L9+1 -> 4 | M10: =POISSON(L10,$C$5,FALSE) -> 0.033902661 | N10: =$N$5*M10 -> 0.015190721 | O10: =$O$5*M10 -> 0.012195243 | P10: =$P$5*M10 -> 0.004895224 | Q10: =$Q$5*M10 -> 0.0013099762 | R10: =$R$5*M10 -> 0.00026291508 | S10: =$S$5*M10 -> 4.2214105e-05 | T10: =IF(W6>0.4,"u0.5",IF(W7>0.52,"U1.5",IF(W8>0.721,"u2.5",IF(W9>0.79775,"U3.5",IF(W10>0.8165,"u4.5","Run"))))) -> U3.5 | U10: =IF(X10>0.55,"O4.5",IF(X9>0.69775,"O3.5",IF(X8>0.7,"O2.5",IF(X7>0.79,"O1.5",IF(X6>0.92,"O0.5","Run"))))) -> Run | V10: =V9+1 -> 4.5 | W10: =SUM(N6,N7,O6,P6,O7,N8,N9,O8,P7,Q6,R6,Q7,P8,O9,N10) -> 0.93542408 | X10: =(Y6-W10) -> 0.061970057 | Y10: =(X8/$Y$16)*100 -> 14.211113 | Z10: =Y8-U13 -> 30.414826 | AA10: =IF(Z10<0,1,0) -> 0 | AD10: 1 | AE10: =AD10+AF10 -> 3 | AF10: 2 | AG10: =POISSON(AD10,$C$6,FALSE)*POISSON(AF10,$D$6,FALSE)*100 -> 6.2964039 | AH10: =RANK(AG10,$AG$5:$AG$36,0) -> 2 | AI10: =IF(AI6="draw",1,IF(AI6="draw 1-1",1,IF(AI6="home",2,IF(AI6="home 2-1",2,IF(AI6="away",3,IF(AI6="away 1-2",3,IF(AI6="away 0-2",3,0))))))) -> 0 | AJ10: =COUNTIF(AJ6:AJ9,"small") -> 0 | AK10: =AK9+1 -> 4 | AL10: =POISSON(AK10,$C$6,FALSE) -> 0.11248415 | AM10: =$AM$5*AL10 -> 0.011345038 | AN10: =$AN$5*AL10 -> 0.026025878 | AO10: =$AO$5*AL10 -> 0.029852097 | AP10: =$AP$5*AL10 -> 0.02282722 | AQ10: =$AQ$5*AL10 -> 0.013091593 | AR10: =$AR$5*AL10 -> 0.0060065062 | AS10: =IF(AV6>0.4,"u0.5",IF(AV7>0.52,"U1.5",IF(AV8>0.721,"u2.5",IF(AV9>0.79775,"U3.5",IF(AV10>0.8165,"u4.5","Run"))))) -> Run | AT10: =IF(AW10>0.55,"O4.5",IF(AW9>0.69775,"O3.5",IF(AW8>0.7,"O2.5",IF(AW7>0.79,"O1.5",IF(AW6>0.92,"O0.5","Run"))))) -> O2.5 | AU10: =AU9+1 -> 4.5 | AV10: =SUM(AM6,AM7,AN6,AO6,AN7,AM8,AM9,AN8,AO7,AP6,AQ6,AP7,AO8,AN9,AM10) -> 0.52391499 | AW10: =(AX6-AV10) -> 0.41991383 | AX10: =(AW8/$AX$16)*100 -> 32.847359 | AY10: =AX8-AT13 -> 39.098244 | AZ10: =IF(AY10<0,1,0) -> 0 | BC10: 1 | BD10: : | BE10: 2 | BF10: =POISSON(BC10,$C$7,FALSE)*POISSON(BE10,$D$7,FALSE)*100 -> 6.2964039 | BG10: =RANK(BF10,$BF$5:$BF$36,0) -> 2 | BH10: =IF(BH6="draw",1,IF(BH6="draw 1-1",1,IF(BH6="home",2,IF(BH6="home 2-1",2,IF(BH6="away",3,IF(BH6="away 1-2",3,IF(BH6="away 0-2",3,0))))))) -> 0 | BI10: =COUNTIF(BI6:BI9,"small") -> 0 | BJ10: =BJ9+1 -> 4 | BK10: =POISSON(BJ10,$C$7,FALSE) -> 0.11248415 | BL10: =$BL$5*BK10 -> 0.011345038 | BM10: =$BM$5*BK10 -> 0.026025878 | BN10: =$BN$5*BK10 -> 0.029852097 | BO10: =$BO$5*BK10 -> 0.02282722 | BP10: =$BP$5*BK10 -> 0.013091593 | BQ10: =$BQ$5*BK10 -> 0.0060065062 | BR10: =IF(BU6>0.4,"u0.5",IF(BU7>0.52,"U1.5",IF(BU8>0.721,"u2.5",IF(BU9>0.79775,"U3.5",IF(BU10>0.8165,"u4.5","Run"))))) -> Run | BS10: =IF(BV10>0.55,"O4.5",IF(BV9>0.69775,"O3.5",IF(BV8>0.7,"O2.5",IF(BV7>0.79,"O1.5",IF(BV6>0.92,"O0.5","Run"))))) -> O2.5 | BT10: =BT9+1 -> 4.5 | BU10: =SUM(BL6,BL7,BM6,BN6,BM7,BL8,BL9,BM8,BN7,BO6,BP6,BO7,BN8,BM9,BL10) -> 0.52391499 | BV10: =(BW6-BU10) -> 0.41991383 | CB10: 1 | CC10: : | CD10: 2 | CE10: =POISSON(CB10,$C$8,FALSE)*POISSON(CD10,$D$8,FALSE)*100 -> 5.0894893 | CF10: =RANK(CE10,$CE$5:$CE$36,0) -> 6 | CG10: =IF(CG6="draw",1,IF(CG6="draw 1-1",1,IF(CG6="home",2,IF(CG6="home 2-1",2,IF(CG6="away",3,IF(CG6="away 1-2",3,IF(CG6="away 0-2",3,0))))))) -> 2 | CH10: =COUNTIF(CH6:CH9,"small") -> 3 | CI10: =CI9+1 -> 4 | CJ10: =POISSON(CI10,$C$8,FALSE) -> 0.033902661 | CK10: =$CK$5*CJ10 -> 0.015190721 | CL10: =$CL$5*CJ10 -> 0.012195243 | CM10: =$CM$5*CJ10 -> 0.004895224 | CN10: =$CN$5*CJ10 -> 0.0013099762 | CO10: =$CO$5*CJ10 -> 0.00026291508 | CP10: =$CP$5*CJ10 -> 4.2214105e-05 | CQ10: =IF(CT6>0.4,"u0.5",IF(CT7>0.52,"U1.5",IF(CT8>0.721,"u2.5",IF(CT9>0.79775,"U3.5",IF(CT10>0.8165,"u4.5","Run"))))) -> U3.5 | CR10: =IF(CU10>0.55,"O4.5",IF(CU9>0.69775,"O3.5",IF(CU8>0.7,"O2.5",IF(CU7>0.79,"O1.5",IF(CU6>0.92,"O0.5","Run"))))) -> Run | CS10: =CS9+1 -> 4.5 | CT10: =SUM(CK6,CK7,CL6,CM6,CL7,CK8,CK9,CL8,CM7,CN6,CO6,CN7,CM8,CL9,CK10) -> 0.93542408 | CU10: =(CV6-CT10) -> 0.061970057 | DA10: 1 | DB10: : | DC10: 2 | DD10: =POISSON(DA10,$C$9,FALSE)*POISSON(DC10,$D$9,FALSE)*100 -> #N/A | DE10: =RANK(DD10,$DD$5:$DD$36,0) -> #N/A | DF10: =IF(DF6="draw",1,IF(DF6="draw 1-1",1,IF(DF6="home",2,IF(DF6="home 2-1",2,IF(DF6="away",3,IF(DF6="away 1-2",3,IF(DF6="away 0-2",3,0))))))) -> #N/A | DG10: =COUNTIF(DG6:DG9,"small") -> 0 | DH10: =DH9+1 -> 4 | DI10: =POISSON(DH10,$C$9,FALSE) -> #N/A | DJ10: =$DJ$5*DI10 -> #N/A | DK10: =$DK$5*DI10 -> #N/A | DL10: =$DL$5*DI10 -> #N/A | DM10: =$DM$5*DI10 -> #N/A | DN10: =$DN$5*DI10 -> #N/A | DO10: =$DO$5*DI10 -> #N/A | DP10: =IF(DS6>0.4,"u0.5",IF(DS7>0.52,"U1.5",IF(DS8>0.721,"u2.5",IF(DS9>0.79775,"U3.5",IF(DS10>0.8165,"u4.5","Run"))))) -> #N/A | DQ10: =IF(DT10>0.55,"O4.5",IF(DT9>0.69775,"O3.5",IF(DT8>0.7,"O2.5",IF(DT7>0.79,"O1.5",IF(DT6>0.92,"O0.5","Run"))))) -> #N/A | DR10: =DR9+1 -> 4.5 | DS10: =SUM(DJ6,DJ7,DK6,DL6,DK7,DJ8,DJ9,DK8,DL7,DM6,DN6,DM7,DL8,DK9,DJ10) -> #N/A | DT10: =(DU6-DS10) -> #N/A
D11: =IF(D10>1.28,"High scoring league",IF(D10<1.1,"low scoring","medium")) -> High scoring league | E11: 2 | F11: : | G11: 1 | H11: =POISSON(E11,$C$5,FALSE)*POISSON(G11,$D$5,FALSE)*100 -> 8.3784815 | I11: =RANK(H11,$H$5:$H$36,0) -> 5 | J11: =IF(J7="draw",1,IF(J7="draw 1-1",1,IF(J7="home",2,IF(J7="home 2-1",2,IF(J7="away",3,IF(J7="away 1-2",3,IF(J7="away 0-2",3,0))))))) -> 1 | K11: =COUNTIF(K6:K9,"under") -> 1 | L11: =L10+1 -> 5 | M11: =POISSON(L11,$C$5,FALSE) -> 0.0089612167 | N11: =$N$5*M11 -> 0.0040152406 | O11: =$O$5*M11 -> 0.0032234703 | P11: =$P$5*M11 -> 0.001293915 | Q11: =$Q$5*M11 -> 0.00034625543 | R11: =$R$5*M11 -> 6.9494222e-05 | S11: =$S$5*M11 -> 1.1158114e-05 | V11: decision | W11: =IF(W6>0.46,"u0.5",IF(W7>0.688,"U1.5",IF(W8>0.855,"u2.5",IF(W9>0.908,"U3.5",IF(W10>0.93,"u4.5","Run"))))) -> u4.5 | X11: =IF(X10>0.77,"O4.5",IF(X9>0.79,"O3.5",IF(X8>0.84,"O2.5",IF(X7>0.855,"O1.5",IF(X6>0.88,"O0.5","Run"))))) -> Run | Y11: =(X9/$Y$16)*100 -> 6.5526981 | Z11: =Y9-U14 -> 10.051907 | AA11: =IF(Z11<0,1,0) -> 0 | AD11: 2 | AE11: =AD11+AF11 -> 3 | AF11: 1 | AG11: =POISSON(AD11,$C$6,FALSE)*POISSON(AF11,$D$6,FALSE)*100 -> 6.1733984 | AH11: =RANK(AG11,$AG$5:$AG$36,0) -> 3 | AI11: =IF(AI7="draw",1,IF(AI7="draw 1-1",1,IF(AI7="home",2,IF(AI7="home 2-1",2,IF(AI7="away",3,IF(AI7="away 1-2",3,IF(AI7="away 0-2",3,0))))))) -> 3 | AJ11: =COUNTIF(AJ6:AJ9,"under") -> 1 | AK11: =AK10+1 -> 5 | AL11: =POISSON(AK11,$C$6,FALSE) -> 0.05060023 | AM11: =$AM$5*AL11 -> 0.0051034882 | AN11: =$AN$5*AL11 -> 0.011707565 | AO11: =$AO$5*AL11 -> 0.013428763 | AP11: =$AP$5*AL11 -> 0.01026867 | AQ11: =$AQ$5*AL11 -> 0.005889164 | AR11: =$AR$5*AL11 -> 0.002701986 | AU11: decision | AV11: =IF(AV6>0.46,"u0.5",IF(AV7>0.688,"U1.5",IF(AV8>0.855,"u2.5",IF(AV9>0.908,"U3.5",IF(AV10>0.93,"u4.5","Run"))))) -> Run | AW11: =IF(AW10>0.77,"O4.5",IF(AW9>0.79,"O3.5",IF(AW8>0.84,"O2.5",IF(AW7>0.855,"O1.5",IF(AW6>0.88,"O0.5","Run"))))) -> O1.5 | AX11: =(AW9/$AX$16)*100 -> 25.800309 | AY11: =AX9-AT14 -> 35.00134 | AZ11: =IF(AY11<0,1,0) -> 0 | BC11: 2 | BD11: : | BE11: 1 | BF11: =POISSON(BC11,$C$7,FALSE)*POISSON(BE11,$D$7,FALSE)*100 -> 6.1733984 | BG11: =RANK(BF11,$BF$5:$BF$36,0) -> 3 | BH11: =IF(BH7="draw",1,IF(BH7="draw 1-1",1,IF(BH7="home",2,IF(BH7="home 2-1",2,IF(BH7="away",3,IF(BH7="away 1-2",3,IF(BH7="away 0-2",3,0))))))) -> 3 | BI11: =COUNTIF(BI6:BI9,"under") -> 1 | BJ11: =BJ10+1 -> 5 | BK11: =POISSON(BJ11,$C$7,FALSE) -> 0.05060023 | BL11: =$BL$5*BK11 -> 0.0051034882 | BM11: =$BM$5*BK11 -> 0.011707565 | BN11: =$BN$5*BK11 -> 0.013428763 | BO11: =$BO$5*BK11 -> 0.01026867 | BP11: =$BP$5*BK11 -> 0.005889164 | BQ11: =$BQ$5*BK11 -> 0.002701986 | BT11: decision | BU11: =IF(BU6>0.46,"u0.5",IF(BU7>0.688,"U1.5",IF(BU8>0.855,"u2.5",IF(BU9>0.908,"U3.5",IF(BU10>0.93,"u4.5","Run"))))) -> Run | BV11: =IF(BV10>0.77,"O4.5",IF(BV9>0.79,"O3.5",IF(BV8>0.84,"O2.5",IF(BV7>0.855,"O1.5",IF(BV6>0.88,"O0.5","Run"))))) -> O1.5 | CB11: 2 | CC11: : | CD11: 1 | CE11: =POISSON(CB11,$C$8,FALSE)*POISSON(CD11,$D$8,FALSE)*100 -> 8.3784815 | CF11: =RANK(CE11,$CE$5:$CE$36,0) -> 5 | CG11: =IF(CG7="draw",1,IF(CG7="draw 1-1",1,IF(CG7="home",2,IF(CG7="home 2-1",2,IF(CG7="away",3,IF(CG7="away 1-2",3,IF(CG7="away 0-2",3,0))))))) -> 1 | CH11: =COUNTIF(CH6:CH9,"under") -> 1 | CI11: =CI10+1 -> 5 | CJ11: =POISSON(CI11,$C$8,FALSE) -> 0.0089612167 | CK11: =$CK$5*CJ11 -> 0.0040152406 | CL11: =$CL$5*CJ11 -> 0.0032234703 | CM11: =$CM$5*CJ11 -> 0.001293915 | CN11: =$CN$5*CJ11 -> 0.00034625543 | CO11: =$CO$5*CJ11 -> 6.9494222e-05 | CP11: =$CP$5*CJ11 -> 1.1158114e-05 | CS11: decision | CT11: =IF(CT6>0.46,"u0.5",IF(CT7>0.688,"U1.5",IF(CT8>0.855,"u2.5",IF(CT9>0.908,"U3.5",IF(CT10>0.93,"u4.5","Run"))))) -> u4.5 | CU11: =IF(CU10>0.77,"O4.5",IF(CU9>0.79,"O3.5",IF(CU8>0.84,"O2.5",IF(CU7>0.855,"O1.5",IF(CU6>0.88,"O0.5","Run"))))) -> Run | DA11: 2 | DB11: : | DC11: 1 | DD11: =POISSON(DA11,$C$9,FALSE)*POISSON(DC11,$D$9,FALSE)*100 -> #N/A | DE11: =RANK(DD11,$DD$5:$DD$36,0) -> #N/A | DF11: =IF(DF7="draw",1,IF(DF7="draw 1-1",1,IF(DF7="home",2,IF(DF7="home 2-1",2,IF(DF7="away",3,IF(DF7="away 1-2",3,IF(DF7="away 0-2",3,0))))))) -> #N/A | DG11: =COUNTIF(DG6:DG9,"under") -> 0 | DH11: =DH10+1 -> 5 | DI11: =POISSON(DH11,$C$9,FALSE) -> #N/A | DJ11: =$DJ$5*DI11 -> #N/A | DK11: =$DK$5*DI11 -> #N/A | DL11: =$DL$5*DI11 -> #N/A | DM11: =$DM$5*DI11 -> #N/A | DN11: =$DN$5*DI11 -> #N/A | DO11: =$DO$5*DI11 -> #N/A | DR11: decision | DS11: =IF(DS6>0.46,"u0.5",IF(DS7>0.688,"U1.5",IF(DS8>0.855,"u2.5",IF(DS9>0.908,"U3.5",IF(DS10>0.93,"u4.5","Run"))))) -> #N/A | DT11: =IF(DT10>0.77,"O4.5",IF(DT9>0.79,"O3.5",IF(DT8>0.84,"O2.5",IF(DT7>0.855,"O1.5",IF(DT6>0.88,"O0.5","Run"))))) -> #N/A
